Workbook

Sheet South
A1: =BX56 -> 0.62587413 | C1: =SUM(U4:BT52)+SUM(North!U4:W7) -> 0 | N1: RECORDS | U1: =North!C4 -> Seven Oaks | V1: =North!C5 -> University Club | W1: =North!C6 -> Greystone | X1: =C4 -> Cary | Y1: =C5 -> Scottish Hills | Z1: =C6 -> Cary Park | AA1: =C7 -> Apex | AB1: =C8 -> Medfield | AC1: =C9 -> Sunset Ridge | AD1: =C10 -> Abbington | AE1: =C11 -> Prestonwood | AF1: =C12 -> Dutchman Downs | AG1: =C13 -> Lochmere | AH1: =C14 -> Shepherds Vineyard | AI1: =C15 -> Olive Chapel | AJ1: =C16 -> Preston Village | AK1: =C17 -> Walden Creek | AL1: =C18 -> WoodCreek | AM1: =C19 -> Silverton | AN1: =C20 -> Clubworx | AO1: =C21 -> Brookstone | AP1: =C22 -> Regency | AQ1: =C23 -> Wellsley | AR1: =C24 -> Amberly | AS1: =C25 -> Highcroft | AT1: =C26 -> Weatherstone | AU1: =C27 -> Weldon Ridge | AV1: =C28 -> Oxxford Hunt | AW1: =C29 -> Haddon Hall | AX1: =C30 -> Scotts Mill | AY1: =C31 -> Park at West Lake | AZ1: =C32 -> Life Time Fitness Cary | BA1: =C33 -> Holly Glen | BB1: =C34 -> Bella Casa | BC1: =C35 -> The Reserve | BD1: =C36 -> TCC | BE1: =C37 -> Kildaire Farms | BF1: =C38 -> Carpenter Village | BG1: =C39 -> Bentwinds | BH1: =C40 -> Kitts Creek | BI1: =C41 -> Park Village | BJ1: =C42 -> Brighton Forest | BK1: =C43 -> Eagle Ridge | BL1: =C44 -> Glenridge | BM1: =C45 -> Harmony | BN1: =C46 -> Garner | BO1: =C47 -> Crooked Creek | BP1: =C48 -> Charleston Village | BQ1: =C49 -> Arbor Creek | BR1: =C50 -> Devereaux | BS1: =C51 -> Wellington Park | BT1: =C52 -> Renaissance Park | BU1: =C53 -> Breckenridge | BV1: =C54 -> Sweetwater
A2: 2026 | B2: 2025 | E2: Rank Justified by HTH result | L2: 2023 | N2: Overall | Q2: Division | U2: N1 | V2: N1 | W2: N1 | X2: 1 | Y2: 1 | Z2: 1 | AA2: 1 | AB2: 2 | AC2: 2 | AD2: 2 | AE2: 2 | AF2: 3 | AG2: 3 | AH2: 3 | AI2: 3 | AJ2: 4 | AK2: 4 | AL2: 4 | AM2: 4 | AN2: 5 | AO2: 5 | AP2: 5 | AQ2: 5 | AR2: 6 | AS2: 6 | AT2: 6 | AU2: 6 | AV2: 7 | AW2: 7 | AX2: 7 | AY2: 7 | AZ2: 8 | BA2: 8 | BB2: 8 | BC2: 8 | BD2: 9 | BE2: 9 | BF2: 9 | BG2: 9 | BH2: 10 | BI2: 10 | BJ2: 10 | BK2: 10 | BL2: 11 | BM2: 11 | BN2: 11 | BO2: 11 | BP2: 12 | BQ2: 12 | BR2: 12 | BS2: 13 | BT2: 13 | BU2: 13 | BV2: 13 | BX2: HTH | BY2: HTH | BZ2: HTH
A3: Rank | B3: Rank | E3: Up 3 | F3: Up 2 | G3: Up 1 | H3: Dn 1 | I3: Dn 2 | J3: Dn 3 | L3: Rank | M3: Div | N3: W | O3: L | P3: T | Q3: W | R3: L | S3: T | T3: NC | BX3: Yes | BY3: No | BZ3: Poss | CA3: Percent | CE3: SvS | CF3: Comm | CG3: Diff
A4: 1 | B4: 1 | C4: Cary | E4: =IF(AND(X4>0,$A4<VLOOKUP(X$1,$C:$L,10,FALSE)),1,IF(AND(X4<0,$A4>VLOOKUP(X$1,$C:$L,10,FALSE)),1,0)) -> 0 | F4: =IF(AND(Y4>0,$A4<VLOOKUP(Y$1,$C:$L,10,FALSE)),1,IF(AND(Y4<0,$A4>VLOOKUP(Y$1,$C:$L,10,FALSE)),1,0)) -> 1 | G4: =IF(AND(Z4>0,$A4<VLOOKUP(Z$1,$C:$L,10,FALSE)),1,IF(AND(Z4<0,$A4>VLOOKUP(Z$1,$C:$L,10,FALSE)),1,0)) -> 1 | H4: =IF(AND(AB4>0,$A4<VLOOKUP(AB$1,$C:$L,10,FALSE)),1,IF(AND(AB4<0,$A4>VLOOKUP(AB$1,$C:$L,10,FALSE)),1,0)) -> 1 | I4: =IF(AND(AC4>0,$A4<VLOOKUP(AC$1,$C:$L,10,FALSE)),1,IF(AND(AC4<0,$A4>VLOOKUP(AC$1,$C:$L,10,FALSE)),1,0)) -> 1 | J4: =IF(AND(AD4>0,$A4<VLOOKUP(AD$1,$C:$L,10,FALSE)),1,IF(AND(AD4<0,$A4>VLOOKUP(AD$1,$C:$L,10,FALSE)),1,0)) -> 1 | K4: Updated | L4: =B4 -> 1 | M4: 1 | N4: =COUNTIF($U4:$BT4,">0") -> 5 | O4: =COUNTIF($U4:$BT4,"<0") -> 1 | P4: =COUNTIF($U4:$BT4,"=0") -> 0 | Q4: =COUNTIF($X4:$AA4,">0") -> 3 | R4: =COUNTIF($X4:$AA4,"<0") -> 0 | S4: =COUNTIF($X4:$AA4,"=0") -> 0 | T4: =COUNTIF(U4:BU4,"NC") -> 0 | U4: =IFERROR(IFERROR(VLOOKUP($C4&" "&U$1,Results!$F:$H,3,FALSE),-VLOOKUP($C4&" "&U$1,Results!$G:$H,2,FALSE)),"") -> -134 | V4: =IFERROR(IFERROR(VLOOKUP($C4&" "&V$1,Results!$F:$H,3,FALSE),-VLOOKUP($C4&" "&V$1,Results!$G:$H,2,FALSE)),"") -> 13 | W4: =IFERROR(IFERROR(VLOOKUP($C4&" "&W$1,Results!$F:$H,3,FALSE),-VLOOKUP($C4&" "&W$1,Results!$G:$H,2,FALSE)),"") -> 1 | X4: =IFERROR(IFERROR(VLOOKUP($C4&" "&X$1,Results!$F:$H,3,FALSE),-VLOOKUP($C4&" "&X$1,Results!$G:$H,2,FALSE)),"") | Y4: =IFERROR(IFERROR(VLOOKUP($C4&" "&Y$1,Results!$F:$H,3,FALSE),-VLOOKUP($C4&" "&Y$1,Results!$G:$H,2,FALSE)),"") -> 29 | Z4: =IFERROR(IFERROR(VLOOKUP($C4&" "&Z$1,Results!$F:$H,3,FALSE),-VLOOKUP($C4&" "&Z$1,Results!$G:$H,2,FALSE)),"") -> 70 | AA4: =IFERROR(IFERROR(VLOOKUP($C4&" "&AA$1,Results!$F:$H,3,FALSE),-VLOOKUP($C4&" "&AA$1,Results!$G:$H,2,FALSE)),"") -> 68 | AB4: =IFERROR(IFERROR(VLOOKUP($C4&" "&AB$1,Results!$F:$H,3,FALSE),-VLOOKUP($C4&" "&AB$1,Results!$G:$H,2,FALSE)),"") | ... AE4: =IFERROR(IFERROR(VLOOKUP($C4&" "&AE$1,Results!$F:$H,3,FALSE),-VLOOKUP($C4&" "&AE$1,Results!$G:$H,2,FALSE)),"") | BW4: =SUM(U4:BS4) -> 47 | BX4: =COUNTIF(E4:J4,1) -> 5 | BY4: =COUNTIF(E4:J4,0) -> 1 | BZ4: =COUNT(E4:J4) -> 6 | CA4: =+BX4/BZ4 -> 0.83333333 | CC4: =SUM(U4:BT4) -> 47 | CE4: 8 | CF4: =A4 -> 1 | CG4: =+CE4-CF4 -> 7
A5: 3 | B5: 2 | C5: Scottish Hills | F5: =IF(AND(X5>0,$A5<VLOOKUP(X$1,$C:$L,10,FALSE)),1,IF(AND(X5<0,$A5>VLOOKUP(X$1,$C:$L,10,FALSE)),1,0)) -> 1 | G5: =IF(AND(Y5>0,$A5<VLOOKUP(Y$1,$C:$L,10,FALSE)),1,IF(AND(Y5<0,$A5>VLOOKUP(Y$1,$C:$L,10,FALSE)),1,0)) -> 0 | H5: =IF(AND(AA5>0,$A5<VLOOKUP(AA$1,$C:$L,10,FALSE)),1,IF(AND(AA5<0,$A5>VLOOKUP(AA$1,$C:$L,10,FALSE)),1,0)) -> 1 | I5: =IF(AND(AB5>0,$A5<VLOOKUP(AB$1,$C:$L,10,FALSE)),1,IF(AND(AB5<0,$A5>VLOOKUP(AB$1,$C:$L,10,FALSE)),1,0)) -> 1 | J5: =IF(AND(AC5>0,$A5<VLOOKUP(AC$1,$C:$L,10,FALSE)),1,IF(AND(AC5<0,$A5>VLOOKUP(AC$1,$C:$L,10,FALSE)),1,0)) -> 1 | K5: Updated | L5: =B5 -> 2 | M5: 1 | N5: =COUNTIF($U5:$BT5,">0") -> 2 | O5: =COUNTIF($U5:$BT5,"<0") -> 4 | P5: =COUNTIF($U5:$BT5,"=0") -> 0 | Q5: =COUNTIF($X5:$AA5,">0") -> 1 | R5: =COUNTIF($X5:$AA5,"<0") -> 2 | S5: =COUNTIF($X5:$AA5,"=0") -> 0 | T5: =COUNTIF(U5:BU5,"NC") -> 0 | U5: =IFERROR(IFERROR(VLOOKUP($C5&" "&U$1,Results!$F:$H,3,FALSE),-VLOOKUP($C5&" "&U$1,Results!$G:$H,2,FALSE)),"") -> -197 | V5: =IFERROR(IFERROR(VLOOKUP($C5&" "&V$1,Results!$F:$H,3,FALSE),-VLOOKUP($C5&" "&V$1,Results!$G:$H,2,FALSE)),"") -> -102 | W5: =IFERROR(IFERROR(VLOOKUP($C5&" "&W$1,Results!$F:$H,3,FALSE),-VLOOKUP($C5&" "&W$1,Results!$G:$H,2,FALSE)),"") | X5: =IFERROR(IFERROR(VLOOKUP($C5&" "&X$1,Results!$F:$H,3,FALSE),-VLOOKUP($C5&" "&X$1,Results!$G:$H,2,FALSE)),"") -> -29 | Y5: =IFERROR(IFERROR(VLOOKUP($C5&" "&Y$1,Results!$F:$H,3,FALSE),-VLOOKUP($C5&" "&Y$1,Results!$G:$H,2,FALSE)),"") | Z5: =IFERROR(IFERROR(VLOOKUP($C5&" "&Z$1,Results!$F:$H,3,FALSE),-VLOOKUP($C5&" "&Z$1,Results!$G:$H,2,FALSE)),"") -> -66 | AA5: =IFERROR(IFERROR(VLOOKUP($C5&" "&AA$1,Results!$F:$H,3,FALSE),-VLOOKUP($C5&" "&AA$1,Results!$G:$H,2,FALSE)),"") -> 123 | AB5: =IFERROR(IFERROR(VLOOKUP($C5&" "&AB$1,Results!$F:$H,3,FALSE),-VLOOKUP($C5&" "&AB$1,Results!$G:$H,2,FALSE)),"") -> 116 | ... AE5: =IFERROR(IFERROR(VLOOKUP($C5&" "&AE$1,Results!$F:$H,3,FALSE),-VLOOKUP($C5&" "&AE$1,Results!$G:$H,2,FALSE)),"") | BW5: =SUM(U5:BS5) -> -155 | BX5: =COUNTIF(E5:J5,1) -> 4 | BY5: =COUNTIF(E5:J5,0) -> 1 | BZ5: =COUNT(E5:J5) -> 5 | CA5: =+BX5/BZ5 -> 0.8 | CC5: =SUM(U5:BT5) -> -155 | CE5: 7 | CF5: =A5 -> 3 | CG5: =+CE5-CF5 -> 4
A6: 2 | B6: 3 | C6: Cary Park | G6: =IF(AND(X6>0,$A6<VLOOKUP(X$1,$C:$L,10,FALSE)),1,IF(AND(X6<0,$A6>VLOOKUP(X$1,$C:$L,10,FALSE)),1,0)) -> 1 | H6: =IF(AND(Z6>0,$A6<VLOOKUP(Z$1,$C:$L,10,FALSE)),1,IF(AND(Z6<0,$A6>VLOOKUP(Z$1,$C:$L,10,FALSE)),1,0)) -> 1 | I6: =IF(AND(AA6>0,$A6<VLOOKUP(AA$1,$C:$L,10,FALSE)),1,IF(AND(AA6<0,$A6>VLOOKUP(AA$1,$C:$L,10,FALSE)),1,0)) -> 1 | J6: =IF(AND(AB6>0,$A6<VLOOKUP(AB$1,$C:$L,10,FALSE)),1,IF(AND(AB6<0,$A6>VLOOKUP(AB$1,$C:$L,10,FALSE)),1,0)) -> 1 | K6: Updated | L6: =B6 -> 3 | M6: 1 | N6: =COUNTIF($U6:$BT6,">0") -> 4 | O6: =COUNTIF($U6:$BT6,"<0") -> 2 | P6: =COUNTIF($U6:$BT6,"=0") -> 0 | Q6: =COUNTIF($X6:$AA6,">0") -> 2 | R6: =COUNTIF($X6:$AA6,"<0") -> 1 | S6: =COUNTIF($X6:$AA6,"=0") -> 0 | T6: =COUNTIF(U6:BU6,"NC") -> 0 | U6: =IFERROR(IFERROR(VLOOKUP($C6&" "&U$1,Results!$F:$H,3,FALSE),-VLOOKUP($C6&" "&U$1,Results!$G:$H,2,FALSE)),"") -> -99 | V6: =IFERROR(IFERROR(VLOOKUP($C6&" "&V$1,Results!$F:$H,3,FALSE),-VLOOKUP($C6&" "&V$1,Results!$G:$H,2,FALSE)),"") | W6: =IFERROR(IFERROR(VLOOKUP($C6&" "&W$1,Results!$F:$H,3,FALSE),-VLOOKUP($C6&" "&W$1,Results!$G:$H,2,FALSE)),"") | X6: =IFERROR(IFERROR(VLOOKUP($C6&" "&X$1,Results!$F:$H,3,FALSE),-VLOOKUP($C6&" "&X$1,Results!$G:$H,2,FALSE)),"") -> -70 | Y6: =IFERROR(IFERROR(VLOOKUP($C6&" "&Y$1,Results!$F:$H,3,FALSE),-VLOOKUP($C6&" "&Y$1,Results!$G:$H,2,FALSE)),"") -> 66 | Z6: =IFERROR(IFERROR(VLOOKUP($C6&" "&Z$1,Results!$F:$H,3,FALSE),-VLOOKUP($C6&" "&Z$1,Results!$G:$H,2,FALSE)),"") | AA6: =IFERROR(IFERROR(VLOOKUP($C6&" "&AA$1,Results!$F:$H,3,FALSE),-VLOOKUP($C6&" "&AA$1,Results!$G:$H,2,FALSE)),"") -> 50 | AB6: =IFERROR(IFERROR(VLOOKUP($C6&" "&AB$1,Results!$F:$H,3,FALSE),-VLOOKUP($C6&" "&AB$1,Results!$G:$H,2,FALSE)),"") -> 13 | ... AE6: =IFERROR(IFERROR(VLOOKUP($C6&" "&AE$1,Results!$F:$H,3,FALSE),-VLOOKUP($C6&" "&AE$1,Results!$G:$H,2,FALSE)),"") | BW6: =SUM(U6:BS6) -> 140 | BX6: =COUNTIF(E6:I6,1) -> 3 | BY6: =COUNTIF(E6:J6,0) -> 0 | BZ6: =COUNT(E6:I6) -> 3 | CA6: =+BX6/BZ6 -> 1 | CC6: =SUM(U6:BT6) -> 140 | CE6: 1 | CF6: =A6 -> 2 | CG6: =+CE6-CF6 -> -1
A7: 5 | B7: 4 | C7: Apex | E7: =IF(AND(Z7>0,$A7<VLOOKUP(Z$1,$C:$L,10,FALSE)),1,IF(AND(Z7<0,$A7>VLOOKUP(Z$1,$C:$L,10,FALSE)),1,0)) -> 1 | F7: =IF(AND(AA7>0,$A7<VLOOKUP(AA$1,$C:$L,10,FALSE)),1,IF(AND(AA7<0,$A7>VLOOKUP(AA$1,$C:$L,10,FALSE)),1,0)) -> 0 | G7: =IF(AND(AB7>0,$A7<VLOOKUP(AB$1,$C:$L,10,FALSE)),1,IF(AND(AB7<0,$A7>VLOOKUP(AB$1,$C:$L,10,FALSE)),1,0)) -> 0 | H7: =IF(AND(AD7>0,$A7<VLOOKUP(AD$1,$C:$L,10,FALSE)),1,IF(AND(AD7<0,$A7>VLOOKUP(AD$1,$C:$L,10,FALSE)),1,0)) -> 0 | I7: =IF(AND(AE7>0,$A7<VLOOKUP(AE$1,$C:$L,10,FALSE)),1,IF(AND(AE7<0,$A7>VLOOKUP(AE$1,$C:$L,10,FALSE)),1,0)) -> 1 | J7: =IF(AND(AF7>0,$A7<VLOOKUP(AF$1,$C:$L,10,FALSE)),1,IF(AND(AF7<0,$A7>VLOOKUP(AF$1,$C:$L,10,FALSE)),1,0)) -> 1 | K7: Updated | L7: =B7 -> 4 | M7: 1 | N7: =COUNTIF($U7:$BT7,">0") -> 2 | O7: =COUNTIF($U7:$BT7,"<0") -> 4 | P7: =COUNTIF($U7:$BT7,"=0") -> 0 | Q7: =COUNTIF($X7:$AA7,">0") -> 0 | R7: =COUNTIF($X7:$AA7,"<0") -> 3 | S7: =COUNTIF($X7:$AA7,"=0") -> 0 | T7: =COUNTIF(U7:BU7,"NC") -> 0 | X7: =IFERROR(IFERROR(VLOOKUP($C7&" "&X$1,Results!$F:$H,3,FALSE),-VLOOKUP($C7&" "&X$1,Results!$G:$H,2,FALSE)),"") -> -68 | Y7: =IFERROR(IFERROR(VLOOKUP($C7&" "&Y$1,Results!$F:$H,3,FALSE),-VLOOKUP($C7&" "&Y$1,Results!$G:$H,2,FALSE)),"") -> -123 | Z7: =IFERROR(IFERROR(VLOOKUP($C7&" "&Z$1,Results!$F:$H,3,FALSE),-VLOOKUP($C7&" "&Z$1,Results!$G:$H,2,FALSE)),"") -> -50 | AA7: =IFERROR(IFERROR(VLOOKUP($C7&" "&AA$1,Results!$F:$H,3,FALSE),-VLOOKUP($C7&" "&AA$1,Results!$G:$H,2,FALSE)),"") | AB7: =IFERROR(IFERROR(VLOOKUP($C7&" "&AB$1,Results!$F:$H,3,FALSE),-VLOOKUP($C7&" "&AB$1,Results!$G:$H,2,FALSE)),"") -> 46 | AC7: =IFERROR(IFERROR(VLOOKUP($C7&" "&AC$1,Results!$F:$H,3,FALSE),-VLOOKUP($C7&" "&AC$1,Results!$G:$H,2,FALSE)),"") -> 109 | AD7: =IFERROR(IFERROR(VLOOKUP($C7&" "&AD$1,Results!$F:$H,3,FALSE),-VLOOKUP($C7&" "&AD$1,Results!$G:$H,2,FALSE)),"") -> -66 | AE7: =IFERROR(IFERROR(VLOOKUP($C7&" "&AE$1,Results!$F:$H,3,FALSE),-VLOOKUP($C7&" "&AE$1,Results!$G:$H,2,FALSE)),"") | ... AI7: =IFERROR(IFERROR(VLOOKUP($C7&" "&AI$1,Results!$F:$H,3,FALSE),-VLOOKUP($C7&" "&AI$1,Results!$G:$H,2,FALSE)),"") | BW7: =SUM(U7:BS7) -> -152 | BX7: =COUNTIF(E7:J7,1) -> 3 | BY7: =COUNTIF(E7:J7,0) -> 3 | BZ7: =COUNT(E7:J7) -> 6 | CA7: =+BX7/BZ7 -> 0.5 | CC7: =SUM(U7:BT7) -> -152 | CE7: 4 | CF7: =A7 -> 5 | CG7: =+CE7-CF7 -> -1
A8: 7 | B8: 5 | C8: Medfield | E8: =IF(AND(AC8>0,$A8<VLOOKUP(AC$1,$C:$L,10,FALSE)),1,IF(AND(AC8<0,$A8>VLOOKUP(AC$1,$C:$L,10,FALSE)),1,0)) -> 1 | F8: =IF(AND(AD8>0,$A8<VLOOKUP(AD$1,$C:$L,10,FALSE)),1,IF(AND(AD8<0,$A8>VLOOKUP(AD$1,$C:$L,10,FALSE)),1,0)) -> 0 | G8: =IF(AND(AE8>0,$A8<VLOOKUP(AE$1,$C:$L,10,FALSE)),1,IF(AND(AE8<0,$A8>VLOOKUP(AE$1,$C:$L,10,FALSE)),1,0)) -> 1 | H8: =IF(AND(AG8>0,$A8<VLOOKUP(AG$1,$C:$L,10,FALSE)),1,IF(AND(AG8<0,$A8>VLOOKUP(AG$1,$C:$L,10,FALSE)),1,0)) -> 1 | I8: =IF(AND(AH8>0,$A8<VLOOKUP(AH$1,$C:$L,10,FALSE)),1,IF(AND(AH8<0,$A8>VLOOKUP(AH$1,$C:$L,10,FALSE)),1,0)) -> 1 | J8: =IF(AND(AI8>0,$A8<VLOOKUP(AI$1,$C:$L,10,FALSE)),1,IF(AND(AI8<0,$A8>VLOOKUP(AI$1,$C:$L,10,FALSE)),1,0)) -> 1 | K8: Updated | L8: =B8 -> 5 | M8: 2 | N8: =COUNTIF($U8:$BT8,">0") -> 2 | O8: =COUNTIF($U8:$BT8,"<0") -> 4 | P8: =COUNTIF($U8:$BT8,"=0") -> 0 | Q8: =COUNTIF($AB8:$AE8,">0") -> 2 | R8: =COUNTIF($AB8:$AE8,"<0") -> 1 | S8: =COUNTIF($AB8:$AE8,"=0") -> 0 | T8: =COUNTIF(U8:BU8,"NC") -> 0 | Y8: =IFERROR(IFERROR(VLOOKUP($C8&" "&Y$1,Results!$F:$H,3,FALSE),-VLOOKUP($C8&" "&Y$1,Results!$G:$H,2,FALSE)),"") -> -116 | Z8: =IFERROR(IFERROR(VLOOKUP($C8&" "&Z$1,Results!$F:$H,3,FALSE),-VLOOKUP($C8&" "&Z$1,Results!$G:$H,2,FALSE)),"") -> -13 | AA8: =IFERROR(IFERROR(VLOOKUP($C8&" "&AA$1,Results!$F:$H,3,FALSE),-VLOOKUP($C8&" "&AA$1,Results!$G:$H,2,FALSE)),"") -> -46 | AB8: =IFERROR(IFERROR(VLOOKUP($C8&" "&AB$1,Results!$F:$H,3,FALSE),-VLOOKUP($C8&" "&AB$1,Results!$G:$H,2,FALSE)),"") | AC8: =IFERROR(IFERROR(VLOOKUP($C8&" "&AC$1,Results!$F:$H,3,FALSE),-VLOOKUP($C8&" "&AC$1,Results!$G:$H,2,FALSE)),"") -> -7 | AD8: =IFERROR(IFERROR(VLOOKUP($C8&" "&AD$1,Results!$F:$H,3,FALSE),-VLOOKUP($C8&" "&AD$1,Results!$G:$H,2,FALSE)),"") -> 20 | AE8: =IFERROR(IFERROR(VLOOKUP($C8&" "&AE$1,Results!$F:$H,3,FALSE),-VLOOKUP($C8&" "&AE$1,Results!$G:$H,2,FALSE)),"") -> 59 | AF8: =IFERROR(IFERROR(VLOOKUP($C8&" "&AF$1,Results!$F:$H,3,FALSE),-VLOOKUP($C8&" "&AF$1,Results!$G:$H,2,FALSE)),"") | ... AM8: =IFERROR(IFERROR(VLOOKUP($C8&" "&AM$1,Results!$F:$H,3,FALSE),-VLOOKUP($C8&" "&AM$1,Results!$G:$H,2,FALSE)),"") | BW8: =SUM(U8:BS8) -> -103 | BX8: =COUNTIF(E8:J8,1) -> 5 | BY8: =COUNTIF(E8:J8,0) -> 1 | BZ8: =COUNT(E8:J8) -> 6 | CA8: =+BX8/BZ8 -> 0.83333333 | CC8: =SUM(U8:BT8) -> -103 | CE8: 9 | CF8: =A8 -> 7 | CG8: =+CE8-CF8 -> 2
A9: 4 | B9: 6 | C9: Sunset Ridge | E9: =IF(AND(AA9>0,$A9<VLOOKUP(AA$1,$C:$L,10,FALSE)),1,IF(AND(AA9<0,$A9>VLOOKUP(AA$1,$C:$L,10,FALSE)),1,0)) -> 0 | F9: =IF(AND(AB9>0,$A9<VLOOKUP(AB$1,$C:$L,10,FALSE)),1,IF(AND(AB9<0,$A9>VLOOKUP(AB$1,$C:$L,10,FALSE)),1,0)) -> 1 | G9: =IF(AND(AC9>0,$A9<VLOOKUP(AC$1,$C:$L,10,FALSE)),1,IF(AND(AC9<0,$A9>VLOOKUP(AC$1,$C:$L,10,FALSE)),1,0)) -> 1 | H9: =IF(AND(AE9>0,$A9<VLOOKUP(AE$1,$C:$L,10,FALSE)),1,IF(AND(AE9<0,$A9>VLOOKUP(AE$1,$C:$L,10,FALSE)),1,0)) -> 1 | I9: =IF(AND(AF9>0,$A9<VLOOKUP(AF$1,$C:$L,10,FALSE)),1,IF(AND(AF9<0,$A9>VLOOKUP(AF$1,$C:$L,10,FALSE)),1,0)) -> 0 | J9: =IF(AND(AG9>0,$A9<VLOOKUP(AG$1,$C:$L,10,FALSE)),1,IF(AND(AG9<0,$A9>VLOOKUP(AG$1,$C:$L,10,FALSE)),1,0)) -> 1 | K9: Updated | L9: =B9 -> 6 | M9: 2 | N9: =COUNTIF($U9:$BT9,">0") -> 2 | O9: =COUNTIF($U9:$BT9,"<0") -> 2 | P9: =COUNTIF($U9:$BT9,"=0") -> 2 | Q9: =COUNTIF($AB9:$AE9,">0") -> 2 | R9: =COUNTIF($AB9:$AE9,"<0") -> 0 | S9: =COUNTIF($AB9:$AE9,"=0") -> 1 | T9: =COUNTIF(U9:BU9,"NC") -> 0 | X9: =IFERROR(IFERROR(VLOOKUP($C9&" "&X$1,Results!$F:$H,3,FALSE),-VLOOKUP($C9&" "&X$1,Results!$G:$H,2,FALSE)),"") | Y9: =IFERROR(IFERROR(VLOOKUP($C9&" "&Y$1,Results!$F:$H,3,FALSE),-VLOOKUP($C9&" "&Y$1,Results!$G:$H,2,FALSE)),"") | Z9: =IFERROR(IFERROR(VLOOKUP($C9&" "&Z$1,Results!$F:$H,3,FALSE),-VLOOKUP($C9&" "&Z$1,Results!$G:$H,2,FALSE)),"") -> -180 | AA9: =IFERROR(IFERROR(VLOOKUP($C9&" "&AA$1,Results!$F:$H,3,FALSE),-VLOOKUP($C9&" "&AA$1,Results!$G:$H,2,FALSE)),"") -> -109 | AB9: =IFERROR(IFERROR(VLOOKUP($C9&" "&AB$1,Results!$F:$H,3,FALSE),-VLOOKUP($C9&" "&AB$1,Results!$G:$H,2,FALSE)),"") -> 7 | AC9: =IFERROR(IFERROR(VLOOKUP($C9&" "&AC$1,Results!$F:$H,3,FALSE),-VLOOKUP($C9&" "&AC$1,Results!$G:$H,2,FALSE)),"") | AD9: =IFERROR(IFERROR(VLOOKUP($C9&" "&AD$1,Results!$F:$H,3,FALSE),-VLOOKUP($C9&" "&AD$1,Results!$G:$H,2,FALSE)),"") -> 0 | AE9: =IFERROR(IFERROR(VLOOKUP($C9&" "&AE$1,Results!$F:$H,3,FALSE),-VLOOKUP($C9&" "&AE$1,Results!$G:$H,2,FALSE)),"") -> 58 | ... AI9: =IFERROR(IFERROR(VLOOKUP($C9&" "&AI$1,Results!$F:$H,3,FALSE),-VLOOKUP($C9&" "&AI$1,Results!$G:$H,2,FALSE)),"") | BW9: =SUM(U9:BS9) -> -224 | BX9: =COUNTIF(E9:J9,1) -> 4 | BY9: =COUNTIF(E9:J9,0) -> 2 | BZ9: =COUNT(E9:J9) -> 6 | CA9: =+BX9/BZ9 -> 0.66666667 | CC9: =SUM(U9:BT9) -> -224 | CE9: 11 | CF9: =A9 -> 4 | CG9: =+CE9-CF9 -> 7
A10: 9 | B10: 7 | C10: Abbington | E10: =IF(AND(Y10>0,$A10<VLOOKUP(Y$1,$C:$L,10,FALSE)),1,IF(AND(Y10<0,$A10>VLOOKUP(Y$1,$C:$L,10,FALSE)),1,0)) -> 0 | F10: =IF(AND(Z10>0,$A10<VLOOKUP(Z$1,$C:$L,10,FALSE)),1,IF(AND(Z10<0,$A10>VLOOKUP(Z$1,$C:$L,10,FALSE)),1,0)) -> 0 | G10: =IF(AND(AA10>0,$A10<VLOOKUP(AA$1,$C:$L,10,FALSE)),1,IF(AND(AA10<0,$A10>VLOOKUP(AA$1,$C:$L,10,FALSE)),1,0)) -> 0 | H10: =IF(AND(AC10>0,$A10<VLOOKUP(AC$1,$C:$L,10,FALSE)),1,IF(AND(AC10<0,$A10>VLOOKUP(AC$1,$C:$L,10,FALSE)),1,0)) -> 0 | I10: =IF(AND(AD10>0,$A10<VLOOKUP(AD$1,$C:$L,10,FALSE)),1,IF(AND(AD10<0,$A10>VLOOKUP(AD$1,$C:$L,10,FALSE)),1,0)) -> 0 | J10: =IF(AND(AE10>0,$A10<VLOOKUP(AE$1,$C:$L,10,FALSE)),1,IF(AND(AE10<0,$A10>VLOOKUP(AE$1,$C:$L,10,FALSE)),1,0)) -> 0 | K10: Updated | L10: =B10 -> 7 | M10: 2 | N10: =COUNTIF($U10:$BT10,">0") -> 3 | O10: =COUNTIF($U10:$BT10,"<0") -> 2 | P10: =COUNTIF($U10:$BT10,"=0") -> 1 | Q10: =COUNTIF($AB10:$AE10,">0") -> 1 | R10: =COUNTIF($AB10:$AE10,"<0") -> 1 | S10: =COUNTIF($AB10:$AE10,"=0") -> 1 | T10: =COUNTIF(U10:BU10,"NC") -> 0 | X10: =IFERROR(IFERROR(VLOOKUP($C10&" "&X$1,Results!$F:$H,3,FALSE),-VLOOKUP($C10&" "&X$1,Results!$G:$H,2,FALSE)),"") | Y10: =IFERROR(IFERROR(VLOOKUP($C10&" "&Y$1,Results!$F:$H,3,FALSE),-VLOOKUP($C10&" "&Y$1,Results!$G:$H,2,FALSE)),"") | Z10: =IFERROR(IFERROR(VLOOKUP($C10&" "&Z$1,Results!$F:$H,3,FALSE),-VLOOKUP($C10&" "&Z$1,Results!$G:$H,2,FALSE)),"") | AA10: =IFERROR(IFERROR(VLOOKUP($C10&" "&AA$1,Results!$F:$H,3,FALSE),-VLOOKUP($C10&" "&AA$1,Results!$G:$H,2,FALSE)),"") -> 66 | AB10: =IFERROR(IFERROR(VLOOKUP($C10&" "&AB$1,Results!$F:$H,3,FALSE),-VLOOKUP($C10&" "&AB$1,Results!$G:$H,2,FALSE)),"") -> -20 | AC10: =IFERROR(IFERROR(VLOOKUP($C10&" "&AC$1,Results!$F:$H,3,FALSE),-VLOOKUP($C10&" "&AC$1,Results!$G:$H,2,FALSE)),"") -> 0 | AD10: =IFERROR(IFERROR(VLOOKUP($C10&" "&AD$1,Results!$F:$H,3,FALSE),-VLOOKUP($C10&" "&AD$1,Results!$G:$H,2,FALSE)),"") | AE10: =IFERROR(IFERROR(VLOOKUP($C10&" "&AE$1,Results!$F:$H,3,FALSE),-VLOOKUP($C10&" "&AE$1,Results!$G:$H,2,FALSE)),"") -> 95 | ... AI10: =IFERROR(IFERROR(VLOOKUP($C10&" "&AI$1,Results!$F:$H,3,FALSE),-VLOOKUP($C10&" "&AI$1,Results!$G:$H,2,FALSE)),"") | BW10: =SUM(U10:BS10) -> 170 | BX10: =COUNTIF(E10:J10,1) -> 0 | BY10: =COUNTIF(E10:J10,0) -> 6 | BZ10: =COUNT(E10:J10) -> 6 | CA10: =+BX10/BZ10 -> 0 | CC10: =SUM(U10:BT10) -> 170 | CE10: 3 | CF10: =A10 -> 9 | CG10: =+CE10-CF10 -> -6
A11: 13 | B11: 8 | C11: Prestonwood | H11: =IF(AND(Y11>0,$A11<VLOOKUP(Y$1,$C:$L,10,FALSE)),1,IF(AND(Y11<0,$A11>VLOOKUP(Y$1,$C:$L,10,FALSE)),1,0)) -> 0 | I11: =IF(AND(Z11>0,$A11<VLOOKUP(Z$1,$C:$L,10,FALSE)),1,IF(AND(Z11<0,$A11>VLOOKUP(Z$1,$C:$L,10,FALSE)),1,0)) -> 0 | J11: =IF(AND(AA11>0,$A11<VLOOKUP(AA$1,$C:$L,10,FALSE)),1,IF(AND(AA11<0,$A11>VLOOKUP(AA$1,$C:$L,10,FALSE)),1,0)) -> 0 | K11: Updated | L11: =B11 -> 8 | M11: 2 | N11: =COUNTIF($U11:$BT11,">0") -> 0 | O11: =COUNTIF($U11:$BT11,"<0") -> 6 | P11: =COUNTIF($U11:$BT11,"=0") -> 0 | Q11: =COUNTIF($AB11:$AE11,">0") -> 0 | R11: =COUNTIF($AB11:$AE11,"<0") -> 3 | S11: =COUNTIF($AB11:$AE11,"=0") -> 0 | T11: =COUNTIF(U11:BU11,"NC") -> 0 | U11: =IFERROR(IFERROR(VLOOKUP($C11&" "&U$1,Results!$F:$H,3,FALSE),-VLOOKUP($C11&" "&U$1,Results!$G:$H,2,FALSE)),"") | V11: =IFERROR(IFERROR(VLOOKUP($C11&" "&V$1,Results!$F:$H,3,FALSE),-VLOOKUP($C11&" "&V$1,Results!$G:$H,2,FALSE)),"") | W11: =IFERROR(IFERROR(VLOOKUP($C11&" "&W$1,Results!$F:$H,3,FALSE),-VLOOKUP($C11&" "&W$1,Results!$G:$H,2,FALSE)),"") | X11: =IFERROR(IFERROR(VLOOKUP($C11&" "&X$1,Results!$F:$H,3,FALSE),-VLOOKUP($C11&" "&X$1,Results!$G:$H,2,FALSE)),"") | Y11: =IFERROR(IFERROR(VLOOKUP($C11&" "&Y$1,Results!$F:$H,3,FALSE),-VLOOKUP($C11&" "&Y$1,Results!$G:$H,2,FALSE)),"") | Z11: =IFERROR(IFERROR(VLOOKUP($C11&" "&Z$1,Results!$F:$H,3,FALSE),-VLOOKUP($C11&" "&Z$1,Results!$G:$H,2,FALSE)),"") | AA11: =IFERROR(IFERROR(VLOOKUP($C11&" "&AA$1,Results!$F:$H,3,FALSE),-VLOOKUP($C11&" "&AA$1,Results!$G:$H,2,FALSE)),"") | AB11: =IFERROR(IFERROR(VLOOKUP($C11&" "&AB$1,Results!$F:$H,3,FALSE),-VLOOKUP($C11&" "&AB$1,Results!$G:$H,2,FALSE)),"") -> -59 | ... AH11: =IFERROR(IFERROR(VLOOKUP($C11&" "&AH$1,Results!$F:$H,3,FALSE),-VLOOKUP($C11&" "&AH$1,Results!$G:$H,2,FALSE)),"") -> -94 | BW11: =SUM(U11:BS11) -> -381 | BX11: =COUNTIF(E11:J11,1) -> 0 | BY11: =COUNTIF(E11:J11,0) -> 3 | BZ11: =COUNT(E11:J11) -> 3 | CA11: =+BX11/BZ11 -> 0 | CC11: =SUM(U11:BT11) -> -381 | CE11: 2 | CF11: =A11 -> 13 | CG11: =+CE11-CF11 -> -11
A12: 8 | B12: 9 | C12: Dutchman Downs | E12: =IF(AND(AF12>0,$A12<VLOOKUP(AF$1,$C:$L,10,FALSE)),1,IF(AND(AF12<0,$A12>VLOOKUP(AF$1,$C:$L,10,FALSE)),1,0)) -> 1 | F12: =IF(AND(AG12>0,$A12<VLOOKUP(AG$1,$C:$L,10,FALSE)),1,IF(AND(AG12<0,$A12>VLOOKUP(AG$1,$C:$L,10,FALSE)),1,0)) -> 1 | G12: =IF(AND(AH12>0,$A12<VLOOKUP(AH$1,$C:$L,10,FALSE)),1,IF(AND(AH12<0,$A12>VLOOKUP(AH$1,$C:$L,10,FALSE)),1,0)) -> 0 | H12: =IF(AND(AJ12>0,$A12<VLOOKUP(AJ$1,$C:$L,10,FALSE)),1,IF(AND(AJ12<0,$A12>VLOOKUP(AJ$1,$C:$L,10,FALSE)),1,0)) -> 1 | I12: =IF(AND(AK12>0,$A12<VLOOKUP(AK$1,$C:$L,10,FALSE)),1,IF(AND(AK12<0,$A12>VLOOKUP(AK$1,$C:$L,10,FALSE)),1,0)) -> 1 | J12: =IF(AND(AL12>0,$A12<VLOOKUP(AL$1,$C:$L,10,FALSE)),1,IF(AND(AL12<0,$A12>VLOOKUP(AL$1,$C:$L,10,FALSE)),1,0)) -> 1 | K12: Updated | L12: =B12 -> 9 | M12: 3 | N12: =COUNTIF($U12:$BT12,">0") -> 4 | O12: =COUNTIF($U12:$BT12,"<0") -> 1 | P12: =COUNTIF($U12:$BT12,"=0") -> 1 | Q12: =COUNTIF($AF12:$AI12,">0") -> 2 | R12: =COUNTIF($AF12:$AI12,"<0") -> 1 | S12: =COUNTIF($AF12:$AI12,"=0") -> 0 | T12: =COUNTIF(U12:BU12,"NC") -> 0 | AB12: =IFERROR(IFERROR(VLOOKUP($C12&" "&AB$1,Results!$F:$H,3,FALSE),-VLOOKUP($C12&" "&AB$1,Results!$G:$H,2,FALSE)),"") | AC12: =IFERROR(IFERROR(VLOOKUP($C12&" "&AC$1,Results!$F:$H,3,FALSE),-VLOOKUP($C12&" "&AC$1,Results!$G:$H,2,FALSE)),"") -> 0 | AD12: =IFERROR(IFERROR(VLOOKUP($C12&" "&AD$1,Results!$F:$H,3,FALSE),-VLOOKUP($C12&" "&AD$1,Results!$G:$H,2,FALSE)),"") -> 32 | AE12: =IFERROR(IFERROR(VLOOKUP($C12&" "&AE$1,Results!$F:$H,3,FALSE),-VLOOKUP($C12&" "&AE$1,Results!$G:$H,2,FALSE)),"") -> 61 | AF12: =IFERROR(IFERROR(VLOOKUP($C12&" "&AF$1,Results!$F:$H,3,FALSE),-VLOOKUP($C12&" "&AF$1,Results!$G:$H,2,FALSE)),"") | AG12: =IFERROR(IFERROR(VLOOKUP($C12&" "&AG$1,Results!$F:$H,3,FALSE),-VLOOKUP($C12&" "&AG$1,Results!$G:$H,2,FALSE)),"") -> 31 | AH12: =IFERROR(IFERROR(VLOOKUP($C12&" "&AH$1,Results!$F:$H,3,FALSE),-VLOOKUP($C12&" "&AH$1,Results!$G:$H,2,FALSE)),"") -> -34 | AI12: =IFERROR(IFERROR(VLOOKUP($C12&" "&AI$1,Results!$F:$H,3,FALSE),-VLOOKUP($C12&" "&AI$1,Results!$G:$H,2,FALSE)),"") -> 30 | ... AM12: =IFERROR(IFERROR(VLOOKUP($C12&" "&AM$1,Results!$F:$H,3,FALSE),-VLOOKUP($C12&" "&AM$1,Results!$G:$H,2,FALSE)),"") | BW12: =SUM(U12:BS12) -> 120 | BX12: =COUNTIF(E12:J12,1) -> 5 | BY12: =COUNTIF(E12:J12,0) -> 1 | BZ12: =COUNT(E12:J12) -> 6 | CA12: =+BX12/BZ12 -> 0.83333333 | CC12: =SUM(U12:BT12) -> 120 | CE12: 14 | CF12: =A12 -> 8 | CG12: =+CE12-CF12 -> 6
A13: 12 | B13: 10 | C13: Lochmere | E13: =IF(AND(AG13>0,$A13<VLOOKUP(AG$1,$C:$L,10,FALSE)),1,IF(AND(AG13<0,$A13>VLOOKUP(AG$1,$C:$L,10,FALSE)),1,0)) -> 0 | F13: =IF(AND(AH13>0,$A13<VLOOKUP(AH$1,$C:$L,10,FALSE)),1,IF(AND(AH13<0,$A13>VLOOKUP(AH$1,$C:$L,10,FALSE)),1,0)) -> 0 | G13: =IF(AND(AI13>0,$A13<VLOOKUP(AI$1,$C:$L,10,FALSE)),1,IF(AND(AI13<0,$A13>VLOOKUP(AI$1,$C:$L,10,FALSE)),1,0)) -> 0 | H13: =IF(AND(AK13>0,$A13<VLOOKUP(AK$1,$C:$L,10,FALSE)),1,IF(AND(AK13<0,$A13>VLOOKUP(AK$1,$C:$L,10,FALSE)),1,0)) -> 1 | I13: =IF(AND(AL13>0,$A13<VLOOKUP(AL$1,$C:$L,10,FALSE)),1,IF(AND(AL13<0,$A13>VLOOKUP(AL$1,$C:$L,10,FALSE)),1,0)) -> 1 | J13: =IF(AND(AM13>0,$A13<VLOOKUP(AM$1,$C:$L,10,FALSE)),1,IF(AND(AM13<0,$A13>VLOOKUP(AM$1,$C:$L,10,FALSE)),1,0)) -> 1 | K13: Updated | L13: =B13 -> 10 | M13: 3 | N13: =COUNTIF($U13:$BT13,">0") -> 3 | O13: =COUNTIF($U13:$BT13,"<0") -> 3 | P13: =COUNTIF($U13:$BT13,"=0") -> 0 | Q13: =COUNTIF($AF13:$AI13,">0") -> 2 | R13: =COUNTIF($AF13:$AI13,"<0") -> 1 | S13: =COUNTIF($AF13:$AI13,"=0") -> 0 | T13: =COUNTIF(U13:BU13,"NC") -> 0 | AD13: =IFERROR(IFERROR(VLOOKUP($C13&" "&AD$1,Results!$F:$H,3,FALSE),-VLOOKUP($C13&" "&AD$1,Results!$G:$H,2,FALSE)),"") -> -61 | AE13: =IFERROR(IFERROR(VLOOKUP($C13&" "&AE$1,Results!$F:$H,3,FALSE),-VLOOKUP($C13&" "&AE$1,Results!$G:$H,2,FALSE)),"") -> 14 | AF13: =IFERROR(IFERROR(VLOOKUP($C13&" "&AF$1,Results!$F:$H,3,FALSE),-VLOOKUP($C13&" "&AF$1,Results!$G:$H,2,FALSE)),"") -> -31 | AG13: =IFERROR(IFERROR(VLOOKUP($C13&" "&AG$1,Results!$F:$H,3,FALSE),-VLOOKUP($C13&" "&AG$1,Results!$G:$H,2,FALSE)),"") | AH13: =IFERROR(IFERROR(VLOOKUP($C13&" "&AH$1,Results!$F:$H,3,FALSE),-VLOOKUP($C13&" "&AH$1,Results!$G:$H,2,FALSE)),"") -> 49 | AI13: =IFERROR(IFERROR(VLOOKUP($C13&" "&AI$1,Results!$F:$H,3,FALSE),-VLOOKUP($C13&" "&AI$1,Results!$G:$H,2,FALSE)),"") -> 24 | AJ13: =IFERROR(IFERROR(VLOOKUP($C13&" "&AJ$1,Results!$F:$H,3,FALSE),-VLOOKUP($C13&" "&AJ$1,Results!$G:$H,2,FALSE)),"") -> -91 | AK13: =IFERROR(IFERROR(VLOOKUP($C13&" "&AK$1,Results!$F:$H,3,FALSE),-VLOOKUP($C13&" "&AK$1,Results!$G:$H,2,FALSE)),"") | ... BC13: =IFERROR(IFERROR(VLOOKUP($C13&" "&BC$1,Results!$F:$H,3,FALSE),-VLOOKUP($C13&" "&BC$1,Results!$G:$H,2,FALSE)),"") | BW13: =SUM(U13:BS13) -> -96 | BX13: =COUNTIF(E13:J13,1) -> 3 | BY13: =COUNTIF(E13:J13,0) -> 3 | BZ13: =COUNT(E13:J13) -> 6 | CA13: =+BX13/BZ13 -> 0.5 | CC13: =SUM(U13:BT13) -> -96 | CE13: 8 | CF13: =A13 -> 12 | CG13: =+CE13-CF13 -> -4
A14: 6 | B14: 11 | C14: Shepherds Vineyard | E14: =IF(AND(AD14>0,$A14<VLOOKUP(AD$1,$C:$L,10,FALSE)),1,IF(AND(AD14<0,$A14>VLOOKUP(AD$1,$C:$L,10,FALSE)),1,0)) -> 1 | F14: =IF(AND(AE14>0,$A14<VLOOKUP(AE$1,$C:$L,10,FALSE)),1,IF(AND(AE14<0,$A14>VLOOKUP(AE$1,$C:$L,10,FALSE)),1,0)) -> 1 | G14: =IF(AND(AF14>0,$A14<VLOOKUP(AF$1,$C:$L,10,FALSE)),1,IF(AND(AF14<0,$A14>VLOOKUP(AF$1,$C:$L,10,FALSE)),1,0)) -> 1 | H14: =IF(AND(AH14>0,$A14<VLOOKUP(AH$1,$C:$L,10,FALSE)),1,IF(AND(AH14<0,$A14>VLOOKUP(AH$1,$C:$L,10,FALSE)),1,0)) -> 1 | I14: =IF(AND(AI14>0,$A14<VLOOKUP(AI$1,$C:$L,10,FALSE)),1,IF(AND(AI14<0,$A14>VLOOKUP(AI$1,$C:$L,10,FALSE)),1,0)) -> 1 | J14: =IF(AND(AJ14>0,$A14<VLOOKUP(AJ$1,$C:$L,10,FALSE)),1,IF(AND(AJ14<0,$A14>VLOOKUP(AJ$1,$C:$L,10,FALSE)),1,0)) -> 1 | K14: Updated | L14: =B14 -> 11 | M14: 3 | N14: =COUNTIF($U14:$BT14,">0") -> 5 | O14: =COUNTIF($U14:$BT14,"<0") -> 1 | P14: =COUNTIF($U14:$BT14,"=0") -> 0 | Q14: =COUNTIF($AF14:$AI14,">0") -> 2 | R14: =COUNTIF($AF14:$AI14,"<0") -> 1 | S14: =COUNTIF($AB14:$AF14,"=0") -> 0 | T14: =COUNTIF(U14:BU14,"NC") -> 0 | AB14: =IFERROR(IFERROR(VLOOKUP($C14&" "&AB$1,Results!$F:$H,3,FALSE),-VLOOKUP($C14&" "&AB$1,Results!$G:$H,2,FALSE)),"") | AC14: =IFERROR(IFERROR(VLOOKUP($C14&" "&AC$1,Results!$F:$H,3,FALSE),-VLOOKUP($C14&" "&AC$1,Results!$G:$H,2,FALSE)),"") | AD14: =IFERROR(IFERROR(VLOOKUP($C14&" "&AD$1,Results!$F:$H,3,FALSE),-VLOOKUP($C14&" "&AD$1,Results!$G:$H,2,FALSE)),"") | AE14: =IFERROR(IFERROR(VLOOKUP($C14&" "&AE$1,Results!$F:$H,3,FALSE),-VLOOKUP($C14&" "&AE$1,Results!$G:$H,2,FALSE)),"") -> 94 | AF14: =IFERROR(IFERROR(VLOOKUP($C14&" "&AF$1,Results!$F:$H,3,FALSE),-VLOOKUP($C14&" "&AF$1,Results!$G:$H,2,FALSE)),"") -> 34 | AG14: =IFERROR(IFERROR(VLOOKUP($C14&" "&AG$1,Results!$F:$H,3,FALSE),-VLOOKUP($C14&" "&AG$1,Results!$G:$H,2,FALSE)),"") -> -49 | AH14: =IFERROR(IFERROR(VLOOKUP($C14&" "&AH$1,Results!$F:$H,3,FALSE),-VLOOKUP($C14&" "&AH$1,Results!$G:$H,2,FALSE)),"") | AI14: =IFERROR(IFERROR(VLOOKUP($C14&" "&AI$1,Results!$F:$H,3,FALSE),-VLOOKUP($C14&" "&AI$1,Results!$G:$H,2,FALSE)),"") -> 72 | ... AM14: =IFERROR(IFERROR(VLOOKUP($C14&" "&AM$1,Results!$F:$H,3,FALSE),-VLOOKUP($C14&" "&AM$1,Results!$G:$H,2,FALSE)),"") | BW14: =SUM(U14:BS14) -> 493 | BX14: =COUNTIF(E14:J14,1) -> 6 | BY14: =COUNTIF(E14:J14,0) -> 0 | BZ14: =COUNT(E14:J14) -> 6 | CA14: =+BX14/BZ14 -> 1 | CC14: =SUM(U14:BT14) -> 493 | CE14: 10 | CF14: =A14 -> 6 | CG14: =+CE14-CF14 -> 4
A15: 15 | B15: 12 | C15: Olive Chapel | E15: =IF(AND(AB15>0,$A15<VLOOKUP(AB$1,$C:$L,10,FALSE)),1,IF(AND(AB15<0,$A15>VLOOKUP(AB$1,$C:$L,10,FALSE)),1,0)) -> 0 | F15: =IF(AND(AC15>0,$A15<VLOOKUP(AC$1,$C:$L,10,FALSE)),1,IF(AND(AC15<0,$A15>VLOOKUP(AC$1,$C:$L,10,FALSE)),1,0)) -> 0 | G15: =IF(AND(AD15>0,$A15<VLOOKUP(AD$1,$C:$L,10,FALSE)),1,IF(AND(AD15<0,$A15>VLOOKUP(AD$1,$C:$L,10,FALSE)),1,0)) -> 0 | H15: =IF(AND(AF15>0,$A15<VLOOKUP(AF$1,$C:$L,10,FALSE)),1,IF(AND(AF15<0,$A15>VLOOKUP(AF$1,$C:$L,10,FALSE)),1,0)) -> 1 | I15: =IF(AND(AG15>0,$A15<VLOOKUP(AG$1,$C:$L,10,FALSE)),1,IF(AND(AG15<0,$A15>VLOOKUP(AG$1,$C:$L,10,FALSE)),1,0)) -> 1 | J15: =IF(AND(AH15>0,$A15<VLOOKUP(AH$1,$C:$L,10,FALSE)),1,IF(AND(AH15<0,$A15>VLOOKUP(AH$1,$C:$L,10,FALSE)),1,0)) -> 1 | K15: Updated | L15: =B15 -> 12 | M15: 3 | N15: =COUNTIF($U15:$BT15,">0") -> 1 | O15: =COUNTIF($U15:$BT15,"<0") -> 5 | P15: =COUNTIF($U15:$BT15,"=0") -> 0 | Q15: =COUNTIF($AF15:$AI15,">0") -> 0 | R15: =COUNTIF($AF15:$AI15,"<0") -> 3 | S15: =COUNTIF($AF15:$AI15,"=0") -> 0 | T15: =COUNTIF(U15:BU15,"NC") -> 0 | X15: =IFERROR(IFERROR(VLOOKUP($C15&" "&X$1,Results!$F:$H,3,FALSE),-VLOOKUP($C15&" "&X$1,Results!$G:$H,2,FALSE)),"") | Y15: =IFERROR(IFERROR(VLOOKUP($C15&" "&Y$1,Results!$F:$H,3,FALSE),-VLOOKUP($C15&" "&Y$1,Results!$G:$H,2,FALSE)),"") | Z15: =IFERROR(IFERROR(VLOOKUP($C15&" "&Z$1,Results!$F:$H,3,FALSE),-VLOOKUP($C15&" "&Z$1,Results!$G:$H,2,FALSE)),"") | AA15: =IFERROR(IFERROR(VLOOKUP($C15&" "&AA$1,Results!$F:$H,3,FALSE),-VLOOKUP($C15&" "&AA$1,Results!$G:$H,2,FALSE)),"") | AB15: =IFERROR(IFERROR(VLOOKUP($C15&" "&AB$1,Results!$F:$H,3,FALSE),-VLOOKUP($C15&" "&AB$1,Results!$G:$H,2,FALSE)),"") | AC15: =IFERROR(IFERROR(VLOOKUP($C15&" "&AC$1,Results!$F:$H,3,FALSE),-VLOOKUP($C15&" "&AC$1,Results!$G:$H,2,FALSE)),"") | AD15: =IFERROR(IFERROR(VLOOKUP($C15&" "&AD$1,Results!$F:$H,3,FALSE),-VLOOKUP($C15&" "&AD$1,Results!$G:$H,2,FALSE)),"") | AE15: =IFERROR(IFERROR(VLOOKUP($C15&" "&AE$1,Results!$F:$H,3,FALSE),-VLOOKUP($C15&" "&AE$1,Results!$G:$H,2,FALSE)),"") | ... AM15: =IFERROR(IFERROR(VLOOKUP($C15&" "&AM$1,Results!$F:$H,3,FALSE),-VLOOKUP($C15&" "&AM$1,Results!$G:$H,2,FALSE)),"") | BW15: =SUM(U15:BS15) -> -46 | BX15: =COUNTIF(E15:J15,1) -> 3 | BY15: =COUNTIF(E15:J15,0) -> 3 | BZ15: =COUNT(E15:J15) -> 6 | CA15: =+BX15/BZ15 -> 0.5 | CC15: =SUM(U15:BT15) -> -46 | CE15: 5 | CF15: =A15 -> 15 | CG15: =+CE15-CF15 -> -10
A16: 11 | B16: 13 | C16: Preston Village | E16: =IF(AND(AL16>0,$A16<VLOOKUP(AL$1,$C:$L,10,FALSE)),1,IF(AND(AL16<0,$A16>VLOOKUP(AL$1,$C:$L,10,FALSE)),1,0)) -> 0 | F16: =IF(AND(AM16>0,$A16<VLOOKUP(AM$1,$C:$L,10,FALSE)),1,IF(AND(AM16<0,$A16>VLOOKUP(AM$1,$C:$L,10,FALSE)),1,0)) -> 1 | G16: =IF(AND(AN16>0,$A16<VLOOKUP(AN$1,$C:$L,10,FALSE)),1,IF(AND(AN16<0,$A16>VLOOKUP(AN$1,$C:$L,10,FALSE)),1,0)) -> 1 | H16: =IF(AND(AP16>0,$A16<VLOOKUP(AP$1,$C:$L,10,FALSE)),1,IF(AND(AP16<0,$A16>VLOOKUP(AP$1,$C:$L,10,FALSE)),1,0)) -> 1 | I16: =IF(AND(AQ16>0,$A16<VLOOKUP(AQ$1,$C:$L,10,FALSE)),1,IF(AND(AQ16<0,$A16>VLOOKUP(AQ$1,$C:$L,10,FALSE)),1,0)) -> 1 | J16: =IF(AND(AR16>0,$A16<VLOOKUP(AR$1,$C:$L,10,FALSE)),1,IF(AND(AR16<0,$A16>VLOOKUP(AR$1,$C:$L,10,FALSE)),1,0)) -> 1 | K16: Updated | L16: =B16 -> 13 | M16: 4 | N16: =COUNTIF($U16:$BT16,">0") -> 4 | O16: =COUNTIF($U16:$BT16,"<0") -> 2 | P16: =COUNTIF($U16:$BT16,"=0") -> 0 | Q16: =COUNTIF($AJ16:$AM16,">0") -> 2 | R16: =COUNTIF($AJ16:$AM16,"<0") -> 1 | S16: =COUNTIF($AJ16:$AM16,"=0") -> 0 | T16: =COUNTIF(U16:BU16,"NC") -> 0 | AF16: =IFERROR(IFERROR(VLOOKUP($C16&" "&AF$1,Results!$F:$H,3,FALSE),-VLOOKUP($C16&" "&AF$1,Results!$G:$H,2,FALSE)),"") | AG16: =IFERROR(IFERROR(VLOOKUP($C16&" "&AG$1,Results!$F:$H,3,FALSE),-VLOOKUP($C16&" "&AG$1,Results!$G:$H,2,FALSE)),"") -> 91 | AH16: =IFERROR(IFERROR(VLOOKUP($C16&" "&AH$1,Results!$F:$H,3,FALSE),-VLOOKUP($C16&" "&AH$1,Results!$G:$H,2,FALSE)),"") -> -92 | AI16: =IFERROR(IFERROR(VLOOKUP($C16&" "&AI$1,Results!$F:$H,3,FALSE),-VLOOKUP($C16&" "&AI$1,Results!$G:$H,2,FALSE)),"") -> 11 | AJ16: =IFERROR(IFERROR(VLOOKUP($C16&" "&AJ$1,Results!$F:$H,3,FALSE),-VLOOKUP($C16&" "&AJ$1,Results!$G:$H,2,FALSE)),"") | AK16: =IFERROR(IFERROR(VLOOKUP($C16&" "&AK$1,Results!$F:$H,3,FALSE),-VLOOKUP($C16&" "&AK$1,Results!$G:$H,2,FALSE)),"") -> 7 | AL16: =IFERROR(IFERROR(VLOOKUP($C16&" "&AL$1,Results!$F:$H,3,FALSE),-VLOOKUP($C16&" "&AL$1,Results!$G:$H,2,FALSE)),"") -> -84 | AM16: =IFERROR(IFERROR(VLOOKUP($C16&" "&AM$1,Results!$F:$H,3,FALSE),-VLOOKUP($C16&" "&AM$1,Results!$G:$H,2,FALSE)),"") -> 107 | ... BC16: =IFERROR(IFERROR(VLOOKUP($C16&" "&BC$1,Results!$F:$H,3,FALSE),-VLOOKUP($C16&" "&BC$1,Results!$G:$H,2,FALSE)),"") | BW16: =SUM(U16:BS16) -> 40 | BX16: =COUNTIF(E16:J16,1) -> 5 | BY16: =COUNTIF(E16:J16,0) -> 1 | BZ16: =COUNT(E16:J16) -> 6 | CA16: =+BX16/BZ16 -> 0.83333333 | CC16: =SUM(U16:BT16) -> 40 | CE16: 18 | CF16: =A16 -> 11 | CG16: =+CE16-CF16 -> 7
A17: 20 | B17: 14 | C17: Walden Creek | E17: =IF(AND(AE17>0,$A17<VLOOKUP(AE$1,$C:$L,10,FALSE)),1,IF(AND(AE17<0,$A17>VLOOKUP(AE$1,$C:$L,10,FALSE)),1,0)) -> 0 | F17: =IF(AND(AF17>0,$A17<VLOOKUP(AF$1,$C:$L,10,FALSE)),1,IF(AND(AF17<0,$A17>VLOOKUP(AF$1,$C:$L,10,FALSE)),1,0)) -> 0 | G17: =IF(AND(AG17>0,$A17<VLOOKUP(AG$1,$C:$L,10,FALSE)),1,IF(AND(AG17<0,$A17>VLOOKUP(AG$1,$C:$L,10,FALSE)),1,0)) -> 0 | H17: =IF(AND(AI17>0,$A17<VLOOKUP(AI$1,$C:$L,10,FALSE)),1,IF(AND(AI17<0,$A17>VLOOKUP(AI$1,$C:$L,10,FALSE)),1,0)) -> 1 | I17: =IF(AND(AJ17>0,$A17<VLOOKUP(AJ$1,$C:$L,10,FALSE)),1,IF(AND(AJ17<0,$A17>VLOOKUP(AJ$1,$C:$L,10,FALSE)),1,0)) -> 1 | J17: =IF(AND(AK17>0,$A17<VLOOKUP(AK$1,$C:$L,10,FALSE)),1,IF(AND(AK17<0,$A17>VLOOKUP(AK$1,$C:$L,10,FALSE)),1,0)) -> 0 | K17: Updated | L17: =B17 -> 14 | M17: 4 | N17: =COUNTIF($U17:$BT17,">0") -> 0 | O17: =COUNTIF($U17:$BT17,"<0") -> 6 | P17: =COUNTIF($U17:$BT17,"=0") -> 0 | Q17: =COUNTIF($AJ17:$AM17,">0") -> 0 | R17: =COUNTIF($AJ17:$AM17,"<0") -> 3 | S17: =COUNTIF($AJ17:$AM17,"=0") -> 0 | T17: =COUNTIF(U17:BU17,"NC") -> 0 | AB17: =IFERROR(IFERROR(VLOOKUP($C17&" "&AB$1,Results!$F:$H,3,FALSE),-VLOOKUP($C17&" "&AB$1,Results!$G:$H,2,FALSE)),"") | AC17: =IFERROR(IFERROR(VLOOKUP($C17&" "&AC$1,Results!$F:$H,3,FALSE),-VLOOKUP($C17&" "&AC$1,Results!$G:$H,2,FALSE)),"") | AD17: =IFERROR(IFERROR(VLOOKUP($C17&" "&AD$1,Results!$F:$H,3,FALSE),-VLOOKUP($C17&" "&AD$1,Results!$G:$H,2,FALSE)),"") | AE17: =IFERROR(IFERROR(VLOOKUP($C17&" "&AE$1,Results!$F:$H,3,FALSE),-VLOOKUP($C17&" "&AE$1,Results!$G:$H,2,FALSE)),"") | AF17: =IFERROR(IFERROR(VLOOKUP($C17&" "&AF$1,Results!$F:$H,3,FALSE),-VLOOKUP($C17&" "&AF$1,Results!$G:$H,2,FALSE)),"") | AG17: =IFERROR(IFERROR(VLOOKUP($C17&" "&AG$1,Results!$F:$H,3,FALSE),-VLOOKUP($C17&" "&AG$1,Results!$G:$H,2,FALSE)),"") | AH17: =IFERROR(IFERROR(VLOOKUP($C17&" "&AH$1,Results!$F:$H,3,FALSE),-VLOOKUP($C17&" "&AH$1,Results!$G:$H,2,FALSE)),"") -> -250 | AI17: =IFERROR(IFERROR(VLOOKUP($C17&" "&AI$1,Results!$F:$H,3,FALSE),-VLOOKUP($C17&" "&AI$1,Results!$G:$H,2,FALSE)),"") -> -123 | ... AN17: =IFERROR(IFERROR(VLOOKUP($C17&" "&AN$1,Results!$F:$H,3,FALSE),-VLOOKUP($C17&" "&AN$1,Results!$G:$H,2,FALSE)),"") -> -175 | BW17: =SUM(U17:BS17) -> -843 | BX17: =COUNTIF(E17:J17,1) -> 2 | BY17: =COUNTIF(E17:J17,0) -> 4 | BZ17: =COUNT(E17:J17) -> 6 | CA17: =+BX17/BZ17 -> 0.33333333 | CC17: =SUM(U17:BT17) -> -843 | CE17: 6 | CF17: =A17 -> 20 | CG17: =+CE17-CF17 -> -14
A18: 10 | B18: 15 | C18: WoodCreek | E18: =IF(AND(AI18>0,$A18<VLOOKUP(AI$1,$C:$L,10,FALSE)),1,IF(AND(AI18<0,$A18>VLOOKUP(AI$1,$C:$L,10,FALSE)),1,0)) -> 1 | F18: =IF(AND(AJ18>0,$A18<VLOOKUP(AJ$1,$C:$L,10,FALSE)),1,IF(AND(AJ18<0,$A18>VLOOKUP(AJ$1,$C:$L,10,FALSE)),1,0)) -> 1 | G18: =IF(AND(AK18>0,$A18<VLOOKUP(AK$1,$C:$L,10,FALSE)),1,IF(AND(AK18<0,$A18>VLOOKUP(AK$1,$C:$L,10,FALSE)),1,0)) -> 1 | H18: =IF(AND(AM18>0,$A18<VLOOKUP(AM$1,$C:$L,10,FALSE)),1,IF(AND(AM18<0,$A18>VLOOKUP(AM$1,$C:$L,10,FALSE)),1,0)) -> 1 | I18: =IF(AND(AN18>0,$A18<VLOOKUP(AN$1,$C:$L,10,FALSE)),1,IF(AND(AN18<0,$A18>VLOOKUP(AN$1,$C:$L,10,FALSE)),1,0)) -> 1 | J18: =IF(AND(AO18>0,$A18<VLOOKUP(AO$1,$C:$L,10,FALSE)),1,IF(AND(AO18<0,$A18>VLOOKUP(AO$1,$C:$L,10,FALSE)),1,0)) -> 1 | K18: Updated | L18: =B18 -> 15 | M18: 4 | N18: =COUNTIF($U18:$BT18,">0") -> 6 | O18: =COUNTIF($U18:$BT18,"<0") -> 0 | P18: =COUNTIF($U18:$BT18,"=0") -> 0 | Q18: =COUNTIF($AJ18:$AM18,">0") -> 3 | R18: =COUNTIF($AJ18:$AM18,"<0") -> 0 | S18: =COUNTIF($AJ18:$AM18,"=0") -> 0 | T18: =COUNTIF(U18:BU18,"NC") -> 0 | AF18: =IFERROR(IFERROR(VLOOKUP($C18&" "&AF$1,Results!$F:$H,3,FALSE),-VLOOKUP($C18&" "&AF$1,Results!$G:$H,2,FALSE)),"") | AG18: =IFERROR(IFERROR(VLOOKUP($C18&" "&AG$1,Results!$F:$H,3,FALSE),-VLOOKUP($C18&" "&AG$1,Results!$G:$H,2,FALSE)),"") | AH18: =IFERROR(IFERROR(VLOOKUP($C18&" "&AH$1,Results!$F:$H,3,FALSE),-VLOOKUP($C18&" "&AH$1,Results!$G:$H,2,FALSE)),"") | AI18: =IFERROR(IFERROR(VLOOKUP($C18&" "&AI$1,Results!$F:$H,3,FALSE),-VLOOKUP($C18&" "&AI$1,Results!$G:$H,2,FALSE)),"") -> 32 | AJ18: =IFERROR(IFERROR(VLOOKUP($C18&" "&AJ$1,Results!$F:$H,3,FALSE),-VLOOKUP($C18&" "&AJ$1,Results!$G:$H,2,FALSE)),"") -> 84 | AK18: =IFERROR(IFERROR(VLOOKUP($C18&" "&AK$1,Results!$F:$H,3,FALSE),-VLOOKUP($C18&" "&AK$1,Results!$G:$H,2,FALSE)),"") -> 212 | AL18: =IFERROR(IFERROR(VLOOKUP($C18&" "&AL$1,Results!$F:$H,3,FALSE),-VLOOKUP($C18&" "&AL$1,Results!$G:$H,2,FALSE)),"") | AM18: =IFERROR(IFERROR(VLOOKUP($C18&" "&AM$1,Results!$F:$H,3,FALSE),-VLOOKUP($C18&" "&AM$1,Results!$G:$H,2,FALSE)),"") -> 84 | ... BC18: =IFERROR(IFERROR(VLOOKUP($C18&" "&BC$1,Results!$F:$H,3,FALSE),-VLOOKUP($C18&" "&BC$1,Results!$G:$H,2,FALSE)),"") | BW18: =SUM(U18:BS18) -> 612 | BX18: =COUNTIF(E18:J18,1) -> 6 | BY18: =COUNTIF(E18:J18,0) -> 0 | BZ18: =COUNT(E18:J18) -> 6 | CA18: =+BX18/BZ18 -> 1 | CC18: =SUM(U18:BT18) -> 612 | CE18: 21 | CF18: =A18 -> 10 | CG18: =+CE18-CF18 -> 11
A19: 18 | B19: 16 | C19: Silverton | E19: =IF(AND(AJ19>0,$A19<VLOOKUP(AJ$1,$C:$L,10,FALSE)),1,IF(AND(AJ19<0,$A19>VLOOKUP(AJ$1,$C:$L,10,FALSE)),1,0)) -> 1 | F19: =IF(AND(AK19>0,$A19<VLOOKUP(AK$1,$C:$L,10,FALSE)),1,IF(AND(AK19<0,$A19>VLOOKUP(AK$1,$C:$L,10,FALSE)),1,0)) -> 0 | G19: =IF(AND(AL19>0,$A19<VLOOKUP(AL$1,$C:$L,10,FALSE)),1,IF(AND(AL19<0,$A19>VLOOKUP(AL$1,$C:$L,10,FALSE)),1,0)) -> 1 | H19: =IF(AND(AN19>0,$A19<VLOOKUP(AN$1,$C:$L,10,FALSE)),1,IF(AND(AN19<0,$A19>VLOOKUP(AN$1,$C:$L,10,FALSE)),1,0)) -> 1 | I19: =IF(AND(AO19>0,$A19<VLOOKUP(AO$1,$C:$L,10,FALSE)),1,IF(AND(AO19<0,$A19>VLOOKUP(AO$1,$C:$L,10,FALSE)),1,0)) -> 0 | J19: =IF(AND(AP19>0,$A19<VLOOKUP(AP$1,$C:$L,10,FALSE)),1,IF(AND(AP19<0,$A19>VLOOKUP(AP$1,$C:$L,10,FALSE)),1,0)) -> 1 | K19: Updated | L19: =B19 -> 16 | M19: 4 | N19: =COUNTIF($U19:$BT19,">0") -> 3 | O19: =COUNTIF($U19:$BT19,"<0") -> 3 | P19: =COUNTIF($U19:$BT19,"=0") -> 0 | Q19: =COUNTIF($AJ19:$AM19,">0") -> 1 | R19: =COUNTIF($AJ19:$AM19,"<0") -> 2 | S19: =COUNTIF($AJ19:$AM19,"=0") -> 0 | T19: =COUNTIF(U19:BU19,"NC") -> 0 | AF19: =IFERROR(IFERROR(VLOOKUP($C19&" "&AF$1,Results!$F:$H,3,FALSE),-VLOOKUP($C19&" "&AF$1,Results!$G:$H,2,FALSE)),"") | AG19: =IFERROR(IFERROR(VLOOKUP($C19&" "&AG$1,Results!$F:$H,3,FALSE),-VLOOKUP($C19&" "&AG$1,Results!$G:$H,2,FALSE)),"") | AH19: =IFERROR(IFERROR(VLOOKUP($C19&" "&AH$1,Results!$F:$H,3,FALSE),-VLOOKUP($C19&" "&AH$1,Results!$G:$H,2,FALSE)),"") | AI19: =IFERROR(IFERROR(VLOOKUP($C19&" "&AI$1,Results!$F:$H,3,FALSE),-VLOOKUP($C19&" "&AI$1,Results!$G:$H,2,FALSE)),"") | AJ19: =IFERROR(IFERROR(VLOOKUP($C19&" "&AJ$1,Results!$F:$H,3,FALSE),-VLOOKUP($C19&" "&AJ$1,Results!$G:$H,2,FALSE)),"") -> -107 | AK19: =IFERROR(IFERROR(VLOOKUP($C19&" "&AK$1,Results!$F:$H,3,FALSE),-VLOOKUP($C19&" "&AK$1,Results!$G:$H,2,FALSE)),"") -> 76 | AL19: =IFERROR(IFERROR(VLOOKUP($C19&" "&AL$1,Results!$F:$H,3,FALSE),-VLOOKUP($C19&" "&AL$1,Results!$G:$H,2,FALSE)),"") -> -84 | AM19: =IFERROR(IFERROR(VLOOKUP($C19&" "&AM$1,Results!$F:$H,3,FALSE),-VLOOKUP($C19&" "&AM$1,Results!$G:$H,2,FALSE)),"") | ... BC19: =IFERROR(IFERROR(VLOOKUP($C19&" "&BC$1,Results!$F:$H,3,FALSE),-VLOOKUP($C19&" "&BC$1,Results!$G:$H,2,FALSE)),"") | BW19: =SUM(U19:BS19) -> -187 | BX19: =COUNTIF(E19:J19,1) -> 4 | BY19: =COUNTIF(E19:J19,0) -> 2 | BZ19: =COUNT(E19:J19) -> 6 | CA19: =+BX19/BZ19 -> 0.66666667 | CC19: =SUM(U19:BT19) -> -187 | CE19: 12 | CF19: =A19 -> 18 | CG19: =+CE19-CF19 -> -6
A20: 14 | B20: 17 | C20: Clubworx | E20: =IF(AND(AO20>0,$A20<VLOOKUP(AO$1,$C:$L,10,FALSE)),1,IF(AND(AO20<0,$A20>VLOOKUP(AO$1,$C:$L,10,FALSE)),1,0)) -> 1 | F20: =IF(AND(AP20>0,$A20<VLOOKUP(AP$1,$C:$L,10,FALSE)),1,IF(AND(AP20<0,$A20>VLOOKUP(AP$1,$C:$L,10,FALSE)),1,0)) -> 1 | G20: =IF(AND(AQ20>0,$A20<VLOOKUP(AQ$1,$C:$L,10,FALSE)),1,IF(AND(AQ20<0,$A20>VLOOKUP(AQ$1,$C:$L,10,FALSE)),1,0)) -> 1 | H20: =IF(AND(AS20>0,$A20<VLOOKUP(AS$1,$C:$L,10,FALSE)),1,IF(AND(AS20<0,$A20>VLOOKUP(AS$1,$C:$L,10,FALSE)),1,0)) -> 1 | I20: =IF(AND(AT20>0,$A20<VLOOKUP(AT$1,$C:$L,10,FALSE)),1,IF(AND(AT20<0,$A20>VLOOKUP(AT$1,$C:$L,10,FALSE)),1,0)) -> 1 | J20: =IF(AND(AU20>0,$A20<VLOOKUP(AU$1,$C:$L,10,FALSE)),1,IF(AND(AU20<0,$A20>VLOOKUP(AU$1,$C:$L,10,FALSE)),1,0)) -> 1 | K20: Updated | L20: =B20 -> 17 | M20: 5 | N20: =COUNTIF($U20:$BT20,">0") -> 5 | O20: =COUNTIF($U20:$BT20,"<0") -> 1 | P20: =COUNTIF($U20:$BT20,"=0") -> 0 | Q20: =COUNTIF($AN20:$AQ20,">0") -> 3 | R20: =COUNTIF($AN20:$AQ20,"<0") -> 0 | S20: =COUNTIF($AR20:$AU20,"=0") -> 0 | T20: =COUNTIF(U20:BU20,"NC") -> 0 | AF20: =IFERROR(IFERROR(VLOOKUP($C20&" "&AF$1,Results!$F:$H,3,FALSE),-VLOOKUP($C20&" "&AF$1,Results!$G:$H,2,FALSE)),"") | AG20: =IFERROR(IFERROR(VLOOKUP($C20&" "&AG$1,Results!$F:$H,3,FALSE),-VLOOKUP($C20&" "&AG$1,Results!$G:$H,2,FALSE)),"") | AH20: =IFERROR(IFERROR(VLOOKUP($C20&" "&AH$1,Results!$F:$H,3,FALSE),-VLOOKUP($C20&" "&AH$1,Results!$G:$H,2,FALSE)),"") | AI20: =IFERROR(IFERROR(VLOOKUP($C20&" "&AI$1,Results!$F:$H,3,FALSE),-VLOOKUP($C20&" "&AI$1,Results!$G:$H,2,FALSE)),"") | AJ20: =IFERROR(IFERROR(VLOOKUP($C20&" "&AJ$1,Results!$F:$H,3,FALSE),-VLOOKUP($C20&" "&AJ$1,Results!$G:$H,2,FALSE)),"") | AK20: =IFERROR(IFERROR(VLOOKUP($C20&" "&AK$1,Results!$F:$H,3,FALSE),-VLOOKUP($C20&" "&AK$1,Results!$G:$H,2,FALSE)),"") -> 175 | AL20: =IFERROR(IFERROR(VLOOKUP($C20&" "&AL$1,Results!$F:$H,3,FALSE),-VLOOKUP($C20&" "&AL$1,Results!$G:$H,2,FALSE)),"") -> -103 | AM20: =IFERROR(IFERROR(VLOOKUP($C20&" "&AM$1,Results!$F:$H,3,FALSE),-VLOOKUP($C20&" "&AM$1,Results!$G:$H,2,FALSE)),"") -> 129 | ... BC20: =IFERROR(IFERROR(VLOOKUP($C20&" "&BC$1,Results!$F:$H,3,FALSE),-VLOOKUP($C20&" "&BC$1,Results!$G:$H,2,FALSE)),"") | BW20: =SUM(U20:BS20) -> 499 | BX20: =COUNTIF(E20:J20,1) -> 6 | BY20: =COUNTIF(E20:J20,0) -> 0 | BZ20: =COUNT(E20:J20) -> 6 | CA20: =+BX20/BZ20 -> 1 | CC20: =SUM(U20:BT20) -> 499 | CE20: 23 | CF20: =A20 -> 14 | CG20: =+CE20-CF20 -> 9
A21: 19 | B21: 18 | C21: Brookstone | E21: =IF(AND(AH21>0,$A21<VLOOKUP(AH$1,$C:$L,10,FALSE)),1,IF(AND(AH21<0,$A21>VLOOKUP(AH$1,$C:$L,10,FALSE)),1,0)) -> 0 | F21: =IF(AND(AI21>0,$A21<VLOOKUP(AI$1,$C:$L,10,FALSE)),1,IF(AND(AI21<0,$A21>VLOOKUP(AI$1,$C:$L,10,FALSE)),1,0)) -> 0 | G21: =IF(AND(AJ21>0,$A21<VLOOKUP(AJ$1,$C:$L,10,FALSE)),1,IF(AND(AJ21<0,$A21>VLOOKUP(AJ$1,$C:$L,10,FALSE)),1,0)) -> 0 | H21: =IF(AND(AL21>0,$A21<VLOOKUP(AL$1,$C:$L,10,FALSE)),1,IF(AND(AL21<0,$A21>VLOOKUP(AL$1,$C:$L,10,FALSE)),1,0)) -> 1 | I21: =IF(AND(AM21>0,$A21<VLOOKUP(AM$1,$C:$L,10,FALSE)),1,IF(AND(AM21<0,$A21>VLOOKUP(AM$1,$C:$L,10,FALSE)),1,0)) -> 1 | J21: =IF(AND(AN21>0,$A21<VLOOKUP(AN$1,$C:$L,10,FALSE)),1,IF(AND(AN21<0,$A21>VLOOKUP(AN$1,$C:$L,10,FALSE)),1,0)) -> 1 | K21: Updated | L21: =B21 -> 18 | M21: 5 | N21: =COUNTIF($U21:$BT21,">0") -> 1 | O21: =COUNTIF($U21:$BT21,"<0") -> 5 | P21: =COUNTIF($U21:$BT21,"=0") -> 0 | Q21: =COUNTIF($AN21:$AQ21,">0") -> 1 | R21: =COUNTIF($AN21:$AQ21,"<0") -> 2 | S21: =COUNTIF($AN21:$AQ21,"=0") -> 0 | T21: =COUNTIF(U21:BU21,"NC") -> 0 | AF21: =IFERROR(IFERROR(VLOOKUP($C21&" "&AF$1,Results!$F:$H,3,FALSE),-VLOOKUP($C21&" "&AF$1,Results!$G:$H,2,FALSE)),"") | AG21: =IFERROR(IFERROR(VLOOKUP($C21&" "&AG$1,Results!$F:$H,3,FALSE),-VLOOKUP($C21&" "&AG$1,Results!$G:$H,2,FALSE)),"") | AH21: =IFERROR(IFERROR(VLOOKUP($C21&" "&AH$1,Results!$F:$H,3,FALSE),-VLOOKUP($C21&" "&AH$1,Results!$G:$H,2,FALSE)),"") | AI21: =IFERROR(IFERROR(VLOOKUP($C21&" "&AI$1,Results!$F:$H,3,FALSE),-VLOOKUP($C21&" "&AI$1,Results!$G:$H,2,FALSE)),"") | AJ21: =IFERROR(IFERROR(VLOOKUP($C21&" "&AJ$1,Results!$F:$H,3,FALSE),-VLOOKUP($C21&" "&AJ$1,Results!$G:$H,2,FALSE)),"") | AK21: =IFERROR(IFERROR(VLOOKUP($C21&" "&AK$1,Results!$F:$H,3,FALSE),-VLOOKUP($C21&" "&AK$1,Results!$G:$H,2,FALSE)),"") | AL21: =IFERROR(IFERROR(VLOOKUP($C21&" "&AL$1,Results!$F:$H,3,FALSE),-VLOOKUP($C21&" "&AL$1,Results!$G:$H,2,FALSE)),"") -> -97 | AM21: =IFERROR(IFERROR(VLOOKUP($C21&" "&AM$1,Results!$F:$H,3,FALSE),-VLOOKUP($C21&" "&AM$1,Results!$G:$H,2,FALSE)),"") -> -39 | ... BC21: =IFERROR(IFERROR(VLOOKUP($C21&" "&BC$1,Results!$F:$H,3,FALSE),-VLOOKUP($C21&" "&BC$1,Results!$G:$H,2,FALSE)),"") | BW21: =SUM(U21:BS21) -> -371 | BX21: =COUNTIF(E21:J21,1) -> 3 | BY21: =COUNTIF(E21:J21,0) -> 3 | BZ21: =COUNT(E21:J21) -> 6 | CA21: =+BX21/BZ21 -> 0.5 | CC21: =SUM(U21:BT21) -> -371 | CE21: 13 | CF21: =A21 -> 19 | CG21: =+CE21-CF21 -> -6
A22: 21 | B22: 19 | C22: Regency | E22: =IF(AND(AM22>0,$A22<VLOOKUP(AM$1,$C:$L,10,FALSE)),1,IF(AND(AM22<0,$A22>VLOOKUP(AM$1,$C:$L,10,FALSE)),1,0)) -> 1 | F22: =IF(AND(AN22>0,$A22<VLOOKUP(AN$1,$C:$L,10,FALSE)),1,IF(AND(AN22<0,$A22>VLOOKUP(AN$1,$C:$L,10,FALSE)),1,0)) -> 1 | G22: =IF(AND(AO22>0,$A22<VLOOKUP(AO$1,$C:$L,10,FALSE)),1,IF(AND(AO22<0,$A22>VLOOKUP(AO$1,$C:$L,10,FALSE)),1,0)) -> 1 | H22: =IF(AND(AQ22>0,$A22<VLOOKUP(AQ$1,$C:$L,10,FALSE)),1,IF(AND(AQ22<0,$A22>VLOOKUP(AQ$1,$C:$L,10,FALSE)),1,0)) -> 1 | I22: =IF(AND(AR22>0,$A22<VLOOKUP(AR$1,$C:$L,10,FALSE)),1,IF(AND(AR22<0,$A22>VLOOKUP(AR$1,$C:$L,10,FALSE)),1,0)) -> 0 | J22: =IF(AND(AS22>0,$A22<VLOOKUP(AS$1,$C:$L,10,FALSE)),1,IF(AND(AS22<0,$A22>VLOOKUP(AS$1,$C:$L,10,FALSE)),1,0)) -> 1 | K22: Updated | L22: =B22 -> 19 | M22: 5 | N22: =COUNTIF($U22:$BT22,">0") -> 1 | O22: =COUNTIF($U22:$BT22,"<0") -> 5 | P22: =COUNTIF($U22:$BT22,"=0") -> 0 | Q22: =COUNTIF($AN22:$AQ22,">0") -> 0 | R22: =COUNTIF($AN22:$AQ22,"<0") -> 3 | S22: =COUNTIF($AN22:$AQ22,"=0") -> 0 | T22: =COUNTIF(U22:BU22,"NC") -> 0 | AF22: =IFERROR(IFERROR(VLOOKUP($C22&" "&AF$1,Results!$F:$H,3,FALSE),-VLOOKUP($C22&" "&AF$1,Results!$G:$H,2,FALSE)),"") | AG22: =IFERROR(IFERROR(VLOOKUP($C22&" "&AG$1,Results!$F:$H,3,FALSE),-VLOOKUP($C22&" "&AG$1,Results!$G:$H,2,FALSE)),"") | AH22: =IFERROR(IFERROR(VLOOKUP($C22&" "&AH$1,Results!$F:$H,3,FALSE),-VLOOKUP($C22&" "&AH$1,Results!$G:$H,2,FALSE)),"") | AI22: =IFERROR(IFERROR(VLOOKUP($C22&" "&AI$1,Results!$F:$H,3,FALSE),-VLOOKUP($C22&" "&AI$1,Results!$G:$H,2,FALSE)),"") | AJ22: =IFERROR(IFERROR(VLOOKUP($C22&" "&AJ$1,Results!$F:$H,3,FALSE),-VLOOKUP($C22&" "&AJ$1,Results!$G:$H,2,FALSE)),"") | AK22: =IFERROR(IFERROR(VLOOKUP($C22&" "&AK$1,Results!$F:$H,3,FALSE),-VLOOKUP($C22&" "&AK$1,Results!$G:$H,2,FALSE)),"") | AL22: =IFERROR(IFERROR(VLOOKUP($C22&" "&AL$1,Results!$F:$H,3,FALSE),-VLOOKUP($C22&" "&AL$1,Results!$G:$H,2,FALSE)),"") | AM22: =IFERROR(IFERROR(VLOOKUP($C22&" "&AM$1,Results!$F:$H,3,FALSE),-VLOOKUP($C22&" "&AM$1,Results!$G:$H,2,FALSE)),"") -> -18 | ... BC22: =IFERROR(IFERROR(VLOOKUP($C22&" "&BC$1,Results!$F:$H,3,FALSE),-VLOOKUP($C22&" "&BC$1,Results!$G:$H,2,FALSE)),"") | BW22: =SUM(U22:BS22) -> -168 | BX22: =COUNTIF(E22:J22,1) -> 5 | BY22: =COUNTIF(E22:J22,0) -> 1 | BZ22: =COUNT(E22:J22) -> 6 | CA22: =+BX22/BZ22 -> 0.83333333 | CC22: =SUM(U22:BT22) -> -168 | CE22: 17 | CF22: =A22 -> 21 | CG22: =+CE22-CF22 -> -4
A23: 16 | B23: 20 | C23: Wellsley | E23: =IF(AND(AT23>0,$A23<VLOOKUP(AT$1,$C:$L,10,FALSE)),1,IF(AND(AT23<0,$A23>VLOOKUP(AT$1,$C:$L,10,FALSE)),1,0)) -> 1 | F23: =IF(AND(AU23>0,$A23<VLOOKUP(AU$1,$C:$L,10,FALSE)),1,IF(AND(AU23<0,$A23>VLOOKUP(AU$1,$C:$L,10,FALSE)),1,0)) -> 1 | G23: =IF(AND(AV23>0,$A23<VLOOKUP(AV$1,$C:$L,10,FALSE)),1,IF(AND(AV23<0,$A23>VLOOKUP(AV$1,$C:$L,10,FALSE)),1,0)) -> 1 | H23: =IF(AND(AX23>0,$A23<VLOOKUP(AX$1,$C:$L,10,FALSE)),1,IF(AND(AX23<0,$A23>VLOOKUP(AX$1,$C:$L,10,FALSE)),1,0)) -> 1 | I23: =IF(AND(AY23>0,$A23<VLOOKUP(AY$1,$C:$L,10,FALSE)),1,IF(AND(AY23<0,$A23>VLOOKUP(AY$1,$C:$L,10,FALSE)),1,0)) -> 1 | J23: =IF(AND(AZ23>0,$A23<VLOOKUP(AZ$1,$C:$L,10,FALSE)),1,IF(AND(AZ23<0,$A23>VLOOKUP(AZ$1,$C:$L,10,FALSE)),1,0)) -> 1 | K23: Updated | L23: =B23 -> 20 | M23: 5 | N23: =COUNTIF($U23:$BT23,">0") -> 5 | O23: =COUNTIF($U23:$BT23,"<0") -> 1 | P23: =COUNTIF($U23:$BT23,"=0") -> 0 | Q23: =COUNTIF($AN23:$AQ23,">0") -> 2 | R23: =COUNTIF($AN23:$AQ23,"<0") -> 1 | S23: =COUNTIF($AN23:$AQ23,"=0") -> 0 | T23: =COUNTIF(U23:BU23,"NC") -> 0 | AF23: =IFERROR(IFERROR(VLOOKUP($C23&" "&AF$1,Results!$F:$H,3,FALSE),-VLOOKUP($C23&" "&AF$1,Results!$G:$H,2,FALSE)),"") | AG23: =IFERROR(IFERROR(VLOOKUP($C23&" "&AG$1,Results!$F:$H,3,FALSE),-VLOOKUP($C23&" "&AG$1,Results!$G:$H,2,FALSE)),"") | AH23: =IFERROR(IFERROR(VLOOKUP($C23&" "&AH$1,Results!$F:$H,3,FALSE),-VLOOKUP($C23&" "&AH$1,Results!$G:$H,2,FALSE)),"") | AI23: =IFERROR(IFERROR(VLOOKUP($C23&" "&AI$1,Results!$F:$H,3,FALSE),-VLOOKUP($C23&" "&AI$1,Results!$G:$H,2,FALSE)),"") | AJ23: =IFERROR(IFERROR(VLOOKUP($C23&" "&AJ$1,Results!$F:$H,3,FALSE),-VLOOKUP($C23&" "&AJ$1,Results!$G:$H,2,FALSE)),"") | AK23: =IFERROR(IFERROR(VLOOKUP($C23&" "&AK$1,Results!$F:$H,3,FALSE),-VLOOKUP($C23&" "&AK$1,Results!$G:$H,2,FALSE)),"") | AL23: =IFERROR(IFERROR(VLOOKUP($C23&" "&AL$1,Results!$F:$H,3,FALSE),-VLOOKUP($C23&" "&AL$1,Results!$G:$H,2,FALSE)),"") | AM23: =IFERROR(IFERROR(VLOOKUP($C23&" "&AM$1,Results!$F:$H,3,FALSE),-VLOOKUP($C23&" "&AM$1,Results!$G:$H,2,FALSE)),"") | ... BC23: =IFERROR(IFERROR(VLOOKUP($C23&" "&BC$1,Results!$F:$H,3,FALSE),-VLOOKUP($C23&" "&BC$1,Results!$G:$H,2,FALSE)),"") | BW23: =SUM(U23:BS23) -> 438 | BX23: =COUNTIF(E23:J23,1) -> 6 | BY23: =COUNTIF(E23:J23,0) -> 0 | BZ23: =COUNT(E23:J23) -> 6 | CA23: =+BX23/BZ23 -> 1 | CC23: =SUM(U23:BT23) -> 438 | CE23: 29 | CF23: =A23 -> 16 | CG23: =+CE23-CF23 -> 13
A24: 17 | B24: 21 | C24: Amberly | E24: =IF(AND(AR24>0,$A24<VLOOKUP(AR$1,$C:$L,10,FALSE)),1,IF(AND(AR24<0,$A24>VLOOKUP(AR$1,$C:$L,10,FALSE)),1,0)) -> 1 | F24: =IF(AND(AS24>0,$A24<VLOOKUP(AS$1,$C:$L,10,FALSE)),1,IF(AND(AS24<0,$A24>VLOOKUP(AS$1,$C:$L,10,FALSE)),1,0)) -> 1 | G24: =IF(AND(AT24>0,$A24<VLOOKUP(AT$1,$C:$L,10,FALSE)),1,IF(AND(AT24<0,$A24>VLOOKUP(AT$1,$C:$L,10,FALSE)),1,0)) -> 1 | H24: =IF(AND(AV24>0,$A24<VLOOKUP(AV$1,$C:$L,10,FALSE)),1,IF(AND(AV24<0,$A24>VLOOKUP(AV$1,$C:$L,10,FALSE)),1,0)) -> 1 | I24: =IF(AND(AW24>0,$A24<VLOOKUP(AW$1,$C:$L,10,FALSE)),1,IF(AND(AW24<0,$A24>VLOOKUP(AW$1,$C:$L,10,FALSE)),1,0)) -> 1 | J24: =IF(AND(AX24>0,$A24<VLOOKUP(AX$1,$C:$L,10,FALSE)),1,IF(AND(AX24<0,$A24>VLOOKUP(AX$1,$C:$L,10,FALSE)),1,0)) -> 1 | K24: Updated | L24: =B24 -> 21 | M24: 6 | N24: =COUNTIF($U24:$BT24,">0") -> 5 | O24: =COUNTIF($U24:$BT24,"<0") -> 1 | P24: =COUNTIF($U24:$BT24,"=0") -> 0 | Q24: =COUNTIF($AR24:$AU24,">0") -> 3 | R24: =COUNTIF($AR24:$AU24,"<0") -> 0 | S24: =COUNTIF($AR24:$AU24,"=0") -> 0 | T24: =COUNTIF(U24:BU24,"NC") -> 0 | AF24: =IFERROR(IFERROR(VLOOKUP($C24&" "&AF$1,Results!$F:$H,3,FALSE),-VLOOKUP($C24&" "&AF$1,Results!$G:$H,2,FALSE)),"") | AG24: =IFERROR(IFERROR(VLOOKUP($C24&" "&AG$1,Results!$F:$H,3,FALSE),-VLOOKUP($C24&" "&AG$1,Results!$G:$H,2,FALSE)),"") | AH24: =IFERROR(IFERROR(VLOOKUP($C24&" "&AH$1,Results!$F:$H,3,FALSE),-VLOOKUP($C24&" "&AH$1,Results!$G:$H,2,FALSE)),"") | AI24: =IFERROR(IFERROR(VLOOKUP($C24&" "&AI$1,Results!$F:$H,3,FALSE),-VLOOKUP($C24&" "&AI$1,Results!$G:$H,2,FALSE)),"") | AJ24: =IFERROR(IFERROR(VLOOKUP($C24&" "&AJ$1,Results!$F:$H,3,FALSE),-VLOOKUP($C24&" "&AJ$1,Results!$G:$H,2,FALSE)),"") | AK24: =IFERROR(IFERROR(VLOOKUP($C24&" "&AK$1,Results!$F:$H,3,FALSE),-VLOOKUP($C24&" "&AK$1,Results!$G:$H,2,FALSE)),"") | AL24: =IFERROR(IFERROR(VLOOKUP($C24&" "&AL$1,Results!$F:$H,3,FALSE),-VLOOKUP($C24&" "&AL$1,Results!$G:$H,2,FALSE)),"") | AM24: =IFERROR(IFERROR(VLOOKUP($C24&" "&AM$1,Results!$F:$H,3,FALSE),-VLOOKUP($C24&" "&AM$1,Results!$G:$H,2,FALSE)),"") | ... BC24: =IFERROR(IFERROR(VLOOKUP($C24&" "&BC$1,Results!$F:$H,3,FALSE),-VLOOKUP($C24&" "&BC$1,Results!$G:$H,2,FALSE)),"") | BW24: =SUM(U24:BS24) -> 437 | BX24: =COUNTIF(E24:J24,1) -> 6 | BY24: =COUNTIF(E24:J24,0) -> 0 | BZ24: =COUNT(E24:J24) -> 6 | CA24: =+BX24/BZ24 -> 1 | CC24: =SUM(U24:BT24) -> 437 | CE24: 20 | CF24: =A24 -> 17 | CG24: =+CE24-CF24 -> 3
A25: 23 | B25: 22 | C25: Highcroft | E25: =IF(AND(AP25>0,$A25<VLOOKUP(AP$1,$C:$L,10,FALSE)),1,IF(AND(AP25<0,$A25>VLOOKUP(AP$1,$C:$L,10,FALSE)),1,0)) -> 1 | F25: =IF(AND(AQ25>0,$A25<VLOOKUP(AQ$1,$C:$L,10,FALSE)),1,IF(AND(AQ25<0,$A25>VLOOKUP(AQ$1,$C:$L,10,FALSE)),1,0)) -> 1 | G25: =IF(AND(AR25>0,$A25<VLOOKUP(AR$1,$C:$L,10,FALSE)),1,IF(AND(AR25<0,$A25>VLOOKUP(AR$1,$C:$L,10,FALSE)),1,0)) -> 1 | H25: =IF(AND(AT25>0,$A25<VLOOKUP(AT$1,$C:$L,10,FALSE)),1,IF(AND(AT25<0,$A25>VLOOKUP(AT$1,$C:$L,10,FALSE)),1,0)) -> 0 | I25: =IF(AND(AU25>0,$A25<VLOOKUP(AU$1,$C:$L,10,FALSE)),1,IF(AND(AU25<0,$A25>VLOOKUP(AU$1,$C:$L,10,FALSE)),1,0)) -> 1 | J25: =IF(AND(AV25>0,$A25<VLOOKUP(AV$1,$C:$L,10,FALSE)),1,IF(AND(AV25<0,$A25>VLOOKUP(AV$1,$C:$L,10,FALSE)),1,0)) -> 0 | K25: Updated | L25: =B25 -> 22 | M25: 6 | N25: =COUNTIF($U25:$BT25,">0") -> 2 | O25: =COUNTIF($U25:$BT25,"<0") -> 4 | P25: =COUNTIF($U25:$BT25,"=0") -> 0 | Q25: =COUNTIF($AR25:$AU25,">0") -> 2 | R25: =COUNTIF($AR25:$AU25,"<0") -> 1 | S25: =COUNTIF($AR25:$AU25,"=0") -> 0 | T25: =COUNTIF(U25:BU25,"NC") -> 0 | AF25: =IFERROR(IFERROR(VLOOKUP($C25&" "&AF$1,Results!$F:$H,3,FALSE),-VLOOKUP($C25&" "&AF$1,Results!$G:$H,2,FALSE)),"") | AG25: =IFERROR(IFERROR(VLOOKUP($C25&" "&AG$1,Results!$F:$H,3,FALSE),-VLOOKUP($C25&" "&AG$1,Results!$G:$H,2,FALSE)),"") | AH25: =IFERROR(IFERROR(VLOOKUP($C25&" "&AH$1,Results!$F:$H,3,FALSE),-VLOOKUP($C25&" "&AH$1,Results!$G:$H,2,FALSE)),"") | AI25: =IFERROR(IFERROR(VLOOKUP($C25&" "&AI$1,Results!$F:$H,3,FALSE),-VLOOKUP($C25&" "&AI$1,Results!$G:$H,2,FALSE)),"") | AJ25: =IFERROR(IFERROR(VLOOKUP($C25&" "&AJ$1,Results!$F:$H,3,FALSE),-VLOOKUP($C25&" "&AJ$1,Results!$G:$H,2,FALSE)),"") | AK25: =IFERROR(IFERROR(VLOOKUP($C25&" "&AK$1,Results!$F:$H,3,FALSE),-VLOOKUP($C25&" "&AK$1,Results!$G:$H,2,FALSE)),"") | AL25: =IFERROR(IFERROR(VLOOKUP($C25&" "&AL$1,Results!$F:$H,3,FALSE),-VLOOKUP($C25&" "&AL$1,Results!$G:$H,2,FALSE)),"") | AM25: =IFERROR(IFERROR(VLOOKUP($C25&" "&AM$1,Results!$F:$H,3,FALSE),-VLOOKUP($C25&" "&AM$1,Results!$G:$H,2,FALSE)),"") | ... BC25: =IFERROR(IFERROR(VLOOKUP($C25&" "&BC$1,Results!$F:$H,3,FALSE),-VLOOKUP($C25&" "&BC$1,Results!$G:$H,2,FALSE)),"") | BW25: =SUM(U25:BS25) -> -201 | BX25: =COUNTIF(E25:J25,1) -> 4 | BY25: =COUNTIF(E25:J25,0) -> 2 | BZ25: =COUNT(E25:J25) -> 6 | CA25: =+BX25/BZ25 -> 0.66666667 | CC25: =SUM(U25:BT25) -> -201 | CE25: 25 | CF25: =A25 -> 23 | CG25: =+CE25-CF25 -> 2
A26: 27 | B26: 23 | C26: Weatherstone | E26: =IF(AND(AK26>0,$A26<VLOOKUP(AK$1,$C:$L,10,FALSE)),1,IF(AND(AK26<0,$A26>VLOOKUP(AK$1,$C:$L,10,FALSE)),1,0)) -> 0 | F26: =IF(AND(AL26>0,$A26<VLOOKUP(AL$1,$C:$L,10,FALSE)),1,IF(AND(AL26<0,$A26>VLOOKUP(AL$1,$C:$L,10,FALSE)),1,0)) -> 0 | G26: =IF(AND(AM26>0,$A26<VLOOKUP(AM$1,$C:$L,10,FALSE)),1,IF(AND(AM26<0,$A26>VLOOKUP(AM$1,$C:$L,10,FALSE)),1,0)) -> 0 | H26: =IF(AND(AO26>0,$A26<VLOOKUP(AO$1,$C:$L,10,FALSE)),1,IF(AND(AO26<0,$A26>VLOOKUP(AO$1,$C:$L,10,FALSE)),1,0)) -> 0 | I26: =IF(AND(AP26>0,$A26<VLOOKUP(AP$1,$C:$L,10,FALSE)),1,IF(AND(AP26<0,$A26>VLOOKUP(AP$1,$C:$L,10,FALSE)),1,0)) -> 0 | J26: =IF(AND(AQ26>0,$A26<VLOOKUP(AQ$1,$C:$L,10,FALSE)),1,IF(AND(AQ26<0,$A26>VLOOKUP(AQ$1,$C:$L,10,FALSE)),1,0)) -> 1 | K26: Updated | L26: =B26 -> 23 | M26: 6 | N26: =COUNTIF($U26:$BT26,">0") -> 1 | O26: =COUNTIF($U26:$BT26,"<0") -> 5 | P26: =COUNTIF($U26:$BT26,"=0") -> 0 | Q26: =COUNTIF($AR26:$AU26,">0") -> 1 | R26: =COUNTIF($AR26:$AU26,"<0") -> 2 | S26: =COUNTIF($AR26:$AU26,"=0") -> 0 | T26: =COUNTIF(U26:BU26,"NC") -> 0 | AF26: =IFERROR(IFERROR(VLOOKUP($C26&" "&AF$1,Results!$F:$H,3,FALSE),-VLOOKUP($C26&" "&AF$1,Results!$G:$H,2,FALSE)),"") | AG26: =IFERROR(IFERROR(VLOOKUP($C26&" "&AG$1,Results!$F:$H,3,FALSE),-VLOOKUP($C26&" "&AG$1,Results!$G:$H,2,FALSE)),"") | AH26: =IFERROR(IFERROR(VLOOKUP($C26&" "&AH$1,Results!$F:$H,3,FALSE),-VLOOKUP($C26&" "&AH$1,Results!$G:$H,2,FALSE)),"") | AI26: =IFERROR(IFERROR(VLOOKUP($C26&" "&AI$1,Results!$F:$H,3,FALSE),-VLOOKUP($C26&" "&AI$1,Results!$G:$H,2,FALSE)),"") | AJ26: =IFERROR(IFERROR(VLOOKUP($C26&" "&AJ$1,Results!$F:$H,3,FALSE),-VLOOKUP($C26&" "&AJ$1,Results!$G:$H,2,FALSE)),"") | AK26: =IFERROR(IFERROR(VLOOKUP($C26&" "&AK$1,Results!$F:$H,3,FALSE),-VLOOKUP($C26&" "&AK$1,Results!$G:$H,2,FALSE)),"") | AL26: =IFERROR(IFERROR(VLOOKUP($C26&" "&AL$1,Results!$F:$H,3,FALSE),-VLOOKUP($C26&" "&AL$1,Results!$G:$H,2,FALSE)),"") | AM26: =IFERROR(IFERROR(VLOOKUP($C26&" "&AM$1,Results!$F:$H,3,FALSE),-VLOOKUP($C26&" "&AM$1,Results!$G:$H,2,FALSE)),"") | ... BC26: =IFERROR(IFERROR(VLOOKUP($C26&" "&BC$1,Results!$F:$H,3,FALSE),-VLOOKUP($C26&" "&BC$1,Results!$G:$H,2,FALSE)),"") | BW26: =SUM(U26:BS26) -> -638 | BX26: =COUNTIF(E26:J26,1) -> 1 | BY26: =COUNTIF(E26:J26,0) -> 5 | BZ26: =COUNT(E26:J26) -> 6 | CA26: =+BX26/BZ26 -> 0.16666667 | CC26: =SUM(U26:BT26) -> -638 | CE26: 15 | CF26: =A26 -> 27 | CG26: =+CE26-CF26 -> -12
A27: 25 | B27: 24 | C27: Weldon Ridge | E27: =IF(AND(AW27>0,$A27<VLOOKUP(AW$1,$C:$L,10,FALSE)),1,IF(AND(AW27<0,$A27>VLOOKUP(AW$1,$C:$L,10,FALSE)),1,0)) -> 1 | F27: =IF(AND(AX27>0,$A27<VLOOKUP(AX$1,$C:$L,10,FALSE)),1,IF(AND(AX27<0,$A27>VLOOKUP(AX$1,$C:$L,10,FALSE)),1,0)) -> 0 | G27: =IF(AND(AY27>0,$A27<VLOOKUP(AY$1,$C:$L,10,FALSE)),1,IF(AND(AY27<0,$A27>VLOOKUP(AY$1,$C:$L,10,FALSE)),1,0)) -> 1 | H27: =IF(AND(BA27>0,$A27<VLOOKUP(BA$1,$C:$L,10,FALSE)),1,IF(AND(BA27<0,$A27>VLOOKUP(BA$1,$C:$L,10,FALSE)),1,0)) -> 1 | I27: =IF(AND(BB27>0,$A27<VLOOKUP(BB$1,$C:$L,10,FALSE)),1,IF(AND(BB27<0,$A27>VLOOKUP(BB$1,$C:$L,10,FALSE)),1,0)) -> 1 | J27: =IF(AND(BC27>0,$A27<VLOOKUP(BC$1,$C:$L,10,FALSE)),1,IF(AND(BC27<0,$A27>VLOOKUP(BC$1,$C:$L,10,FALSE)),1,0)) -> 1 | K27: Updated | L27: =B27 -> 24 | M27: 6 | N27: =COUNTIF($U27:$BT27,">0") -> 2 | O27: =COUNTIF($U27:$BT27,"<0") -> 4 | P27: =COUNTIF($U27:$BT27,"=0") -> 0 | Q27: =COUNTIF($AR27:$AU27,">0") -> 0 | R27: =COUNTIF($AR27:$AU27,"<0") -> 3 | S27: =COUNTIF($AR27:$AU27,"=0") -> 0 | T27: =COUNTIF(U27:BU27,"NC") -> 0 | AR27: =IFERROR(IFERROR(VLOOKUP($C27&" "&AR$1,Results!$F:$H,3,FALSE),-VLOOKUP($C27&" "&AR$1,Results!$G:$H,2,FALSE)),"") -> -189 | AS27: =IFERROR(IFERROR(VLOOKUP($C27&" "&AS$1,Results!$F:$H,3,FALSE),-VLOOKUP($C27&" "&AS$1,Results!$G:$H,2,FALSE)),"") -> -31 | AT27: =IFERROR(IFERROR(VLOOKUP($C27&" "&AT$1,Results!$F:$H,3,FALSE),-VLOOKUP($C27&" "&AT$1,Results!$G:$H,2,FALSE)),"") -> -13 | AU27: =IFERROR(IFERROR(VLOOKUP($C27&" "&AU$1,Results!$F:$H,3,FALSE),-VLOOKUP($C27&" "&AU$1,Results!$G:$H,2,FALSE)),"") | AV27: =IFERROR(IFERROR(VLOOKUP($C27&" "&AV$1,Results!$F:$H,3,FALSE),-VLOOKUP($C27&" "&AV$1,Results!$G:$H,2,FALSE)),"") -> 4 | AW27: =IFERROR(IFERROR(VLOOKUP($C27&" "&AW$1,Results!$F:$H,3,FALSE),-VLOOKUP($C27&" "&AW$1,Results!$G:$H,2,FALSE)),"") -> 10 | AX27: =IFERROR(IFERROR(VLOOKUP($C27&" "&AX$1,Results!$F:$H,3,FALSE),-VLOOKUP($C27&" "&AX$1,Results!$G:$H,2,FALSE)),"") -> -30 | AY27: =IFERROR(IFERROR(VLOOKUP($C27&" "&AY$1,Results!$F:$H,3,FALSE),-VLOOKUP($C27&" "&AY$1,Results!$G:$H,2,FALSE)),"") | ... BT27: =IFERROR(IFERROR(VLOOKUP($C27&" "&BT$1,Results!$F:$H,3,FALSE),-VLOOKUP($C27&" "&BT$1,Results!$G:$H,2,FALSE)),"") | BW27: =SUM(U27:BS27) -> -249 | BX27: =COUNTIF(E27:J27,1) -> 5 | BY27: =COUNTIF(E27:J27,0) -> 1 | BZ27: =COUNT(E27:J27) -> 6 | CA27: =+BX27/BZ27 -> 0.83333333 | CC27: =SUM(U27:BT27) -> -249 | CE27: 28 | CF27: =A27 -> 25 | CG27: =+CE27-CF27 -> 3
