Workbook

Sheet South
A1: =BX55 -> 0 | C1: =SUM(V4:BV53)+SUM(North!V4:BI40) -> 0 | N1: RECORDS | V1: University Club | W1: Seven Oaks | X1: Meredith Townes | Y1: Apex | Z1: Shepherds Vineyard | AA1: Cary Park | AB1: Sunset Ridge | AC1: Medfield | AD1: Prestonwood | AE1: Abbington | AF1: Lochmere | AG1: Olive Chapel | AH1: Scottish Hills | AI1: Walden Creek | AJ1: Cary | AK1: Scotts Mill | AL1: Weatherstone | AM1: Wellsley | AN1: Haddon Hall | AO1: Dutchman Downs | AP1: The Reserve | AQ1: Silverton | AR1: Oxxford Hunt | AS1: Regency | AT1: Life Time Fitness Cary | AU1: Highcroft | AV1: Brookstone | AW1: Clubworx | AX1: Park Village | AY1: Park at West Lake | AZ1: TCC | BA1: Amberly | BB1: Preston Village | BC1: Bella Casa | BD1: WoodCreek | BE1: Weldon Ridge | BF1: Garner | BG1: Glenridge | BH1: Kildaire Farms | BI1: Twelve Oaks | BJ1: Carpenter Village | BK1: Devereaux | BL1: Brighton Forest | BM1: Bentwinds | BN1: Harmony | BO1: Charleston Village | BP1: Eagle Ridge | BQ1: Crooked Creek | BR1: Kitts Creek | BS1: TAC | BT1: Wellington Park | BU1: Renaissance Park | BV1: Holly Glen
A2: 2020 | B2: 2019 | E2: Rank Justified by HTH result | L2: 2020 | N2: Overall | Q2: Division | V2: N1 | W2: N1 | X2: N1 | Y2: 1 | Z2: 1 | AA2: 1 | AB2: 1 | AC2: 2 | AD2: 2 | AE2: 2 | AF2: 2 | AG2: 3 | AH2: 3 | AI2: 3 | AJ2: 3 | AK2: 4 | AL2: 4 | AM2: 4 | AN2: 4 | AO2: 5 | AP2: 5 | AQ2: 5 | AR2: 5 | AS2: 6 | AT2: 6 | AU2: 6 | AV2: 6 | AW2: 7 | AX2: 7 | AY2: 7 | AZ2: 7 | BA2: 8 | BB2: 8 | BC2: 8 | BD2: 8 | BE2: 9 | BF2: 9 | BG2: 9 | BH2: 9 | BI2: 10 | BJ2: 10 | BK2: 10 | BL2: 10 | BM2: 11 | BN2: 11 | BO2: 11 | BP2: 11 | BQ2: 12 | BR2: 12 | BS2: 12 | BT2: 13 | BU2: 13 | BV2: 13 | BX2: HTH | BY2: HTH | BZ2: HTH
A3: Rank | B3: Rank | E3: Up 3 | F3: Up 2 | G3: Up 1 | H3: Dn 1 | I3: Dn 2 | J3: Dn 3 | L3: Rank | M3: Div | N3: W | O3: L | P3: T | Q3: W | R3: L | S3: T | T3: NC | BX3: Yes | BY3: No | BZ3: Poss | CA3: Percent | CE3: MS | CF3: Comm | CG3: Diff
B4: 1 | C4: Apex | H4: =IF(AND(Z4>0,$A4<VLOOKUP(Z$1,$C:$L,10,FALSE)),1,IF(AND(Z4<0,$A4>VLOOKUP(Z$1,$C:$L,10,FALSE)),1,0)) -> 0 | I4: =IF(AND(AA4>0,$A4<VLOOKUP(AA$1,$C:$L,10,FALSE)),1,IF(AND(AA4<0,$A4>VLOOKUP(AA$1,$C:$L,10,FALSE)),1,0)) -> 0 | J4: =IF(AND(AB4>0,$A4<VLOOKUP(AB$1,$C:$L,10,FALSE)),1,IF(AND(AB4<0,$A4>VLOOKUP(AB$1,$C:$L,10,FALSE)),1,0)) -> 0 | K4: Updated | L4: =A4 -> 0 | M4: 1 | N4: =COUNTIF($V4:$BU4,">0") -> 3 | O4: =COUNTIF($V4:$BU4,"<0") -> 3 | P4: =COUNTIF($V4:$BU4,"=0") -> 0 | Q4: =COUNTIF($Y4:$AB4,">0") -> 2 | R4: =COUNTIF($Y4:$AB4,"<0") -> 1 | S4: =COUNTIF($Y4:$AB4,"=0") -> 0 | T4: =COUNTIF(V4:BJ4,"NC") -> 0 | V4: =IFERROR(IFERROR(VLOOKUP($C4&" "&V$1,Results!$G:$I,3,FALSE),-VLOOKUP($C4&" "&V$1,Results!$H:$I,2,FALSE)),"") -> -38 | W4: =IFERROR(IFERROR(VLOOKUP($C4&" "&W$1,Results!$G:$I,3,FALSE),-VLOOKUP($C4&" "&W$1,Results!$H:$I,2,FALSE)),"") -> -100 | X4: =IFERROR(IFERROR(VLOOKUP($C4&" "&X$1,Results!$G:$I,3,FALSE),-VLOOKUP($C4&" "&X$1,Results!$H:$I,2,FALSE)),"") -> 58 | Y4: =IFERROR(IFERROR(VLOOKUP($C4&" "&Y$1,Results!$G:$I,3,FALSE),-VLOOKUP($C4&" "&Y$1,Results!$H:$I,2,FALSE)),"") | Z4: =IFERROR(IFERROR(VLOOKUP($C4&" "&Z$1,Results!$G:$I,3,FALSE),-VLOOKUP($C4&" "&Z$1,Results!$H:$I,2,FALSE)),"") -> 88 | AA4: =IFERROR(IFERROR(VLOOKUP($C4&" "&AA$1,Results!$G:$I,3,FALSE),-VLOOKUP($C4&" "&AA$1,Results!$H:$I,2,FALSE)),"") -> -29 | AB4: =IFERROR(IFERROR(VLOOKUP($C4&" "&AB$1,Results!$G:$I,3,FALSE),-VLOOKUP($C4&" "&AB$1,Results!$H:$I,2,FALSE)),"") -> 82 | AC4: =IFERROR(IFERROR(VLOOKUP($C4&" "&AC$1,Results!$G:$I,3,FALSE),-VLOOKUP($C4&" "&AC$1,Results!$H:$I,2,FALSE)),"") | ... AF4: =IFERROR(IFERROR(VLOOKUP($C4&" "&AF$1,Results!$G:$I,3,FALSE),-VLOOKUP($C4&" "&AF$1,Results!$H:$I,2,FALSE)),"") | BW4: =SUM(V4:BT4) -> 61 | BX4: =COUNTIF(E4:J4,1) -> 0 | BY4: =COUNTIF(E4:J4,0) -> 3 | BZ4: =COUNT(E4:J4) -> 3 | CA4: =+BX4/BZ4 -> 0 | CC4: =SUM(V4:BU4) -> 61 | CE4: 1 | CF4: =A4 -> 0 | CG4: =+CE4-CF4 -> 1
B5: 2 | C5: Shepherds Vineyard | G5: =IF(AND(Y5>0,$A5<VLOOKUP(Y$1,$C:$L,10,FALSE)),1,IF(AND(Y5<0,$A5>VLOOKUP(Y$1,$C:$L,10,FALSE)),1,0)) -> 0 | H5: =IF(AND(AA5>0,$A5<VLOOKUP(AA$1,$C:$L,10,FALSE)),1,IF(AND(AA5<0,$A5>VLOOKUP(AA$1,$C:$L,10,FALSE)),1,0)) -> 0 | I5: =IF(AND(AB5>0,$A5<VLOOKUP(AB$1,$C:$L,10,FALSE)),1,IF(AND(AB5<0,$A5>VLOOKUP(AB$1,$C:$L,10,FALSE)),1,0)) -> 0 | J5: =IF(AND(AC5>0,$A5<VLOOKUP(AC$1,$C:$L,10,FALSE)),1,IF(AND(AC5<0,$A5>VLOOKUP(AC$1,$C:$L,10,FALSE)),1,0)) -> 0 | K5: Updated | L5: =A5 -> 0 | M5: 1 | N5: =COUNTIF($V5:$BU5,">0") -> 1 | O5: =COUNTIF($V5:$BU5,"<0") -> 5 | P5: =COUNTIF($V5:$BU5,"=0") -> 0 | Q5: =COUNTIF($Y5:$AB5,">0") -> 0 | R5: =COUNTIF($Y5:$AB5,"<0") -> 3 | S5: =COUNTIF($Y5:$AB5,"=0") -> 0 | T5: =COUNTIF(V5:BJ5,"NC") -> 0 | V5: =IFERROR(IFERROR(VLOOKUP($C5&" "&V$1,Results!$G:$I,3,FALSE),-VLOOKUP($C5&" "&V$1,Results!$H:$I,2,FALSE)),"") -> -200 | W5: =IFERROR(IFERROR(VLOOKUP($C5&" "&W$1,Results!$G:$I,3,FALSE),-VLOOKUP($C5&" "&W$1,Results!$H:$I,2,FALSE)),"") -> -124 | X5: =IFERROR(IFERROR(VLOOKUP($C5&" "&X$1,Results!$G:$I,3,FALSE),-VLOOKUP($C5&" "&X$1,Results!$H:$I,2,FALSE)),"") | Y5: =IFERROR(IFERROR(VLOOKUP($C5&" "&Y$1,Results!$G:$I,3,FALSE),-VLOOKUP($C5&" "&Y$1,Results!$H:$I,2,FALSE)),"") -> -88 | Z5: =IFERROR(IFERROR(VLOOKUP($C5&" "&Z$1,Results!$G:$I,3,FALSE),-VLOOKUP($C5&" "&Z$1,Results!$H:$I,2,FALSE)),"") | AA5: =IFERROR(IFERROR(VLOOKUP($C5&" "&AA$1,Results!$G:$I,3,FALSE),-VLOOKUP($C5&" "&AA$1,Results!$H:$I,2,FALSE)),"") -> -42 | AB5: =IFERROR(IFERROR(VLOOKUP($C5&" "&AB$1,Results!$G:$I,3,FALSE),-VLOOKUP($C5&" "&AB$1,Results!$H:$I,2,FALSE)),"") -> -16 | AC5: =IFERROR(IFERROR(VLOOKUP($C5&" "&AC$1,Results!$G:$I,3,FALSE),-VLOOKUP($C5&" "&AC$1,Results!$H:$I,2,FALSE)),"") -> 95 | ... AF5: =IFERROR(IFERROR(VLOOKUP($C5&" "&AF$1,Results!$G:$I,3,FALSE),-VLOOKUP($C5&" "&AF$1,Results!$H:$I,2,FALSE)),"") | BW5: =SUM(V5:BT5) -> -375 | BX5: =COUNTIF(E5:I5,1) -> 0 | BY5: =COUNTIF(E5:I5,0) -> 3 | BZ5: =COUNT(E5:I5) -> 3 | CA5: =+BX5/BZ5 -> 0 | CC5: =SUM(V5:BU5) -> -375 | CE5: 3 | CF5: =A5 -> 0 | CG5: =+CE5-CF5 -> 3
B6: 3 | C6: Cary Park | F6: =IF(AND(Y6>0,$A6<VLOOKUP(Y$1,$C:$L,10,FALSE)),1,IF(AND(Y6<0,$A6>VLOOKUP(Y$1,$C:$L,10,FALSE)),1,0)) -> 0 | G6: =IF(AND(Z6>0,$A6<VLOOKUP(Z$1,$C:$L,10,FALSE)),1,IF(AND(Z6<0,$A6>VLOOKUP(Z$1,$C:$L,10,FALSE)),1,0)) -> 0 | H6: =IF(AND(AB6>0,$A6<VLOOKUP(AB$1,$C:$L,10,FALSE)),1,IF(AND(AB6<0,$A6>VLOOKUP(AB$1,$C:$L,10,FALSE)),1,0)) -> 0 | I6: =IF(AND(AC6>0,$A6<VLOOKUP(AC$1,$C:$L,10,FALSE)),1,IF(AND(AC6<0,$A6>VLOOKUP(AC$1,$C:$L,10,FALSE)),1,0)) -> 0 | J6: =IF(AND(AD6>0,$A6<VLOOKUP(AD$1,$C:$L,10,FALSE)),1,IF(AND(AD6<0,$A6>VLOOKUP(AD$1,$C:$L,10,FALSE)),1,0)) -> 0 | K6: Updated | L6: =A6 -> 0 | M6: 1 | N6: =COUNTIF($V6:$BU6,">0") -> 5 | O6: =COUNTIF($V6:$BU6,"<0") -> 1 | P6: =COUNTIF($V6:$BU6,"=0") -> 0 | Q6: =COUNTIF($Y6:$AB6,">0") -> 3 | R6: =COUNTIF($Y6:$AB6,"<0") -> 0 | S6: =COUNTIF($Y6:$AB6,"=0") -> 0 | T6: =COUNTIF(V6:BJ6,"NC") -> 0 | V6: =IFERROR(IFERROR(VLOOKUP($C6&" "&V$1,Results!$G:$I,3,FALSE),-VLOOKUP($C6&" "&V$1,Results!$H:$I,2,FALSE)),"") -> -109 | W6: =IFERROR(IFERROR(VLOOKUP($C6&" "&W$1,Results!$G:$I,3,FALSE),-VLOOKUP($C6&" "&W$1,Results!$H:$I,2,FALSE)),"") | X6: =IFERROR(IFERROR(VLOOKUP($C6&" "&X$1,Results!$G:$I,3,FALSE),-VLOOKUP($C6&" "&X$1,Results!$H:$I,2,FALSE)),"") | Y6: =IFERROR(IFERROR(VLOOKUP($C6&" "&Y$1,Results!$G:$I,3,FALSE),-VLOOKUP($C6&" "&Y$1,Results!$H:$I,2,FALSE)),"") -> 29 | Z6: =IFERROR(IFERROR(VLOOKUP($C6&" "&Z$1,Results!$G:$I,3,FALSE),-VLOOKUP($C6&" "&Z$1,Results!$H:$I,2,FALSE)),"") -> 42 | AA6: =IFERROR(IFERROR(VLOOKUP($C6&" "&AA$1,Results!$G:$I,3,FALSE),-VLOOKUP($C6&" "&AA$1,Results!$H:$I,2,FALSE)),"") | AB6: =IFERROR(IFERROR(VLOOKUP($C6&" "&AB$1,Results!$G:$I,3,FALSE),-VLOOKUP($C6&" "&AB$1,Results!$H:$I,2,FALSE)),"") -> 155 | AC6: =IFERROR(IFERROR(VLOOKUP($C6&" "&AC$1,Results!$G:$I,3,FALSE),-VLOOKUP($C6&" "&AC$1,Results!$H:$I,2,FALSE)),"") -> 159 | ... AF6: =IFERROR(IFERROR(VLOOKUP($C6&" "&AF$1,Results!$G:$I,3,FALSE),-VLOOKUP($C6&" "&AF$1,Results!$H:$I,2,FALSE)),"") | BW6: =SUM(V6:BT6) -> 354 | BX6: =COUNTIF(E6:J6,1) -> 0 | BY6: =COUNTIF(E6:J6,0) -> 5 | BZ6: =COUNT(E6:J6) -> 5 | CA6: =+BX6/BZ6 -> 0 | CC6: =SUM(V6:BU6) -> 354 | CE6: 2 | CF6: =A6 -> 0 | CG6: =+CE6-CF6 -> 2
B7: 4 | C7: Sunset Ridge | E7: =IF(AND(Y7>0,$A7<VLOOKUP(Y$1,$C:$L,10,FALSE)),1,IF(AND(Y7<0,$A7>VLOOKUP(Y$1,$C:$L,10,FALSE)),1,0)) -> 0 | F7: =IF(AND(Z7>0,$A7<VLOOKUP(Z$1,$C:$L,10,FALSE)),1,IF(AND(Z7<0,$A7>VLOOKUP(Z$1,$C:$L,10,FALSE)),1,0)) -> 0 | G7: =IF(AND(AA7>0,$A7<VLOOKUP(AA$1,$C:$L,10,FALSE)),1,IF(AND(AA7<0,$A7>VLOOKUP(AA$1,$C:$L,10,FALSE)),1,0)) -> 0 | H7: =IF(AND(AC7>0,$A7<VLOOKUP(AC$1,$C:$L,10,FALSE)),1,IF(AND(AC7<0,$A7>VLOOKUP(AC$1,$C:$L,10,FALSE)),1,0)) -> 0 | I7: =IF(AND(AD7>0,$A7<VLOOKUP(AD$1,$C:$L,10,FALSE)),1,IF(AND(AD7<0,$A7>VLOOKUP(AD$1,$C:$L,10,FALSE)),1,0)) -> 0 | J7: =IF(AND(AE7>0,$A7<VLOOKUP(AE$1,$C:$L,10,FALSE)),1,IF(AND(AE7<0,$A7>VLOOKUP(AE$1,$C:$L,10,FALSE)),1,0)) -> 0 | K7: Updated | L7: =A7 -> 0 | M7: 1 | N7: =COUNTIF($V7:$BU7,">0") -> 4 | O7: =COUNTIF($V7:$BU7,"<0") -> 2 | P7: =COUNTIF($V7:$BU7,"=0") -> 0 | Q7: =COUNTIF($Y7:$AB7,">0") -> 1 | R7: =COUNTIF($Y7:$AB7,"<0") -> 2 | S7: =COUNTIF($Y7:$AB7,"=0") -> 0 | T7: =COUNTIF(V7:BJ7,"NC") -> 0 | V7: =IFERROR(IFERROR(VLOOKUP($C7&" "&V$1,Results!$G:$I,3,FALSE),-VLOOKUP($C7&" "&V$1,Results!$H:$I,2,FALSE)),"") | W7: =IFERROR(IFERROR(VLOOKUP($C7&" "&W$1,Results!$G:$I,3,FALSE),-VLOOKUP($C7&" "&W$1,Results!$H:$I,2,FALSE)),"") | X7: =IFERROR(IFERROR(VLOOKUP($C7&" "&X$1,Results!$G:$I,3,FALSE),-VLOOKUP($C7&" "&X$1,Results!$H:$I,2,FALSE)),"") | Y7: =IFERROR(IFERROR(VLOOKUP($C7&" "&Y$1,Results!$G:$I,3,FALSE),-VLOOKUP($C7&" "&Y$1,Results!$H:$I,2,FALSE)),"") -> -82 | Z7: =IFERROR(IFERROR(VLOOKUP($C7&" "&Z$1,Results!$G:$I,3,FALSE),-VLOOKUP($C7&" "&Z$1,Results!$H:$I,2,FALSE)),"") -> 16 | AA7: =IFERROR(IFERROR(VLOOKUP($C7&" "&AA$1,Results!$G:$I,3,FALSE),-VLOOKUP($C7&" "&AA$1,Results!$H:$I,2,FALSE)),"") -> -155 | AB7: =IFERROR(IFERROR(VLOOKUP($C7&" "&AB$1,Results!$G:$I,3,FALSE),-VLOOKUP($C7&" "&AB$1,Results!$H:$I,2,FALSE)),"") | AC7: =IFERROR(IFERROR(VLOOKUP($C7&" "&AC$1,Results!$G:$I,3,FALSE),-VLOOKUP($C7&" "&AC$1,Results!$H:$I,2,FALSE)),"") -> 39 | ... AF7: =IFERROR(IFERROR(VLOOKUP($C7&" "&AF$1,Results!$G:$I,3,FALSE),-VLOOKUP($C7&" "&AF$1,Results!$H:$I,2,FALSE)),"") | BW7: =SUM(V7:BT7) -> -37 | BX7: =COUNTIF(E7:J7,1) -> 0 | BY7: =COUNTIF(E7:J7,0) -> 6 | BZ7: =COUNT(E7:J7) -> 6 | CA7: =+BX7/BZ7 -> 0 | CC7: =SUM(V7:BU7) -> -37 | CE7: 9 | CF7: =A7 -> 0 | CG7: =+CE7-CF7 -> 9
B8: 5 | C8: Medfield | E8: =IF(AND(Z8>0,$A8<VLOOKUP(Z$1,$C:$L,10,FALSE)),1,IF(AND(Z8<0,$A8>VLOOKUP(Z$1,$C:$L,10,FALSE)),1,0)) -> 0 | F8: =IF(AND(AA8>0,$A8<VLOOKUP(AA$1,$C:$L,10,FALSE)),1,IF(AND(AA8<0,$A8>VLOOKUP(AA$1,$C:$L,10,FALSE)),1,0)) -> 0 | G8: =IF(AND(AB8>0,$A8<VLOOKUP(AB$1,$C:$L,10,FALSE)),1,IF(AND(AB8<0,$A8>VLOOKUP(AB$1,$C:$L,10,FALSE)),1,0)) -> 0 | H8: =IF(AND(AD8>0,$A8<VLOOKUP(AD$1,$C:$L,10,FALSE)),1,IF(AND(AD8<0,$A8>VLOOKUP(AD$1,$C:$L,10,FALSE)),1,0)) -> 0 | I8: =IF(AND(AE8>0,$A8<VLOOKUP(AE$1,$C:$L,10,FALSE)),1,IF(AND(AE8<0,$A8>VLOOKUP(AE$1,$C:$L,10,FALSE)),1,0)) -> 0 | J8: =IF(AND(AF8>0,$A8<VLOOKUP(AF$1,$C:$L,10,FALSE)),1,IF(AND(AF8<0,$A8>VLOOKUP(AF$1,$C:$L,10,FALSE)),1,0)) -> 0 | K8: Updated | L8: =A8 -> 0 | M8: 2 | N8: =COUNTIF($V8:$BU8,">0") -> 2 | O8: =COUNTIF($V8:$BU8,"<0") -> 4 | P8: =COUNTIF($V8:$BU8,"=0") -> 0 | Q8: =COUNTIF($AC8:$AF8,">0") -> 2 | R8: =COUNTIF($AC8:$AF8,"<0") -> 1 | S8: =COUNTIF($AC8:$AF8,"=0") -> 0 | T8: =COUNTIF(V8:BJ8,"NC") -> 0 | Y8: =IFERROR(IFERROR(VLOOKUP($C8&" "&Y$1,Results!$G:$I,3,FALSE),-VLOOKUP($C8&" "&Y$1,Results!$H:$I,2,FALSE)),"") | Z8: =IFERROR(IFERROR(VLOOKUP($C8&" "&Z$1,Results!$G:$I,3,FALSE),-VLOOKUP($C8&" "&Z$1,Results!$H:$I,2,FALSE)),"") -> -95 | AA8: =IFERROR(IFERROR(VLOOKUP($C8&" "&AA$1,Results!$G:$I,3,FALSE),-VLOOKUP($C8&" "&AA$1,Results!$H:$I,2,FALSE)),"") -> -159 | AB8: =IFERROR(IFERROR(VLOOKUP($C8&" "&AB$1,Results!$G:$I,3,FALSE),-VLOOKUP($C8&" "&AB$1,Results!$H:$I,2,FALSE)),"") -> -39 | AC8: =IFERROR(IFERROR(VLOOKUP($C8&" "&AC$1,Results!$G:$I,3,FALSE),-VLOOKUP($C8&" "&AC$1,Results!$H:$I,2,FALSE)),"") | AD8: =IFERROR(IFERROR(VLOOKUP($C8&" "&AD$1,Results!$G:$I,3,FALSE),-VLOOKUP($C8&" "&AD$1,Results!$H:$I,2,FALSE)),"") -> -39 | AE8: =IFERROR(IFERROR(VLOOKUP($C8&" "&AE$1,Results!$G:$I,3,FALSE),-VLOOKUP($C8&" "&AE$1,Results!$H:$I,2,FALSE)),"") -> 152 | AF8: =IFERROR(IFERROR(VLOOKUP($C8&" "&AF$1,Results!$G:$I,3,FALSE),-VLOOKUP($C8&" "&AF$1,Results!$H:$I,2,FALSE)),"") -> 59 | ... AJ8: =IFERROR(IFERROR(VLOOKUP($C8&" "&AJ$1,Results!$G:$I,3,FALSE),-VLOOKUP($C8&" "&AJ$1,Results!$H:$I,2,FALSE)),"") | BW8: =SUM(V8:BT8) -> -121 | BX8: =COUNTIF(E8:J8,1) -> 0 | BY8: =COUNTIF(E8:I8,0) -> 5 | BZ8: =COUNT(E8:J8) -> 6 | CA8: =+BX8/BZ8 -> 0 | CC8: =SUM(V8:BU8) -> -121 | CE8: 4 | CF8: =A8 -> 0 | CG8: =+CE8-CF8 -> 4
B9: 6 | C9: Prestonwood | E9: =IF(AND(AA9>0,$A9<VLOOKUP(AA$1,$C:$L,10,FALSE)),1,IF(AND(AA9<0,$A9>VLOOKUP(AA$1,$C:$L,10,FALSE)),1,0)) -> 0 | F9: =IF(AND(AB9>0,$A9<VLOOKUP(AB$1,$C:$L,10,FALSE)),1,IF(AND(AB9<0,$A9>VLOOKUP(AB$1,$C:$L,10,FALSE)),1,0)) -> 0 | G9: =IF(AND(AC9>0,$A9<VLOOKUP(AC$1,$C:$L,10,FALSE)),1,IF(AND(AC9<0,$A9>VLOOKUP(AC$1,$C:$L,10,FALSE)),1,0)) -> 0 | H9: =IF(AND(AE9>0,$A9<VLOOKUP(AE$1,$C:$L,10,FALSE)),1,IF(AND(AE9<0,$A9>VLOOKUP(AE$1,$C:$L,10,FALSE)),1,0)) -> 0 | I9: =IF(AND(AF9>0,$A9<VLOOKUP(AF$1,$C:$L,10,FALSE)),1,IF(AND(AF9<0,$A9>VLOOKUP(AF$1,$C:$L,10,FALSE)),1,0)) -> 0 | J9: =IF(AND(AG9>0,$A9<VLOOKUP(AG$1,$C:$L,10,FALSE)),1,IF(AND(AG9<0,$A9>VLOOKUP(AG$1,$C:$L,10,FALSE)),1,0)) -> 0 | K9: Updated | L9: =A9 -> 0 | M9: 2 | N9: =COUNTIF($V9:$BU9,">0") -> 4 | O9: =COUNTIF($V9:$BU9,"<0") -> 2 | P9: =COUNTIF($V9:$BU9,"=0") -> 0 | Q9: =COUNTIF($AC9:$AF9,">0") -> 3 | R9: =COUNTIF($AC9:$AF9,"<0") -> 0 | S9: =COUNTIF($AC9:$AF9,"=0") -> 0 | T9: =COUNTIF(V9:BJ9,"NC") -> 0 | Y9: =IFERROR(IFERROR(VLOOKUP($C9&" "&Y$1,Results!$G:$I,3,FALSE),-VLOOKUP($C9&" "&Y$1,Results!$H:$I,2,FALSE)),"") | Z9: =IFERROR(IFERROR(VLOOKUP($C9&" "&Z$1,Results!$G:$I,3,FALSE),-VLOOKUP($C9&" "&Z$1,Results!$H:$I,2,FALSE)),"") | AA9: =IFERROR(IFERROR(VLOOKUP($C9&" "&AA$1,Results!$G:$I,3,FALSE),-VLOOKUP($C9&" "&AA$1,Results!$H:$I,2,FALSE)),"") -> -78 | AB9: =IFERROR(IFERROR(VLOOKUP($C9&" "&AB$1,Results!$G:$I,3,FALSE),-VLOOKUP($C9&" "&AB$1,Results!$H:$I,2,FALSE)),"") -> -10 | AC9: =IFERROR(IFERROR(VLOOKUP($C9&" "&AC$1,Results!$G:$I,3,FALSE),-VLOOKUP($C9&" "&AC$1,Results!$H:$I,2,FALSE)),"") -> 39 | AD9: =IFERROR(IFERROR(VLOOKUP($C9&" "&AD$1,Results!$G:$I,3,FALSE),-VLOOKUP($C9&" "&AD$1,Results!$H:$I,2,FALSE)),"") | AE9: =IFERROR(IFERROR(VLOOKUP($C9&" "&AE$1,Results!$G:$I,3,FALSE),-VLOOKUP($C9&" "&AE$1,Results!$H:$I,2,FALSE)),"") -> 180 | AF9: =IFERROR(IFERROR(VLOOKUP($C9&" "&AF$1,Results!$G:$I,3,FALSE),-VLOOKUP($C9&" "&AF$1,Results!$H:$I,2,FALSE)),"") -> 2 | ... AJ9: =IFERROR(IFERROR(VLOOKUP($C9&" "&AJ$1,Results!$G:$I,3,FALSE),-VLOOKUP($C9&" "&AJ$1,Results!$H:$I,2,FALSE)),"") | BW9: =SUM(V9:BT9) -> 137 | BX9: =COUNTIF(E9:J9,1) -> 0 | BY9: =COUNTIF(E9:I9,0) -> 5 | BZ9: =COUNT(E9:J9) -> 6 | CA9: =+BX9/BZ9 -> 0 | CC9: =SUM(V9:BU9) -> 137 | CE9: 7 | CF9: =A9 -> 0 | CG9: =+CE9-CF9 -> 7
B10: 7 | C10: Abbington | E10: =IF(AND(AB10>0,$A10<VLOOKUP(AB$1,$C:$L,10,FALSE)),1,IF(AND(AB10<0,$A10>VLOOKUP(AB$1,$C:$L,10,FALSE)),1,0)) -> 0 | F10: =IF(AND(AC10>0,$A10<VLOOKUP(AC$1,$C:$L,10,FALSE)),1,IF(AND(AC10<0,$A10>VLOOKUP(AC$1,$C:$L,10,FALSE)),1,0)) -> 0 | G10: =IF(AND(AD10>0,$A10<VLOOKUP(AD$1,$C:$L,10,FALSE)),1,IF(AND(AD10<0,$A10>VLOOKUP(AD$1,$C:$L,10,FALSE)),1,0)) -> 0 | H10: =IF(AND(AF10>0,$A10<VLOOKUP(AF$1,$C:$L,10,FALSE)),1,IF(AND(AF10<0,$A10>VLOOKUP(AF$1,$C:$L,10,FALSE)),1,0)) -> 0 | I10: =IF(AND(AG10>0,$A10<VLOOKUP(AG$1,$C:$L,10,FALSE)),1,IF(AND(AG10<0,$A10>VLOOKUP(AG$1,$C:$L,10,FALSE)),1,0)) -> 0 | J10: =IF(AND(AH10>0,$A10<VLOOKUP(AH$1,$C:$L,10,FALSE)),1,IF(AND(AH10<0,$A10>VLOOKUP(AH$1,$C:$L,10,FALSE)),1,0)) -> 0 | K10: Updated | L10: =A10 -> 0 | M10: 2 | N10: =COUNTIF($V10:$BU10,">0") -> 0 | O10: =COUNTIF($V10:$BU10,"<0") -> 6 | P10: =COUNTIF($V10:$BU10,"=0") -> 0 | Q10: =COUNTIF($AC10:$AF10,">0") -> 0 | R10: =COUNTIF($AC10:$AF10,"<0") -> 3 | S10: =COUNTIF($AC10:$AF10,"=0") -> 0 | T10: =COUNTIF(V10:BJ10,"NC") -> 0 | Y10: =IFERROR(IFERROR(VLOOKUP($C10&" "&Y$1,Results!$G:$I,3,FALSE),-VLOOKUP($C10&" "&Y$1,Results!$H:$I,2,FALSE)),"") | Z10: =IFERROR(IFERROR(VLOOKUP($C10&" "&Z$1,Results!$G:$I,3,FALSE),-VLOOKUP($C10&" "&Z$1,Results!$H:$I,2,FALSE)),"") | AA10: =IFERROR(IFERROR(VLOOKUP($C10&" "&AA$1,Results!$G:$I,3,FALSE),-VLOOKUP($C10&" "&AA$1,Results!$H:$I,2,FALSE)),"") | AB10: =IFERROR(IFERROR(VLOOKUP($C10&" "&AB$1,Results!$G:$I,3,FALSE),-VLOOKUP($C10&" "&AB$1,Results!$H:$I,2,FALSE)),"") -> -135 | AC10: =IFERROR(IFERROR(VLOOKUP($C10&" "&AC$1,Results!$G:$I,3,FALSE),-VLOOKUP($C10&" "&AC$1,Results!$H:$I,2,FALSE)),"") -> -152 | AD10: =IFERROR(IFERROR(VLOOKUP($C10&" "&AD$1,Results!$G:$I,3,FALSE),-VLOOKUP($C10&" "&AD$1,Results!$H:$I,2,FALSE)),"") -> -180 | AE10: =IFERROR(IFERROR(VLOOKUP($C10&" "&AE$1,Results!$G:$I,3,FALSE),-VLOOKUP($C10&" "&AE$1,Results!$H:$I,2,FALSE)),"") | AF10: =IFERROR(IFERROR(VLOOKUP($C10&" "&AF$1,Results!$G:$I,3,FALSE),-VLOOKUP($C10&" "&AF$1,Results!$H:$I,2,FALSE)),"") -> -20 | ... AJ10: =IFERROR(IFERROR(VLOOKUP($C10&" "&AJ$1,Results!$G:$I,3,FALSE),-VLOOKUP($C10&" "&AJ$1,Results!$H:$I,2,FALSE)),"") | BW10: =SUM(V10:BT10) -> -663 | BX10: =COUNTIF(E10:J10,1) -> 0 | BY10: =COUNTIF(E10:I10,0) -> 5 | BZ10: =COUNT(E10:J10) -> 6 | CA10: =+BX10/BZ10 -> 0 | CC10: =SUM(V10:BU10) -> -663 | CE10: 6 | CF10: =A10 -> 0 | CG10: =+CE10-CF10 -> 6
B11: 8 | C11: Lochmere | E11: =IF(AND(AC11>0,$A11<VLOOKUP(AC$1,$C:$L,10,FALSE)),1,IF(AND(AC11<0,$A11>VLOOKUP(AC$1,$C:$L,10,FALSE)),1,0)) -> 0 | F11: =IF(AND(AD11>0,$A11<VLOOKUP(AD$1,$C:$L,10,FALSE)),1,IF(AND(AD11<0,$A11>VLOOKUP(AD$1,$C:$L,10,FALSE)),1,0)) -> 0 | G11: =IF(AND(AE11>0,$A11<VLOOKUP(AE$1,$C:$L,10,FALSE)),1,IF(AND(AE11<0,$A11>VLOOKUP(AE$1,$C:$L,10,FALSE)),1,0)) -> 0 | H11: =IF(AND(AG11>0,$A11<VLOOKUP(AG$1,$C:$L,10,FALSE)),1,IF(AND(AG11<0,$A11>VLOOKUP(AG$1,$C:$L,10,FALSE)),1,0)) -> 0 | I11: =IF(AND(AH11>0,$A11<VLOOKUP(AH$1,$C:$L,10,FALSE)),1,IF(AND(AH11<0,$A11>VLOOKUP(AH$1,$C:$L,10,FALSE)),1,0)) -> 0 | J11: =IF(AND(AI11>0,$A11<VLOOKUP(AI$1,$C:$L,10,FALSE)),1,IF(AND(AI11<0,$A11>VLOOKUP(AI$1,$C:$L,10,FALSE)),1,0)) -> 0 | K11: Updated | L11: =A11 -> 0 | M11: 2 | N11: =COUNTIF($V11:$BU11,">0") -> 1 | O11: =COUNTIF($V11:$BU11,"<0") -> 5 | P11: =COUNTIF($V11:$BU11,"=0") -> 0 | Q11: =COUNTIF($AC11:$AF11,">0") -> 1 | R11: =COUNTIF($AC11:$AF11,"<0") -> 2 | S11: =COUNTIF($AC11:$AF11,"=0") -> 0 | T11: =COUNTIF(V11:BJ11,"NC") -> 0 | Y11: =IFERROR(IFERROR(VLOOKUP($C11&" "&Y$1,Results!$G:$I,3,FALSE),-VLOOKUP($C11&" "&Y$1,Results!$H:$I,2,FALSE)),"") | Z11: =IFERROR(IFERROR(VLOOKUP($C11&" "&Z$1,Results!$G:$I,3,FALSE),-VLOOKUP($C11&" "&Z$1,Results!$H:$I,2,FALSE)),"") | AA11: =IFERROR(IFERROR(VLOOKUP($C11&" "&AA$1,Results!$G:$I,3,FALSE),-VLOOKUP($C11&" "&AA$1,Results!$H:$I,2,FALSE)),"") | AB11: =IFERROR(IFERROR(VLOOKUP($C11&" "&AB$1,Results!$G:$I,3,FALSE),-VLOOKUP($C11&" "&AB$1,Results!$H:$I,2,FALSE)),"") | AC11: =IFERROR(IFERROR(VLOOKUP($C11&" "&AC$1,Results!$G:$I,3,FALSE),-VLOOKUP($C11&" "&AC$1,Results!$H:$I,2,FALSE)),"") -> -59 | AD11: =IFERROR(IFERROR(VLOOKUP($C11&" "&AD$1,Results!$G:$I,3,FALSE),-VLOOKUP($C11&" "&AD$1,Results!$H:$I,2,FALSE)),"") -> -2 | AE11: =IFERROR(IFERROR(VLOOKUP($C11&" "&AE$1,Results!$G:$I,3,FALSE),-VLOOKUP($C11&" "&AE$1,Results!$H:$I,2,FALSE)),"") -> 20 | AF11: =IFERROR(IFERROR(VLOOKUP($C11&" "&AF$1,Results!$G:$I,3,FALSE),-VLOOKUP($C11&" "&AF$1,Results!$H:$I,2,FALSE)),"") | ... AJ11: =IFERROR(IFERROR(VLOOKUP($C11&" "&AJ$1,Results!$G:$I,3,FALSE),-VLOOKUP($C11&" "&AJ$1,Results!$H:$I,2,FALSE)),"") | BW11: =SUM(V11:BT11) -> -124 | BX11: =COUNTIF(E11:J11,1) -> 0 | BY11: =COUNTIF(E11:I11,0) -> 5 | BZ11: =COUNT(E11:J11) -> 6 | CA11: =+BX11/BZ11 -> 0 | CC11: =SUM(V11:BU11) -> -124 | CE11: 5 | CF11: =A11 -> 0 | CG11: =+CE11-CF11 -> 5
B12: 9 | C12: Olive Chapel | E12: =IF(AND(AD12>0,$A12<VLOOKUP(AD$1,$C:$L,10,FALSE)),1,IF(AND(AD12<0,$A12>VLOOKUP(AD$1,$C:$L,10,FALSE)),1,0)) -> 0 | F12: =IF(AND(AE12>0,$A12<VLOOKUP(AE$1,$C:$L,10,FALSE)),1,IF(AND(AE12<0,$A12>VLOOKUP(AE$1,$C:$L,10,FALSE)),1,0)) -> 0 | G12: =IF(AND(AF12>0,$A12<VLOOKUP(AF$1,$C:$L,10,FALSE)),1,IF(AND(AF12<0,$A12>VLOOKUP(AF$1,$C:$L,10,FALSE)),1,0)) -> 0 | H12: =IF(AND(AH12>0,$A12<VLOOKUP(AH$1,$C:$L,10,FALSE)),1,IF(AND(AH12<0,$A12>VLOOKUP(AH$1,$C:$L,10,FALSE)),1,0)) -> 0 | I12: =IF(AND(AI12>0,$A12<VLOOKUP(AI$1,$C:$L,10,FALSE)),1,IF(AND(AI12<0,$A12>VLOOKUP(AI$1,$C:$L,10,FALSE)),1,0)) -> 0 | J12: =IF(AND(AJ12>0,$A12<VLOOKUP(AJ$1,$C:$L,10,FALSE)),1,IF(AND(AJ12<0,$A12>VLOOKUP(AJ$1,$C:$L,10,FALSE)),1,0)) -> 0 | K12: Updated | L12: =A12 -> 0 | M12: 3 | N12: =COUNTIF($V12:$BU12,">0") -> 3 | O12: =COUNTIF($V12:$BU12,"<0") -> 3 | P12: =COUNTIF($V12:$BU12,"=0") -> 0 | Q12: =COUNTIF($AG12:$AJ12,">0") -> 1 | R12: =COUNTIF($AG12:$AJ12,"<0") -> 2 | S12: =COUNTIF($AG12:$AJ12,"=0") -> 0 | T12: =COUNTIF(V12:BJ12,"NC") -> 0 | AC12: =IFERROR(IFERROR(VLOOKUP($C12&" "&AC$1,Results!$G:$I,3,FALSE),-VLOOKUP($C12&" "&AC$1,Results!$H:$I,2,FALSE)),"") | AD12: =IFERROR(IFERROR(VLOOKUP($C12&" "&AD$1,Results!$G:$I,3,FALSE),-VLOOKUP($C12&" "&AD$1,Results!$H:$I,2,FALSE)),"") -> -4 | AE12: =IFERROR(IFERROR(VLOOKUP($C12&" "&AE$1,Results!$G:$I,3,FALSE),-VLOOKUP($C12&" "&AE$1,Results!$H:$I,2,FALSE)),"") -> 71 | AF12: =IFERROR(IFERROR(VLOOKUP($C12&" "&AF$1,Results!$G:$I,3,FALSE),-VLOOKUP($C12&" "&AF$1,Results!$H:$I,2,FALSE)),"") -> 19 | AG12: =IFERROR(IFERROR(VLOOKUP($C12&" "&AG$1,Results!$G:$I,3,FALSE),-VLOOKUP($C12&" "&AG$1,Results!$H:$I,2,FALSE)),"") | AH12: =IFERROR(IFERROR(VLOOKUP($C12&" "&AH$1,Results!$G:$I,3,FALSE),-VLOOKUP($C12&" "&AH$1,Results!$H:$I,2,FALSE)),"") -> -12 | AI12: =IFERROR(IFERROR(VLOOKUP($C12&" "&AI$1,Results!$G:$I,3,FALSE),-VLOOKUP($C12&" "&AI$1,Results!$H:$I,2,FALSE)),"") -> -46 | AJ12: =IFERROR(IFERROR(VLOOKUP($C12&" "&AJ$1,Results!$G:$I,3,FALSE),-VLOOKUP($C12&" "&AJ$1,Results!$H:$I,2,FALSE)),"") -> 3 | ... AN12: =IFERROR(IFERROR(VLOOKUP($C12&" "&AN$1,Results!$G:$I,3,FALSE),-VLOOKUP($C12&" "&AN$1,Results!$H:$I,2,FALSE)),"") | BW12: =SUM(V12:BT12) -> 31 | BX12: =COUNTIF(E12:J12,1) -> 0 | BY12: =COUNTIF(E12:I12,0) -> 5 | BZ12: =COUNT(E12:J12) -> 6 | CA12: =+BX12/BZ12 -> 0 | CC12: =SUM(V12:BU12) -> 31 | CE12: 16 | CF12: =A12 -> 0 | CG12: =+CE12-CF12 -> 16
B13: 10 | C13: Scottish Hills | E13: =IF(AND(AE13>0,$A13<VLOOKUP(AE$1,$C:$L,10,FALSE)),1,IF(AND(AE13<0,$A13>VLOOKUP(AE$1,$C:$L,10,FALSE)),1,0)) -> 0 | F13: =IF(AND(AF13>0,$A13<VLOOKUP(AF$1,$C:$L,10,FALSE)),1,IF(AND(AF13<0,$A13>VLOOKUP(AF$1,$C:$L,10,FALSE)),1,0)) -> 0 | G13: =IF(AND(AG13>0,$A13<VLOOKUP(AG$1,$C:$L,10,FALSE)),1,IF(AND(AG13<0,$A13>VLOOKUP(AG$1,$C:$L,10,FALSE)),1,0)) -> 0 | H13: =IF(AND(AI13>0,$A13<VLOOKUP(AI$1,$C:$L,10,FALSE)),1,IF(AND(AI13<0,$A13>VLOOKUP(AI$1,$C:$L,10,FALSE)),1,0)) -> 0 | I13: =IF(AND(AJ13>0,$A13<VLOOKUP(AJ$1,$C:$L,10,FALSE)),1,IF(AND(AJ13<0,$A13>VLOOKUP(AJ$1,$C:$L,10,FALSE)),1,0)) -> 0 | J13: =IF(AND(AK13>0,$A13<VLOOKUP(AK$1,$C:$L,10,FALSE)),1,IF(AND(AK13<0,$A13>VLOOKUP(AK$1,$C:$L,10,FALSE)),1,0)) -> 0 | K13: Updated | L13: =A13 -> 0 | M13: 3 | N13: =COUNTIF($V13:$BU13,">0") -> 6 | O13: =COUNTIF($V13:$BU13,"<0") -> 0 | P13: =COUNTIF($V13:$BU13,"=0") -> 0 | Q13: =COUNTIF($AG13:$AJ13,">0") -> 3 | R13: =COUNTIF($AG13:$AJ13,"<0") -> 0 | S13: =COUNTIF($AG13:$AJ13,"=0") -> 0 | T13: =COUNTIF(V13:BJ13,"NC") -> 0 | AC13: =IFERROR(IFERROR(VLOOKUP($C13&" "&AC$1,Results!$G:$I,3,FALSE),-VLOOKUP($C13&" "&AC$1,Results!$H:$I,2,FALSE)),"") | AD13: =IFERROR(IFERROR(VLOOKUP($C13&" "&AD$1,Results!$G:$I,3,FALSE),-VLOOKUP($C13&" "&AD$1,Results!$H:$I,2,FALSE)),"") | AE13: =IFERROR(IFERROR(VLOOKUP($C13&" "&AE$1,Results!$G:$I,3,FALSE),-VLOOKUP($C13&" "&AE$1,Results!$H:$I,2,FALSE)),"") -> 105 | AF13: =IFERROR(IFERROR(VLOOKUP($C13&" "&AF$1,Results!$G:$I,3,FALSE),-VLOOKUP($C13&" "&AF$1,Results!$H:$I,2,FALSE)),"") -> 13 | AG13: =IFERROR(IFERROR(VLOOKUP($C13&" "&AG$1,Results!$G:$I,3,FALSE),-VLOOKUP($C13&" "&AG$1,Results!$H:$I,2,FALSE)),"") -> 12 | AH13: =IFERROR(IFERROR(VLOOKUP($C13&" "&AH$1,Results!$G:$I,3,FALSE),-VLOOKUP($C13&" "&AH$1,Results!$H:$I,2,FALSE)),"") | AI13: =IFERROR(IFERROR(VLOOKUP($C13&" "&AI$1,Results!$G:$I,3,FALSE),-VLOOKUP($C13&" "&AI$1,Results!$H:$I,2,FALSE)),"") -> 46 | AJ13: =IFERROR(IFERROR(VLOOKUP($C13&" "&AJ$1,Results!$G:$I,3,FALSE),-VLOOKUP($C13&" "&AJ$1,Results!$H:$I,2,FALSE)),"") -> 46 | ... AN13: =IFERROR(IFERROR(VLOOKUP($C13&" "&AN$1,Results!$G:$I,3,FALSE),-VLOOKUP($C13&" "&AN$1,Results!$H:$I,2,FALSE)),"") | BW13: =SUM(V13:BT13) -> 287 | BX13: =COUNTIF(E13:J13,1) -> 0 | BY13: =COUNTIF(E13:I13,0) -> 5 | BZ13: =COUNT(E13:J13) -> 6 | CA13: =+BX13/BZ13 -> 0 | CC13: =SUM(V13:BU13) -> 287 | CE13: 8 | CF13: =A13 -> 0 | CG13: =+CE13-CF13 -> 8
B14: 11 | C14: Walden Creek | E14: =IF(AND(AF14>0,$A14<VLOOKUP(AF$1,$C:$L,10,FALSE)),1,IF(AND(AF14<0,$A14>VLOOKUP(AF$1,$C:$L,10,FALSE)),1,0)) -> 0 | F14: =IF(AND(AG14>0,$A14<VLOOKUP(AG$1,$C:$L,10,FALSE)),1,IF(AND(AG14<0,$A14>VLOOKUP(AG$1,$C:$L,10,FALSE)),1,0)) -> 0 | G14: =IF(AND(AH14>0,$A14<VLOOKUP(AH$1,$C:$L,10,FALSE)),1,IF(AND(AH14<0,$A14>VLOOKUP(AH$1,$C:$L,10,FALSE)),1,0)) -> 0 | H14: =IF(AND(AJ14>0,$A14<VLOOKUP(AJ$1,$C:$L,10,FALSE)),1,IF(AND(AJ14<0,$A14>VLOOKUP(AJ$1,$C:$L,10,FALSE)),1,0)) -> 0 | I14: =IF(AND(AK14>0,$A14<VLOOKUP(AK$1,$C:$L,10,FALSE)),1,IF(AND(AK14<0,$A14>VLOOKUP(AK$1,$C:$L,10,FALSE)),1,0)) -> 0 | J14: =IF(AND(AL14>0,$A14<VLOOKUP(AL$1,$C:$L,10,FALSE)),1,IF(AND(AL14<0,$A14>VLOOKUP(AL$1,$C:$L,10,FALSE)),1,0)) -> 0 | K14: Updated | L14: =A14 -> 0 | M14: 3 | N14: =COUNTIF($V14:$BU14,">0") -> 5 | O14: =COUNTIF($V14:$BU14,"<0") -> 1 | P14: =COUNTIF($V14:$BU14,"=0") -> 0 | Q14: =COUNTIF($AG14:$AJ14,">0") -> 2 | R14: =COUNTIF($AG14:$AJ14,"<0") -> 1 | S14: =COUNTIF($AG14:$AJ14,"=0") -> 0 | T14: =COUNTIF(V14:BJ14,"NC") -> 0 | AC14: =IFERROR(IFERROR(VLOOKUP($C14&" "&AC$1,Results!$G:$I,3,FALSE),-VLOOKUP($C14&" "&AC$1,Results!$H:$I,2,FALSE)),"") | AD14: =IFERROR(IFERROR(VLOOKUP($C14&" "&AD$1,Results!$G:$I,3,FALSE),-VLOOKUP($C14&" "&AD$1,Results!$H:$I,2,FALSE)),"") | AE14: =IFERROR(IFERROR(VLOOKUP($C14&" "&AE$1,Results!$G:$I,3,FALSE),-VLOOKUP($C14&" "&AE$1,Results!$H:$I,2,FALSE)),"") | AF14: =IFERROR(IFERROR(VLOOKUP($C14&" "&AF$1,Results!$G:$I,3,FALSE),-VLOOKUP($C14&" "&AF$1,Results!$H:$I,2,FALSE)),"") -> 51 | AG14: =IFERROR(IFERROR(VLOOKUP($C14&" "&AG$1,Results!$G:$I,3,FALSE),-VLOOKUP($C14&" "&AG$1,Results!$H:$I,2,FALSE)),"") -> 46 | AH14: =IFERROR(IFERROR(VLOOKUP($C14&" "&AH$1,Results!$G:$I,3,FALSE),-VLOOKUP($C14&" "&AH$1,Results!$H:$I,2,FALSE)),"") -> -46 | AI14: =IFERROR(IFERROR(VLOOKUP($C14&" "&AI$1,Results!$G:$I,3,FALSE),-VLOOKUP($C14&" "&AI$1,Results!$H:$I,2,FALSE)),"") | AJ14: =IFERROR(IFERROR(VLOOKUP($C14&" "&AJ$1,Results!$G:$I,3,FALSE),-VLOOKUP($C14&" "&AJ$1,Results!$H:$I,2,FALSE)),"") -> 21 | ... AN14: =IFERROR(IFERROR(VLOOKUP($C14&" "&AN$1,Results!$G:$I,3,FALSE),-VLOOKUP($C14&" "&AN$1,Results!$H:$I,2,FALSE)),"") | BW14: =SUM(V14:BT14) -> 113 | BX14: =COUNTIF(E14:J14,1) -> 0 | BY14: =COUNTIF(E14:I14,0) -> 5 | BZ14: =COUNT(E14:J14) -> 6 | CA14: =+BX14/BZ14 -> 0 | CC14: =SUM(V14:BU14) -> 113 | CE14: 10 | CF14: =A14 -> 0 | CG14: =+CE14-CF14 -> 10
B15: 12 | C15: Cary | E15: =IF(AND(AG15>0,$A15<VLOOKUP(AG$1,$C:$L,10,FALSE)),1,IF(AND(AG15<0,$A15>VLOOKUP(AG$1,$C:$L,10,FALSE)),1,0)) -> 0 | F15: =IF(AND(AH15>0,$A15<VLOOKUP(AH$1,$C:$L,10,FALSE)),1,IF(AND(AH15<0,$A15>VLOOKUP(AH$1,$C:$L,10,FALSE)),1,0)) -> 0 | G15: =IF(AND(AI15>0,$A15<VLOOKUP(AI$1,$C:$L,10,FALSE)),1,IF(AND(AI15<0,$A15>VLOOKUP(AI$1,$C:$L,10,FALSE)),1,0)) -> 0 | H15: =IF(AND(AK15>0,$A15<VLOOKUP(AK$1,$C:$L,10,FALSE)),1,IF(AND(AK15<0,$A15>VLOOKUP(AK$1,$C:$L,10,FALSE)),1,0)) -> 0 | I15: =IF(AND(AL15>0,$A15<VLOOKUP(AL$1,$C:$L,10,FALSE)),1,IF(AND(AL15<0,$A15>VLOOKUP(AL$1,$C:$L,10,FALSE)),1,0)) -> 0 | J15: =IF(AND(AM15>0,$A15<VLOOKUP(AM$1,$C:$L,10,FALSE)),1,IF(AND(AM15<0,$A15>VLOOKUP(AM$1,$C:$L,10,FALSE)),1,0)) -> 0 | K15: Updated | L15: =A15 -> 0 | M15: 3 | N15: =COUNTIF($V15:$BU15,">0") -> 2 | O15: =COUNTIF($V15:$BU15,"<0") -> 4 | P15: =COUNTIF($V15:$BU15,"=0") -> 0 | Q15: =COUNTIF($AG15:$AJ15,">0") -> 0 | R15: =COUNTIF($AG15:$AJ15,"<0") -> 3 | S15: =COUNTIF($AG15:$AJ15,"=0") -> 0 | T15: =COUNTIF(V15:BJ15,"NC") -> 0 | AC15: =IFERROR(IFERROR(VLOOKUP($C15&" "&AC$1,Results!$G:$I,3,FALSE),-VLOOKUP($C15&" "&AC$1,Results!$H:$I,2,FALSE)),"") | AD15: =IFERROR(IFERROR(VLOOKUP($C15&" "&AD$1,Results!$G:$I,3,FALSE),-VLOOKUP($C15&" "&AD$1,Results!$H:$I,2,FALSE)),"") | AE15: =IFERROR(IFERROR(VLOOKUP($C15&" "&AE$1,Results!$G:$I,3,FALSE),-VLOOKUP($C15&" "&AE$1,Results!$H:$I,2,FALSE)),"") | AF15: =IFERROR(IFERROR(VLOOKUP($C15&" "&AF$1,Results!$G:$I,3,FALSE),-VLOOKUP($C15&" "&AF$1,Results!$H:$I,2,FALSE)),"") | AG15: =IFERROR(IFERROR(VLOOKUP($C15&" "&AG$1,Results!$G:$I,3,FALSE),-VLOOKUP($C15&" "&AG$1,Results!$H:$I,2,FALSE)),"") -> -3 | AH15: =IFERROR(IFERROR(VLOOKUP($C15&" "&AH$1,Results!$G:$I,3,FALSE),-VLOOKUP($C15&" "&AH$1,Results!$H:$I,2,FALSE)),"") -> -46 | AI15: =IFERROR(IFERROR(VLOOKUP($C15&" "&AI$1,Results!$G:$I,3,FALSE),-VLOOKUP($C15&" "&AI$1,Results!$H:$I,2,FALSE)),"") -> -21 | AJ15: =IFERROR(IFERROR(VLOOKUP($C15&" "&AJ$1,Results!$G:$I,3,FALSE),-VLOOKUP($C15&" "&AJ$1,Results!$H:$I,2,FALSE)),"") | ... AN15: =IFERROR(IFERROR(VLOOKUP($C15&" "&AN$1,Results!$G:$I,3,FALSE),-VLOOKUP($C15&" "&AN$1,Results!$H:$I,2,FALSE)),"") | BW15: =SUM(V15:BT15) -> -15 | BX15: =COUNTIF(E15:J15,1) -> 0 | BY15: =COUNTIF(E15:I15,0) -> 5 | BZ15: =COUNT(E15:J15) -> 6 | CA15: =+BX15/BZ15 -> 0 | CC15: =SUM(V15:BU15) -> -15 | CE15: 14 | CF15: =A15 -> 0 | CG15: =+CE15-CF15 -> 14
B16: 13 | C16: Scotts Mill | E16: =IF(AND(AH16>0,$A16<VLOOKUP(AH$1,$C:$L,10,FALSE)),1,IF(AND(AH16<0,$A16>VLOOKUP(AH$1,$C:$L,10,FALSE)),1,0)) -> 0 | F16: =IF(AND(AI16>0,$A16<VLOOKUP(AI$1,$C:$L,10,FALSE)),1,IF(AND(AI16<0,$A16>VLOOKUP(AI$1,$C:$L,10,FALSE)),1,0)) -> 0 | G16: =IF(AND(AJ16>0,$A16<VLOOKUP(AJ$1,$C:$L,10,FALSE)),1,IF(AND(AJ16<0,$A16>VLOOKUP(AJ$1,$C:$L,10,FALSE)),1,0)) -> 0 | H16: =IF(AND(AL16>0,$A16<VLOOKUP(AL$1,$C:$L,10,FALSE)),1,IF(AND(AL16<0,$A16>VLOOKUP(AL$1,$C:$L,10,FALSE)),1,0)) -> 0 | I16: =IF(AND(AM16>0,$A16<VLOOKUP(AM$1,$C:$L,10,FALSE)),1,IF(AND(AM16<0,$A16>VLOOKUP(AM$1,$C:$L,10,FALSE)),1,0)) -> 0 | J16: =IF(AND(AN16>0,$A16<VLOOKUP(AN$1,$C:$L,10,FALSE)),1,IF(AND(AN16<0,$A16>VLOOKUP(AN$1,$C:$L,10,FALSE)),1,0)) -> 0 | K16: Updated | L16: =A16 -> 0 | M16: 4 | N16: =COUNTIF($V16:$BU16,">0") -> 2 | O16: =COUNTIF($V16:$BU16,"<0") -> 3 | P16: =COUNTIF($V16:$BU16,"=0") -> 1 | Q16: =COUNTIF($AK16:$AN16,">0") -> 2 | R16: =COUNTIF($AK16:$AN16,"<0") -> 0 | S16: =COUNTIF($AK16:$AN16,"=0") -> 1 | T16: =COUNTIF(V16:BJ16,"NC") -> 0 | AG16: =IFERROR(IFERROR(VLOOKUP($C16&" "&AG$1,Results!$G:$I,3,FALSE),-VLOOKUP($C16&" "&AG$1,Results!$H:$I,2,FALSE)),"") | AH16: =IFERROR(IFERROR(VLOOKUP($C16&" "&AH$1,Results!$G:$I,3,FALSE),-VLOOKUP($C16&" "&AH$1,Results!$H:$I,2,FALSE)),"") -> -65 | AI16: =IFERROR(IFERROR(VLOOKUP($C16&" "&AI$1,Results!$G:$I,3,FALSE),-VLOOKUP($C16&" "&AI$1,Results!$H:$I,2,FALSE)),"") -> -16 | AJ16: =IFERROR(IFERROR(VLOOKUP($C16&" "&AJ$1,Results!$G:$I,3,FALSE),-VLOOKUP($C16&" "&AJ$1,Results!$H:$I,2,FALSE)),"") -> -30 | AK16: =IFERROR(IFERROR(VLOOKUP($C16&" "&AK$1,Results!$G:$I,3,FALSE),-VLOOKUP($C16&" "&AK$1,Results!$H:$I,2,FALSE)),"") | AL16: =IFERROR(IFERROR(VLOOKUP($C16&" "&AL$1,Results!$G:$I,3,FALSE),-VLOOKUP($C16&" "&AL$1,Results!$H:$I,2,FALSE)),"") -> 0 | AM16: =IFERROR(IFERROR(VLOOKUP($C16&" "&AM$1,Results!$G:$I,3,FALSE),-VLOOKUP($C16&" "&AM$1,Results!$H:$I,2,FALSE)),"") -> 122 | AN16: =IFERROR(IFERROR(VLOOKUP($C16&" "&AN$1,Results!$G:$I,3,FALSE),-VLOOKUP($C16&" "&AN$1,Results!$H:$I,2,FALSE)),"") -> 4 | ... BD16: =IFERROR(IFERROR(VLOOKUP($C16&" "&BD$1,Results!$G:$I,3,FALSE),-VLOOKUP($C16&" "&BD$1,Results!$H:$I,2,FALSE)),"") | BW16: =SUM(V16:BT16) -> 15 | BX16: =COUNTIF(E16:J16,1) -> 0 | BY16: =COUNTIF(E16:I16,0) -> 5 | BZ16: =COUNT(E16:J16) -> 6 | CA16: =+BX16/BZ16 -> 0 | CC16: =SUM(V16:BU16) -> 15 | CE16: 15 | CF16: =A16 -> 0 | CG16: =+CE16-CF16 -> 15
B17: 14 | C17: Weatherstone | E17: =IF(AND(AI17>0,$A17<VLOOKUP(AI$1,$C:$L,10,FALSE)),1,IF(AND(AI17<0,$A17>VLOOKUP(AI$1,$C:$L,10,FALSE)),1,0)) -> 0 | F17: =IF(AND(AJ17>0,$A17<VLOOKUP(AJ$1,$C:$L,10,FALSE)),1,IF(AND(AJ17<0,$A17>VLOOKUP(AJ$1,$C:$L,10,FALSE)),1,0)) -> 0 | G17: =IF(AND(AK17>0,$A17<VLOOKUP(AK$1,$C:$L,10,FALSE)),1,IF(AND(AK17<0,$A17>VLOOKUP(AK$1,$C:$L,10,FALSE)),1,0)) -> 0 | H17: =IF(AND(AM17>0,$A17<VLOOKUP(AM$1,$C:$L,10,FALSE)),1,IF(AND(AM17<0,$A17>VLOOKUP(AM$1,$C:$L,10,FALSE)),1,0)) -> 0 | I17: =IF(AND(AN17>0,$A17<VLOOKUP(AN$1,$C:$L,10,FALSE)),1,IF(AND(AN17<0,$A17>VLOOKUP(AN$1,$C:$L,10,FALSE)),1,0)) -> 0 | J17: =IF(AND(AO17>0,$A17<VLOOKUP(AO$1,$C:$L,10,FALSE)),1,IF(AND(AO17<0,$A17>VLOOKUP(AO$1,$C:$L,10,FALSE)),1,0)) -> 0 | K17: Updated | L17: =A17 -> 0 | M17: 4 | N17: =COUNTIF($V17:$BU17,">0") -> 4 | O17: =COUNTIF($V17:$BU17,"<0") -> 1 | P17: =COUNTIF($V17:$BU17,"=0") -> 1 | Q17: =COUNTIF($AK17:$AN17,">0") -> 2 | R17: =COUNTIF($AK17:$AN17,"<0") -> 0 | S17: =COUNTIF($AK17:$AN17,"=0") -> 1 | T17: =COUNTIF(V17:BJ17,"NC") -> 0 | AG17: =IFERROR(IFERROR(VLOOKUP($C17&" "&AG$1,Results!$G:$I,3,FALSE),-VLOOKUP($C17&" "&AG$1,Results!$H:$I,2,FALSE)),"") | AH17: =IFERROR(IFERROR(VLOOKUP($C17&" "&AH$1,Results!$G:$I,3,FALSE),-VLOOKUP($C17&" "&AH$1,Results!$H:$I,2,FALSE)),"") | AI17: =IFERROR(IFERROR(VLOOKUP($C17&" "&AI$1,Results!$G:$I,3,FALSE),-VLOOKUP($C17&" "&AI$1,Results!$H:$I,2,FALSE)),"") -> -25 | AJ17: =IFERROR(IFERROR(VLOOKUP($C17&" "&AJ$1,Results!$G:$I,3,FALSE),-VLOOKUP($C17&" "&AJ$1,Results!$H:$I,2,FALSE)),"") -> 83 | AK17: =IFERROR(IFERROR(VLOOKUP($C17&" "&AK$1,Results!$G:$I,3,FALSE),-VLOOKUP($C17&" "&AK$1,Results!$H:$I,2,FALSE)),"") -> 0 | AL17: =IFERROR(IFERROR(VLOOKUP($C17&" "&AL$1,Results!$G:$I,3,FALSE),-VLOOKUP($C17&" "&AL$1,Results!$H:$I,2,FALSE)),"") | AM17: =IFERROR(IFERROR(VLOOKUP($C17&" "&AM$1,Results!$G:$I,3,FALSE),-VLOOKUP($C17&" "&AM$1,Results!$H:$I,2,FALSE)),"") -> 82 | AN17: =IFERROR(IFERROR(VLOOKUP($C17&" "&AN$1,Results!$G:$I,3,FALSE),-VLOOKUP($C17&" "&AN$1,Results!$H:$I,2,FALSE)),"") -> 28 | ... BD17: =IFERROR(IFERROR(VLOOKUP($C17&" "&BD$1,Results!$G:$I,3,FALSE),-VLOOKUP($C17&" "&BD$1,Results!$H:$I,2,FALSE)),"") | BW17: =SUM(V17:BT17) -> 233 | BX17: =COUNTIF(E17:J17,1) -> 0 | BY17: =COUNTIF(E17:I17,0) -> 5 | BZ17: =COUNT(E17:J17) -> 6 | CA17: =+BX17/BZ17 -> 0 | CC17: =SUM(V17:BU17) -> 233 | CE17: 11 | CF17: =A17 -> 0 | CG17: =+CE17-CF17 -> 11
B18: 15 | C18: Wellsley | E18: =IF(AND(AJ18>0,$A18<VLOOKUP(AJ$1,$C:$L,10,FALSE)),1,IF(AND(AJ18<0,$A18>VLOOKUP(AJ$1,$C:$L,10,FALSE)),1,0)) -> 0 | F18: =IF(AND(AK18>0,$A18<VLOOKUP(AK$1,$C:$L,10,FALSE)),1,IF(AND(AK18<0,$A18>VLOOKUP(AK$1,$C:$L,10,FALSE)),1,0)) -> 0 | G18: =IF(AND(AL18>0,$A18<VLOOKUP(AL$1,$C:$L,10,FALSE)),1,IF(AND(AL18<0,$A18>VLOOKUP(AL$1,$C:$L,10,FALSE)),1,0)) -> 0 | H18: =IF(AND(AN18>0,$A18<VLOOKUP(AN$1,$C:$L,10,FALSE)),1,IF(AND(AN18<0,$A18>VLOOKUP(AN$1,$C:$L,10,FALSE)),1,0)) -> 0 | I18: =IF(AND(AO18>0,$A18<VLOOKUP(AO$1,$C:$L,10,FALSE)),1,IF(AND(AO18<0,$A18>VLOOKUP(AO$1,$C:$L,10,FALSE)),1,0)) -> 0 | J18: =IF(AND(AP18>0,$A18<VLOOKUP(AP$1,$C:$L,10,FALSE)),1,IF(AND(AP18<0,$A18>VLOOKUP(AP$1,$C:$L,10,FALSE)),1,0)) -> 0 | K18: Updated | L18: =A18 -> 0 | M18: 4 | N18: =COUNTIF($V18:$BU18,">0") -> 2 | O18: =COUNTIF($V18:$BU18,"<0") -> 4 | P18: =COUNTIF($V18:$BU18,"=0") -> 0 | Q18: =COUNTIF($AK18:$AN18,">0") -> 0 | R18: =COUNTIF($AK18:$AN18,"<0") -> 3 | S18: =COUNTIF($AK18:$AN18,"=0") -> 0 | T18: =COUNTIF(V18:BJ18,"NC") -> 0 | AG18: =IFERROR(IFERROR(VLOOKUP($C18&" "&AG$1,Results!$G:$I,3,FALSE),-VLOOKUP($C18&" "&AG$1,Results!$H:$I,2,FALSE)),"") | AH18: =IFERROR(IFERROR(VLOOKUP($C18&" "&AH$1,Results!$G:$I,3,FALSE),-VLOOKUP($C18&" "&AH$1,Results!$H:$I,2,FALSE)),"") | AI18: =IFERROR(IFERROR(VLOOKUP($C18&" "&AI$1,Results!$G:$I,3,FALSE),-VLOOKUP($C18&" "&AI$1,Results!$H:$I,2,FALSE)),"") | AJ18: =IFERROR(IFERROR(VLOOKUP($C18&" "&AJ$1,Results!$G:$I,3,FALSE),-VLOOKUP($C18&" "&AJ$1,Results!$H:$I,2,FALSE)),"") -> -108 | AK18: =IFERROR(IFERROR(VLOOKUP($C18&" "&AK$1,Results!$G:$I,3,FALSE),-VLOOKUP($C18&" "&AK$1,Results!$H:$I,2,FALSE)),"") -> -122 | AL18: =IFERROR(IFERROR(VLOOKUP($C18&" "&AL$1,Results!$G:$I,3,FALSE),-VLOOKUP($C18&" "&AL$1,Results!$H:$I,2,FALSE)),"") -> -82 | AM18: =IFERROR(IFERROR(VLOOKUP($C18&" "&AM$1,Results!$G:$I,3,FALSE),-VLOOKUP($C18&" "&AM$1,Results!$H:$I,2,FALSE)),"") | AN18: =IFERROR(IFERROR(VLOOKUP($C18&" "&AN$1,Results!$G:$I,3,FALSE),-VLOOKUP($C18&" "&AN$1,Results!$H:$I,2,FALSE)),"") -> -20 | ... BD18: =IFERROR(IFERROR(VLOOKUP($C18&" "&BD$1,Results!$G:$I,3,FALSE),-VLOOKUP($C18&" "&BD$1,Results!$H:$I,2,FALSE)),"") | BW18: =SUM(V18:BT18) -> -224 | BX18: =COUNTIF(E18:J18,1) -> 0 | BY18: =COUNTIF(E18:I18,0) -> 5 | BZ18: =COUNT(E18:J18) -> 6 | CA18: =+BX18/BZ18 -> 0 | CC18: =SUM(V18:BU18) -> -224 | CE18: 12 | CF18: =A18 -> 0 | CG18: =+CE18-CF18 -> 12
B19: 16 | C19: Haddon Hall | E19: =IF(AND(AK19>0,$A19<VLOOKUP(AK$1,$C:$L,10,FALSE)),1,IF(AND(AK19<0,$A19>VLOOKUP(AK$1,$C:$L,10,FALSE)),1,0)) -> 0 | F19: =IF(AND(AL19>0,$A19<VLOOKUP(AL$1,$C:$L,10,FALSE)),1,IF(AND(AL19<0,$A19>VLOOKUP(AL$1,$C:$L,10,FALSE)),1,0)) -> 0 | G19: =IF(AND(AM19>0,$A19<VLOOKUP(AM$1,$C:$L,10,FALSE)),1,IF(AND(AM19<0,$A19>VLOOKUP(AM$1,$C:$L,10,FALSE)),1,0)) -> 0 | H19: =IF(AND(AO19>0,$A19<VLOOKUP(AO$1,$C:$L,10,FALSE)),1,IF(AND(AO19<0,$A19>VLOOKUP(AO$1,$C:$L,10,FALSE)),1,0)) -> 0 | I19: =IF(AND(AP19>0,$A19<VLOOKUP(AP$1,$C:$L,10,FALSE)),1,IF(AND(AP19<0,$A19>VLOOKUP(AP$1,$C:$L,10,FALSE)),1,0)) -> 0 | J19: =IF(AND(AQ19>0,$A19<VLOOKUP(AQ$1,$C:$L,10,FALSE)),1,IF(AND(AQ19<0,$A19>VLOOKUP(AQ$1,$C:$L,10,FALSE)),1,0)) -> 0 | K19: Updated | L19: =A19 -> 0 | M19: 4 | N19: =COUNTIF($V19:$BU19,">0") -> 4 | O19: =COUNTIF($V19:$BU19,"<0") -> 2 | P19: =COUNTIF($V19:$BU19,"=0") -> 0 | Q19: =COUNTIF($AK19:$AN19,">0") -> 1 | R19: =COUNTIF($AK19:$AN19,"<0") -> 2 | S19: =COUNTIF($AK19:$AN19,"=0") -> 0 | T19: =COUNTIF(V19:BJ19,"NC") -> 0 | AG19: =IFERROR(IFERROR(VLOOKUP($C19&" "&AG$1,Results!$G:$I,3,FALSE),-VLOOKUP($C19&" "&AG$1,Results!$H:$I,2,FALSE)),"") | AH19: =IFERROR(IFERROR(VLOOKUP($C19&" "&AH$1,Results!$G:$I,3,FALSE),-VLOOKUP($C19&" "&AH$1,Results!$H:$I,2,FALSE)),"") | AI19: =IFERROR(IFERROR(VLOOKUP($C19&" "&AI$1,Results!$G:$I,3,FALSE),-VLOOKUP($C19&" "&AI$1,Results!$H:$I,2,FALSE)),"") | AJ19: =IFERROR(IFERROR(VLOOKUP($C19&" "&AJ$1,Results!$G:$I,3,FALSE),-VLOOKUP($C19&" "&AJ$1,Results!$H:$I,2,FALSE)),"") | AK19: =IFERROR(IFERROR(VLOOKUP($C19&" "&AK$1,Results!$G:$I,3,FALSE),-VLOOKUP($C19&" "&AK$1,Results!$H:$I,2,FALSE)),"") -> -4 | AL19: =IFERROR(IFERROR(VLOOKUP($C19&" "&AL$1,Results!$G:$I,3,FALSE),-VLOOKUP($C19&" "&AL$1,Results!$H:$I,2,FALSE)),"") -> -28 | AM19: =IFERROR(IFERROR(VLOOKUP($C19&" "&AM$1,Results!$G:$I,3,FALSE),-VLOOKUP($C19&" "&AM$1,Results!$H:$I,2,FALSE)),"") -> 20 | AN19: =IFERROR(IFERROR(VLOOKUP($C19&" "&AN$1,Results!$G:$I,3,FALSE),-VLOOKUP($C19&" "&AN$1,Results!$H:$I,2,FALSE)),"") | ... BD19: =IFERROR(IFERROR(VLOOKUP($C19&" "&BD$1,Results!$G:$I,3,FALSE),-VLOOKUP($C19&" "&BD$1,Results!$H:$I,2,FALSE)),"") | BW19: =SUM(V19:BT19) -> 111 | BX19: =COUNTIF(E19:J19,1) -> 0 | BY19: =COUNTIF(E19:I19,0) -> 5 | BZ19: =COUNT(E19:J19) -> 6 | CA19: =+BX19/BZ19 -> 0 | CC19: =SUM(V19:BU19) -> 111 | CE19: 13 | CF19: =A19 -> 0 | CG19: =+CE19-CF19 -> 13
B20: 17 | C20: Dutchman Downs | E20: =IF(AND(AL20>0,$A20<VLOOKUP(AL$1,$C:$L,10,FALSE)),1,IF(AND(AL20<0,$A20>VLOOKUP(AL$1,$C:$L,10,FALSE)),1,0)) -> 0 | F20: =IF(AND(AM20>0,$A20<VLOOKUP(AM$1,$C:$L,10,FALSE)),1,IF(AND(AM20<0,$A20>VLOOKUP(AM$1,$C:$L,10,FALSE)),1,0)) -> 0 | G20: =IF(AND(AN20>0,$A20<VLOOKUP(AN$1,$C:$L,10,FALSE)),1,IF(AND(AN20<0,$A20>VLOOKUP(AN$1,$C:$L,10,FALSE)),1,0)) -> 0 | H20: =IF(AND(AP20>0,$A20<VLOOKUP(AP$1,$C:$L,10,FALSE)),1,IF(AND(AP20<0,$A20>VLOOKUP(AP$1,$C:$L,10,FALSE)),1,0)) -> 0 | I20: =IF(AND(AQ20>0,$A20<VLOOKUP(AQ$1,$C:$L,10,FALSE)),1,IF(AND(AQ20<0,$A20>VLOOKUP(AQ$1,$C:$L,10,FALSE)),1,0)) -> 0 | J20: =IF(AND(AR20>0,$A20<VLOOKUP(AR$1,$C:$L,10,FALSE)),1,IF(AND(AR20<0,$A20>VLOOKUP(AR$1,$C:$L,10,FALSE)),1,0)) -> 0 | K20: Updated | L20: =A20 -> 0 | M20: 5 | N20: =COUNTIF($V20:$BU20,">0") -> 1 | O20: =COUNTIF($V20:$BU20,"<0") -> 5 | P20: =COUNTIF($V20:$BU20,"=0") -> 0 | Q20: =COUNTIF($AO20:$AR20,">0") -> 1 | R20: =COUNTIF($AO20:$AR20,"<0") -> 2 | S20: =COUNTIF($AO20:$AR20,"=0") -> 0 | T20: =COUNTIF(V20:BJ20,"NC") -> 0 | AG20: =IFERROR(IFERROR(VLOOKUP($C20&" "&AG$1,Results!$G:$I,3,FALSE),-VLOOKUP($C20&" "&AG$1,Results!$H:$I,2,FALSE)),"") | AH20: =IFERROR(IFERROR(VLOOKUP($C20&" "&AH$1,Results!$G:$I,3,FALSE),-VLOOKUP($C20&" "&AH$1,Results!$H:$I,2,FALSE)),"") | AI20: =IFERROR(IFERROR(VLOOKUP($C20&" "&AI$1,Results!$G:$I,3,FALSE),-VLOOKUP($C20&" "&AI$1,Results!$H:$I,2,FALSE)),"") | AJ20: =IFERROR(IFERROR(VLOOKUP($C20&" "&AJ$1,Results!$G:$I,3,FALSE),-VLOOKUP($C20&" "&AJ$1,Results!$H:$I,2,FALSE)),"") | AK20: =IFERROR(IFERROR(VLOOKUP($C20&" "&AK$1,Results!$G:$I,3,FALSE),-VLOOKUP($C20&" "&AK$1,Results!$H:$I,2,FALSE)),"") | AL20: =IFERROR(IFERROR(VLOOKUP($C20&" "&AL$1,Results!$G:$I,3,FALSE),-VLOOKUP($C20&" "&AL$1,Results!$H:$I,2,FALSE)),"") -> -65 | AM20: =IFERROR(IFERROR(VLOOKUP($C20&" "&AM$1,Results!$G:$I,3,FALSE),-VLOOKUP($C20&" "&AM$1,Results!$H:$I,2,FALSE)),"") -> -55 | AN20: =IFERROR(IFERROR(VLOOKUP($C20&" "&AN$1,Results!$G:$I,3,FALSE),-VLOOKUP($C20&" "&AN$1,Results!$H:$I,2,FALSE)),"") -> -65 | ... BD20: =IFERROR(IFERROR(VLOOKUP($C20&" "&BD$1,Results!$G:$I,3,FALSE),-VLOOKUP($C20&" "&BD$1,Results!$H:$I,2,FALSE)),"") | BW20: =SUM(V20:BT20) -> -197 | BX20: =COUNTIF(E20:J20,1) -> 0 | BY20: =COUNTIF(E20:I20,0) -> 5 | BZ20: =COUNT(E20:J20) -> 6 | CA20: =+BX20/BZ20 -> 0 | CC20: =SUM(V20:BU20) -> -197 | CE20: 18 | CF20: =A20 -> 0 | CG20: =+CE20-CF20 -> 18
B21: 18 | C21: The Reserve | E21: =IF(AND(AM21>0,$A21<VLOOKUP(AM$1,$C:$L,10,FALSE)),1,IF(AND(AM21<0,$A21>VLOOKUP(AM$1,$C:$L,10,FALSE)),1,0)) -> 0 | F21: =IF(AND(AN21>0,$A21<VLOOKUP(AN$1,$C:$L,10,FALSE)),1,IF(AND(AN21<0,$A21>VLOOKUP(AN$1,$C:$L,10,FALSE)),1,0)) -> 0 | G21: =IF(AND(AO21>0,$A21<VLOOKUP(AO$1,$C:$L,10,FALSE)),1,IF(AND(AO21<0,$A21>VLOOKUP(AO$1,$C:$L,10,FALSE)),1,0)) -> 0 | H21: =IF(AND(AQ21>0,$A21<VLOOKUP(AQ$1,$C:$L,10,FALSE)),1,IF(AND(AQ21<0,$A21>VLOOKUP(AQ$1,$C:$L,10,FALSE)),1,0)) -> 0 | I21: =IF(AND(AR21>0,$A21<VLOOKUP(AR$1,$C:$L,10,FALSE)),1,IF(AND(AR21<0,$A21>VLOOKUP(AR$1,$C:$L,10,FALSE)),1,0)) -> 0 | J21: =IF(AND(AS21>0,$A21<VLOOKUP(AS$1,$C:$L,10,FALSE)),1,IF(AND(AS21<0,$A21>VLOOKUP(AS$1,$C:$L,10,FALSE)),1,0)) -> 0 | K21: Updated | L21: =A21 -> 0 | M21: 5 | N21: =COUNTIF($V21:$BU21,">0") -> 3 | O21: =COUNTIF($V21:$BU21,"<0") -> 3 | P21: =COUNTIF($V21:$BU21,"=0") -> 0 | Q21: =COUNTIF($AO21:$AR21,">0") -> 2 | R21: =COUNTIF($AO21:$AR21,"<0") -> 1 | S21: =COUNTIF($AO21:$AR21,"=0") -> 0 | T21: =COUNTIF(V21:BJ21,"NC") -> 0 | AG21: =IFERROR(IFERROR(VLOOKUP($C21&" "&AG$1,Results!$G:$I,3,FALSE),-VLOOKUP($C21&" "&AG$1,Results!$H:$I,2,FALSE)),"") | AH21: =IFERROR(IFERROR(VLOOKUP($C21&" "&AH$1,Results!$G:$I,3,FALSE),-VLOOKUP($C21&" "&AH$1,Results!$H:$I,2,FALSE)),"") | AI21: =IFERROR(IFERROR(VLOOKUP($C21&" "&AI$1,Results!$G:$I,3,FALSE),-VLOOKUP($C21&" "&AI$1,Results!$H:$I,2,FALSE)),"") | AJ21: =IFERROR(IFERROR(VLOOKUP($C21&" "&AJ$1,Results!$G:$I,3,FALSE),-VLOOKUP($C21&" "&AJ$1,Results!$H:$I,2,FALSE)),"") | AK21: =IFERROR(IFERROR(VLOOKUP($C21&" "&AK$1,Results!$G:$I,3,FALSE),-VLOOKUP($C21&" "&AK$1,Results!$H:$I,2,FALSE)),"") | AL21: =IFERROR(IFERROR(VLOOKUP($C21&" "&AL$1,Results!$G:$I,3,FALSE),-VLOOKUP($C21&" "&AL$1,Results!$H:$I,2,FALSE)),"") | AM21: =IFERROR(IFERROR(VLOOKUP($C21&" "&AM$1,Results!$G:$I,3,FALSE),-VLOOKUP($C21&" "&AM$1,Results!$H:$I,2,FALSE)),"") -> -53 | AN21: =IFERROR(IFERROR(VLOOKUP($C21&" "&AN$1,Results!$G:$I,3,FALSE),-VLOOKUP($C21&" "&AN$1,Results!$H:$I,2,FALSE)),"") -> -55 | ... BD21: =IFERROR(IFERROR(VLOOKUP($C21&" "&BD$1,Results!$G:$I,3,FALSE),-VLOOKUP($C21&" "&BD$1,Results!$H:$I,2,FALSE)),"") | BW21: =SUM(V21:BT21) -> -25 | BX21: =COUNTIF(E21:J21,1) -> 0 | BY21: =COUNTIF(E21:I21,0) -> 5 | BZ21: =COUNT(E21:J21) -> 6 | CA21: =+BX21/BZ21 -> 0 | CC21: =SUM(V21:BU21) -> -25 | CE21: 19 | CF21: =A21 -> 0 | CG21: =+CE21-CF21 -> 19
B22: 19 | C22: Silverton | E22: =IF(AND(AN22>0,$A22<VLOOKUP(AN$1,$C:$L,10,FALSE)),1,IF(AND(AN22<0,$A22>VLOOKUP(AN$1,$C:$L,10,FALSE)),1,0)) -> 0 | F22: =IF(AND(AO22>0,$A22<VLOOKUP(AO$1,$C:$L,10,FALSE)),1,IF(AND(AO22<0,$A22>VLOOKUP(AO$1,$C:$L,10,FALSE)),1,0)) -> 0 | G22: =IF(AND(AP22>0,$A22<VLOOKUP(AP$1,$C:$L,10,FALSE)),1,IF(AND(AP22<0,$A22>VLOOKUP(AP$1,$C:$L,10,FALSE)),1,0)) -> 0 | H22: =IF(AND(AR22>0,$A22<VLOOKUP(AR$1,$C:$L,10,FALSE)),1,IF(AND(AR22<0,$A22>VLOOKUP(AR$1,$C:$L,10,FALSE)),1,0)) -> 0 | I22: =IF(AND(AS22>0,$A22<VLOOKUP(AS$1,$C:$L,10,FALSE)),1,IF(AND(AS22<0,$A22>VLOOKUP(AS$1,$C:$L,10,FALSE)),1,0)) -> 0 | J22: =IF(AND(AT22>0,$A22<VLOOKUP(AT$1,$C:$L,10,FALSE)),1,IF(AND(AT22<0,$A22>VLOOKUP(AT$1,$C:$L,10,FALSE)),1,0)) -> 0 | K22: Updated | L22: =A22 -> 0 | M22: 5 | N22: =COUNTIF($V22:$BU22,">0") -> 4 | O22: =COUNTIF($V22:$BU22,"<0") -> 2 | P22: =COUNTIF($V22:$BU22,"=0") -> 0 | Q22: =COUNTIF($AO22:$AR22,">0") -> 2 | R22: =COUNTIF($AO22:$AR22,"<0") -> 1 | S22: =COUNTIF($AO22:$AR22,"=0") -> 0 | T22: =COUNTIF(V22:BJ22,"NC") -> 0 | AG22: =IFERROR(IFERROR(VLOOKUP($C22&" "&AG$1,Results!$G:$I,3,FALSE),-VLOOKUP($C22&" "&AG$1,Results!$H:$I,2,FALSE)),"") | AH22: =IFERROR(IFERROR(VLOOKUP($C22&" "&AH$1,Results!$G:$I,3,FALSE),-VLOOKUP($C22&" "&AH$1,Results!$H:$I,2,FALSE)),"") | AI22: =IFERROR(IFERROR(VLOOKUP($C22&" "&AI$1,Results!$G:$I,3,FALSE),-VLOOKUP($C22&" "&AI$1,Results!$H:$I,2,FALSE)),"") | AJ22: =IFERROR(IFERROR(VLOOKUP($C22&" "&AJ$1,Results!$G:$I,3,FALSE),-VLOOKUP($C22&" "&AJ$1,Results!$H:$I,2,FALSE)),"") | AK22: =IFERROR(IFERROR(VLOOKUP($C22&" "&AK$1,Results!$G:$I,3,FALSE),-VLOOKUP($C22&" "&AK$1,Results!$H:$I,2,FALSE)),"") | AL22: =IFERROR(IFERROR(VLOOKUP($C22&" "&AL$1,Results!$G:$I,3,FALSE),-VLOOKUP($C22&" "&AL$1,Results!$H:$I,2,FALSE)),"") | AM22: =IFERROR(IFERROR(VLOOKUP($C22&" "&AM$1,Results!$G:$I,3,FALSE),-VLOOKUP($C22&" "&AM$1,Results!$H:$I,2,FALSE)),"") | AN22: =IFERROR(IFERROR(VLOOKUP($C22&" "&AN$1,Results!$G:$I,3,FALSE),-VLOOKUP($C22&" "&AN$1,Results!$H:$I,2,FALSE)),"") -> -3 | ... BD22: =IFERROR(IFERROR(VLOOKUP($C22&" "&BD$1,Results!$G:$I,3,FALSE),-VLOOKUP($C22&" "&BD$1,Results!$H:$I,2,FALSE)),"") | BW22: =SUM(V22:BT22) -> 188 | BX22: =COUNTIF(E22:J22,1) -> 0 | BY22: =COUNTIF(E22:I22,0) -> 5 | BZ22: =COUNT(E22:J22) -> 6 | CA22: =+BX22/BZ22 -> 0 | CC22: =SUM(V22:BU22) -> 188 | CE22: 22 | CF22: =A22 -> 0 | CG22: =+CE22-CF22 -> 22
B23: 20 | C23: Oxxford Hunt | E23: =IF(AND(AO23>0,$A23<VLOOKUP(AO$1,$C:$L,10,FALSE)),1,IF(AND(AO23<0,$A23>VLOOKUP(AO$1,$C:$L,10,FALSE)),1,0)) -> 0 | F23: =IF(AND(AP23>0,$A23<VLOOKUP(AP$1,$C:$L,10,FALSE)),1,IF(AND(AP23<0,$A23>VLOOKUP(AP$1,$C:$L,10,FALSE)),1,0)) -> 0 | G23: =IF(AND(AQ23>0,$A23<VLOOKUP(AQ$1,$C:$L,10,FALSE)),1,IF(AND(AQ23<0,$A23>VLOOKUP(AQ$1,$C:$L,10,FALSE)),1,0)) -> 0 | H23: =IF(AND(AS23>0,$A23<VLOOKUP(AS$1,$C:$L,10,FALSE)),1,IF(AND(AS23<0,$A23>VLOOKUP(AS$1,$C:$L,10,FALSE)),1,0)) -> 0 | I23: =IF(AND(AT23>0,$A23<VLOOKUP(AT$1,$C:$L,10,FALSE)),1,IF(AND(AT23<0,$A23>VLOOKUP(AT$1,$C:$L,10,FALSE)),1,0)) -> 0 | J23: =IF(AND(AU23>0,$A23<VLOOKUP(AU$1,$C:$L,10,FALSE)),1,IF(AND(AU23<0,$A23>VLOOKUP(AU$1,$C:$L,10,FALSE)),1,0)) -> 0 | K23: Updated | L23: =A23 -> 0 | M23: 5 | N23: =COUNTIF($V23:$BU23,">0") -> 2 | O23: =COUNTIF($V23:$BU23,"<0") -> 4 | P23: =COUNTIF($V23:$BU23,"=0") -> 0 | Q23: =COUNTIF($AO23:$AR23,">0") -> 1 | R23: =COUNTIF($AO23:$AR23,"<0") -> 2 | S23: =COUNTIF($AO23:$AR23,"=0") -> 0 | T23: =COUNTIF(V23:BJ23,"NC") -> 0 | AG23: =IFERROR(IFERROR(VLOOKUP($C23&" "&AG$1,Results!$G:$I,3,FALSE),-VLOOKUP($C23&" "&AG$1,Results!$H:$I,2,FALSE)),"") | AH23: =IFERROR(IFERROR(VLOOKUP($C23&" "&AH$1,Results!$G:$I,3,FALSE),-VLOOKUP($C23&" "&AH$1,Results!$H:$I,2,FALSE)),"") | AI23: =IFERROR(IFERROR(VLOOKUP($C23&" "&AI$1,Results!$G:$I,3,FALSE),-VLOOKUP($C23&" "&AI$1,Results!$H:$I,2,FALSE)),"") | AJ23: =IFERROR(IFERROR(VLOOKUP($C23&" "&AJ$1,Results!$G:$I,3,FALSE),-VLOOKUP($C23&" "&AJ$1,Results!$H:$I,2,FALSE)),"") | AK23: =IFERROR(IFERROR(VLOOKUP($C23&" "&AK$1,Results!$G:$I,3,FALSE),-VLOOKUP($C23&" "&AK$1,Results!$H:$I,2,FALSE)),"") | AL23: =IFERROR(IFERROR(VLOOKUP($C23&" "&AL$1,Results!$G:$I,3,FALSE),-VLOOKUP($C23&" "&AL$1,Results!$H:$I,2,FALSE)),"") | AM23: =IFERROR(IFERROR(VLOOKUP($C23&" "&AM$1,Results!$G:$I,3,FALSE),-VLOOKUP($C23&" "&AM$1,Results!$H:$I,2,FALSE)),"") | AN23: =IFERROR(IFERROR(VLOOKUP($C23&" "&AN$1,Results!$G:$I,3,FALSE),-VLOOKUP($C23&" "&AN$1,Results!$H:$I,2,FALSE)),"") | ... BD23: =IFERROR(IFERROR(VLOOKUP($C23&" "&BD$1,Results!$G:$I,3,FALSE),-VLOOKUP($C23&" "&BD$1,Results!$H:$I,2,FALSE)),"") | BW23: =SUM(V23:BT23) -> -179 | BX23: =COUNTIF(E23:J23,1) -> 0 | BY23: =COUNTIF(E23:I23,0) -> 5 | BZ23: =COUNT(E23:J23) -> 6 | CA23: =+BX23/BZ23 -> 0 | CC23: =SUM(V23:BU23) -> -179 | CE23: 17 | CF23: =A23 -> 0 | CG23: =+CE23-CF23 -> 17
B24: 21 | C24: Regency | E24: =IF(AND(AP24>0,$A24<VLOOKUP(AP$1,$C:$L,10,FALSE)),1,IF(AND(AP24<0,$A24>VLOOKUP(AP$1,$C:$L,10,FALSE)),1,0)) -> 0 | F24: =IF(AND(AQ24>0,$A24<VLOOKUP(AQ$1,$C:$L,10,FALSE)),1,IF(AND(AQ24<0,$A24>VLOOKUP(AQ$1,$C:$L,10,FALSE)),1,0)) -> 0 | G24: =IF(AND(AR24>0,$A24<VLOOKUP(AR$1,$C:$L,10,FALSE)),1,IF(AND(AR24<0,$A24>VLOOKUP(AR$1,$C:$L,10,FALSE)),1,0)) -> 0 | H24: =IF(AND(AT24>0,$A24<VLOOKUP(AT$1,$C:$L,10,FALSE)),1,IF(AND(AT24<0,$A24>VLOOKUP(AT$1,$C:$L,10,FALSE)),1,0)) -> 0 | I24: =IF(AND(AU24>0,$A24<VLOOKUP(AU$1,$C:$L,10,FALSE)),1,IF(AND(AU24<0,$A24>VLOOKUP(AU$1,$C:$L,10,FALSE)),1,0)) -> 0 | J24: =IF(AND(AV24>0,$A24<VLOOKUP(AV$1,$C:$L,10,FALSE)),1,IF(AND(AV24<0,$A24>VLOOKUP(AV$1,$C:$L,10,FALSE)),1,0)) -> 0 | K24: Updated | L24: =A24 -> 0 | M24: 6 | N24: =COUNTIF($V24:$BU24,">0") -> 0 | O24: =COUNTIF($V24:$BU24,"<0") -> 6 | P24: =COUNTIF($V24:$BU24,"=0") -> 0 | Q24: =COUNTIF($AS24:$AV24,">0") -> 0 | R24: =COUNTIF($AS24:$AV24,"<0") -> 3 | S24: =COUNTIF($AS24:$AV24,"=0") -> 0 | T24: =COUNTIF(V24:BJ24,"NC") -> 0 | AG24: =IFERROR(IFERROR(VLOOKUP($C24&" "&AG$1,Results!$G:$I,3,FALSE),-VLOOKUP($C24&" "&AG$1,Results!$H:$I,2,FALSE)),"") | AH24: =IFERROR(IFERROR(VLOOKUP($C24&" "&AH$1,Results!$G:$I,3,FALSE),-VLOOKUP($C24&" "&AH$1,Results!$H:$I,2,FALSE)),"") | AI24: =IFERROR(IFERROR(VLOOKUP($C24&" "&AI$1,Results!$G:$I,3,FALSE),-VLOOKUP($C24&" "&AI$1,Results!$H:$I,2,FALSE)),"") | AJ24: =IFERROR(IFERROR(VLOOKUP($C24&" "&AJ$1,Results!$G:$I,3,FALSE),-VLOOKUP($C24&" "&AJ$1,Results!$H:$I,2,FALSE)),"") | AK24: =IFERROR(IFERROR(VLOOKUP($C24&" "&AK$1,Results!$G:$I,3,FALSE),-VLOOKUP($C24&" "&AK$1,Results!$H:$I,2,FALSE)),"") | AL24: =IFERROR(IFERROR(VLOOKUP($C24&" "&AL$1,Results!$G:$I,3,FALSE),-VLOOKUP($C24&" "&AL$1,Results!$H:$I,2,FALSE)),"") | AM24: =IFERROR(IFERROR(VLOOKUP($C24&" "&AM$1,Results!$G:$I,3,FALSE),-VLOOKUP($C24&" "&AM$1,Results!$H:$I,2,FALSE)),"") | AN24: =IFERROR(IFERROR(VLOOKUP($C24&" "&AN$1,Results!$G:$I,3,FALSE),-VLOOKUP($C24&" "&AN$1,Results!$H:$I,2,FALSE)),"") | ... BD24: =IFERROR(IFERROR(VLOOKUP($C24&" "&BD$1,Results!$G:$I,3,FALSE),-VLOOKUP($C24&" "&BD$1,Results!$H:$I,2,FALSE)),"") | BW24: =SUM(V24:BT24) -> -349 | BX24: =COUNTIF(E24:J24,1) -> 0 | BY24: =COUNTIF(E24:I24,0) -> 5 | BZ24: =COUNT(E24:J24) -> 6 | CA24: =+BX24/BZ24 -> 0 | CC24: =SUM(V24:BU24) -> -349 | CE24: 21 | CF24: =A24 -> 0 | CG24: =+CE24-CF24 -> 21
B25: 22 | C25: Life Time Fitness Cary | E25: =IF(AND(AQ25>0,$A25<VLOOKUP(AQ$1,$C:$L,10,FALSE)),1,IF(AND(AQ25<0,$A25>VLOOKUP(AQ$1,$C:$L,10,FALSE)),1,0)) -> 0 | F25: =IF(AND(AR25>0,$A25<VLOOKUP(AR$1,$C:$L,10,FALSE)),1,IF(AND(AR25<0,$A25>VLOOKUP(AR$1,$C:$L,10,FALSE)),1,0)) -> 0 | G25: =IF(AND(AS25>0,$A25<VLOOKUP(AS$1,$C:$L,10,FALSE)),1,IF(AND(AS25<0,$A25>VLOOKUP(AS$1,$C:$L,10,FALSE)),1,0)) -> 0 | H25: =IF(AND(AU25>0,$A25<VLOOKUP(AU$1,$C:$L,10,FALSE)),1,IF(AND(AU25<0,$A25>VLOOKUP(AU$1,$C:$L,10,FALSE)),1,0)) -> 0 | I25: =IF(AND(AV25>0,$A25<VLOOKUP(AV$1,$C:$L,10,FALSE)),1,IF(AND(AV25<0,$A25>VLOOKUP(AV$1,$C:$L,10,FALSE)),1,0)) -> 0 | J25: =IF(AND(AW25>0,$A25<VLOOKUP(AW$1,$C:$L,10,FALSE)),1,IF(AND(AW25<0,$A25>VLOOKUP(AW$1,$C:$L,10,FALSE)),1,0)) -> 0 | K25: Updated | L25: =A25 -> 0 | M25: 6 | N25: =COUNTIF($V25:$BU25,">0") -> 3 | O25: =COUNTIF($V25:$BU25,"<0") -> 3 | P25: =COUNTIF($V25:$BU25,"=0") -> 0 | Q25: =COUNTIF($AS25:$AV25,">0") -> 1 | R25: =COUNTIF($AS25:$AV25,"<0") -> 2 | S25: =COUNTIF($AS25:$AV25,"=0") -> 0 | T25: =COUNTIF(V25:BJ25,"NC") -> 0 | AG25: =IFERROR(IFERROR(VLOOKUP($C25&" "&AG$1,Results!$G:$I,3,FALSE),-VLOOKUP($C25&" "&AG$1,Results!$H:$I,2,FALSE)),"") | AH25: =IFERROR(IFERROR(VLOOKUP($C25&" "&AH$1,Results!$G:$I,3,FALSE),-VLOOKUP($C25&" "&AH$1,Results!$H:$I,2,FALSE)),"") | AI25: =IFERROR(IFERROR(VLOOKUP($C25&" "&AI$1,Results!$G:$I,3,FALSE),-VLOOKUP($C25&" "&AI$1,Results!$H:$I,2,FALSE)),"") | AJ25: =IFERROR(IFERROR(VLOOKUP($C25&" "&AJ$1,Results!$G:$I,3,FALSE),-VLOOKUP($C25&" "&AJ$1,Results!$H:$I,2,FALSE)),"") | AK25: =IFERROR(IFERROR(VLOOKUP($C25&" "&AK$1,Results!$G:$I,3,FALSE),-VLOOKUP($C25&" "&AK$1,Results!$H:$I,2,FALSE)),"") | AL25: =IFERROR(IFERROR(VLOOKUP($C25&" "&AL$1,Results!$G:$I,3,FALSE),-VLOOKUP($C25&" "&AL$1,Results!$H:$I,2,FALSE)),"") | AM25: =IFERROR(IFERROR(VLOOKUP($C25&" "&AM$1,Results!$G:$I,3,FALSE),-VLOOKUP($C25&" "&AM$1,Results!$H:$I,2,FALSE)),"") | AN25: =IFERROR(IFERROR(VLOOKUP($C25&" "&AN$1,Results!$G:$I,3,FALSE),-VLOOKUP($C25&" "&AN$1,Results!$H:$I,2,FALSE)),"") | ... BD25: =IFERROR(IFERROR(VLOOKUP($C25&" "&BD$1,Results!$G:$I,3,FALSE),-VLOOKUP($C25&" "&BD$1,Results!$H:$I,2,FALSE)),"") | BW25: =SUM(V25:BT25) -> -37 | BX25: =COUNTIF(E25:J25,1) -> 0 | BY25: =COUNTIF(E25:I25,0) -> 5 | BZ25: =COUNT(E25:J25) -> 6 | CA25: =+BX25/BZ25 -> 0 | CC25: =SUM(V25:BU25) -> -37 | CE25: 27 | CF25: =A25 -> 0 | CG25: =+CE25-CF25 -> 27
B26: 23 | C26: Highcroft | E26: =IF(AND(AR26>0,$A26<VLOOKUP(AR$1,$C:$L,10,FALSE)),1,IF(AND(AR26<0,$A26>VLOOKUP(AR$1,$C:$L,10,FALSE)),1,0)) -> 0 | F26: =IF(AND(AS26>0,$A26<VLOOKUP(AS$1,$C:$L,10,FALSE)),1,IF(AND(AS26<0,$A26>VLOOKUP(AS$1,$C:$L,10,FALSE)),1,0)) -> 0 | G26: =IF(AND(AT26>0,$A26<VLOOKUP(AT$1,$C:$L,10,FALSE)),1,IF(AND(AT26<0,$A26>VLOOKUP(AT$1,$C:$L,10,FALSE)),1,0)) -> 0 | H26: =IF(AND(AV26>0,$A26<VLOOKUP(AV$1,$C:$L,10,FALSE)),1,IF(AND(AV26<0,$A26>VLOOKUP(AV$1,$C:$L,10,FALSE)),1,0)) -> 0 | I26: =IF(AND(AW26>0,$A26<VLOOKUP(AW$1,$C:$L,10,FALSE)),1,IF(AND(AW26<0,$A26>VLOOKUP(AW$1,$C:$L,10,FALSE)),1,0)) -> 0 | J26: =IF(AND(AX26>0,$A26<VLOOKUP(AX$1,$C:$L,10,FALSE)),1,IF(AND(AX26<0,$A26>VLOOKUP(AX$1,$C:$L,10,FALSE)),1,0)) -> 0 | K26: Updated | L26: =A26 -> 0 | M26: 6 | N26: =COUNTIF($V26:$BU26,">0") -> 5 | O26: =COUNTIF($V26:$BU26,"<0") -> 1 | P26: =COUNTIF($V26:$BU26,"=0") -> 0 | Q26: =COUNTIF($AS26:$AV26,">0") -> 3 | R26: =COUNTIF($AS26:$AV26,"<0") -> 0 | S26: =COUNTIF($AS26:$AV26,"=0") -> 0 | T26: =COUNTIF(V26:BJ26,"NC") -> 0 | AG26: =IFERROR(IFERROR(VLOOKUP($C26&" "&AG$1,Results!$G:$I,3,FALSE),-VLOOKUP($C26&" "&AG$1,Results!$H:$I,2,FALSE)),"") | AH26: =IFERROR(IFERROR(VLOOKUP($C26&" "&AH$1,Results!$G:$I,3,FALSE),-VLOOKUP($C26&" "&AH$1,Results!$H:$I,2,FALSE)),"") | AI26: =IFERROR(IFERROR(VLOOKUP($C26&" "&AI$1,Results!$G:$I,3,FALSE),-VLOOKUP($C26&" "&AI$1,Results!$H:$I,2,FALSE)),"") | AJ26: =IFERROR(IFERROR(VLOOKUP($C26&" "&AJ$1,Results!$G:$I,3,FALSE),-VLOOKUP($C26&" "&AJ$1,Results!$H:$I,2,FALSE)),"") | AK26: =IFERROR(IFERROR(VLOOKUP($C26&" "&AK$1,Results!$G:$I,3,FALSE),-VLOOKUP($C26&" "&AK$1,Results!$H:$I,2,FALSE)),"") | AL26: =IFERROR(IFERROR(VLOOKUP($C26&" "&AL$1,Results!$G:$I,3,FALSE),-VLOOKUP($C26&" "&AL$1,Results!$H:$I,2,FALSE)),"") | AM26: =IFERROR(IFERROR(VLOOKUP($C26&" "&AM$1,Results!$G:$I,3,FALSE),-VLOOKUP($C26&" "&AM$1,Results!$H:$I,2,FALSE)),"") | AN26: =IFERROR(IFERROR(VLOOKUP($C26&" "&AN$1,Results!$G:$I,3,FALSE),-VLOOKUP($C26&" "&AN$1,Results!$H:$I,2,FALSE)),"") | ... BD26: =IFERROR(IFERROR(VLOOKUP($C26&" "&BD$1,Results!$G:$I,3,FALSE),-VLOOKUP($C26&" "&BD$1,Results!$H:$I,2,FALSE)),"") | BW26: =SUM(V26:BT26) -> 422 | BX26: =COUNTIF(E26:J26,1) -> 0 | BY26: =COUNTIF(E26:I26,0) -> 5 | BZ26: =COUNT(E26:J26) -> 6 | CA26: =+BX26/BZ26 -> 0 | CC26: =SUM(V26:BU26) -> 422 | CE26: 20 | CF26: =A26 -> 0 | CG26: =+CE26-CF26 -> 20
B27: 24 | C27: Brookstone | E27: =IF(AND(AS27>0,$A27<VLOOKUP(AS$1,$C:$L,10,FALSE)),1,IF(AND(AS27<0,$A27>VLOOKUP(AS$1,$C:$L,10,FALSE)),1,0)) -> 0 | F27: =IF(AND(AT27>0,$A27<VLOOKUP(AT$1,$C:$L,10,FALSE)),1,IF(AND(AT27<0,$A27>VLOOKUP(AT$1,$C:$L,10,FALSE)),1,0)) -> 0 | G27: =IF(AND(AU27>0,$A27<VLOOKUP(AU$1,$C:$L,10,FALSE)),1,IF(AND(AU27<0,$A27>VLOOKUP(AU$1,$C:$L,10,FALSE)),1,0)) -> 0 | H27: =IF(AND(AW27>0,$A27<VLOOKUP(AW$1,$C:$L,10,FALSE)),1,IF(AND(AW27<0,$A27>VLOOKUP(AW$1,$C:$L,10,FALSE)),1,0)) -> 0 | I27: =IF(AND(AX27>0,$A27<VLOOKUP(AX$1,$C:$L,10,FALSE)),1,IF(AND(AX27<0,$A27>VLOOKUP(AX$1,$C:$L,10,FALSE)),1,0)) -> 0 | J27: =IF(AND(AY27>0,$A27<VLOOKUP(AY$1,$C:$L,10,FALSE)),1,IF(AND(AY27<0,$A27>VLOOKUP(AY$1,$C:$L,10,FALSE)),1,0)) -> 0 | K27: Updated | L27: =A27 -> 0 | M27: 6 | N27: =COUNTIF($V27:$BU27,">0") -> 5 | O27: =COUNTIF($V27:$BU27,"<0") -> 1 | P27: =COUNTIF($V27:$BU27,"=0") -> 0 | Q27: =COUNTIF($AS27:$AV27,">0") -> 2 | R27: =COUNTIF($AS27:$AV27,"<0") -> 1 | S27: =COUNTIF($AS27:$AV27,"=0") -> 0 | T27: =COUNTIF(V27:BJ27,"NC") -> 0 | AG27: =IFERROR(IFERROR(VLOOKUP($C27&" "&AG$1,Results!$G:$I,3,FALSE),-VLOOKUP($C27&" "&AG$1,Results!$H:$I,2,FALSE)),"") | AH27: =IFERROR(IFERROR(VLOOKUP($C27&" "&AH$1,Results!$G:$I,3,FALSE),-VLOOKUP($C27&" "&AH$1,Results!$H:$I,2,FALSE)),"") | AI27: =IFERROR(IFERROR(VLOOKUP($C27&" "&AI$1,Results!$G:$I,3,FALSE),-VLOOKUP($C27&" "&AI$1,Results!$H:$I,2,FALSE)),"") | AJ27: =IFERROR(IFERROR(VLOOKUP($C27&" "&AJ$1,Results!$G:$I,3,FALSE),-VLOOKUP($C27&" "&AJ$1,Results!$H:$I,2,FALSE)),"") | AK27: =IFERROR(IFERROR(VLOOKUP($C27&" "&AK$1,Results!$G:$I,3,FALSE),-VLOOKUP($C27&" "&AK$1,Results!$H:$I,2,FALSE)),"") | AL27: =IFERROR(IFERROR(VLOOKUP($C27&" "&AL$1,Results!$G:$I,3,FALSE),-VLOOKUP($C27&" "&AL$1,Results!$H:$I,2,FALSE)),"") | AM27: =IFERROR(IFERROR(VLOOKUP($C27&" "&AM$1,Results!$G:$I,3,FALSE),-VLOOKUP($C27&" "&AM$1,Results!$H:$I,2,FALSE)),"") | AN27: =IFERROR(IFERROR(VLOOKUP($C27&" "&AN$1,Results!$G:$I,3,FALSE),-VLOOKUP($C27&" "&AN$1,Results!$H:$I,2,FALSE)),"") | ... BD27: =IFERROR(IFERROR(VLOOKUP($C27&" "&BD$1,Results!$G:$I,3,FALSE),-VLOOKUP($C27&" "&BD$1,Results!$H:$I,2,FALSE)),"") | BW27: =SUM(V27:BT27) -> 206 | BX27: =COUNTIF(E27:J27,1) -> 0 | BY27: =COUNTIF(E27:I27,0) -> 5 | BZ27: =COUNT(E27:J27) -> 6 | CA27: =+BX27/BZ27 -> 0 | CC27: =SUM(V27:BU27) -> 206 | CE27: 28 | CF27: =A27 -> 0 | CG27: =+CE27-CF27 -> 28
